Workbook

Sheet BANG KE DOANH THU CT 2020
A1: BẢNG KÊ DOANH THU CÁC CÔNG TRÌNH NĂM 2020
A2: STT | B2: TÊN CÔNG TRÌNH | C2: DT THUẦN | D2: GIÁ THÀNH | E2: LỢI NHUẬN TRƯỚC PHÂN BỔ CPQL
B3: DOANH THU Ở ĐỊA BÀN ĐẶC BIỆT KHÓ KHĂN | C3: =SUM(C4:C15) -> 3818033972 | D3: =SUM(D4:D15) -> 3010321577 | E3: =SUM(E4:E15) -> 807712395
B4: 2019_CT:Cải tạo và phát triển lưới điện cung cấp điện cho xã nông thôn mới Nhị quý, Thị Xã Cai Lậy theo hợp đồng 05/2019/HĐGK-TG ngày 20/08/2019 | C4: 863636364 | D4: 863636364 | E4: =C4-D4 -> 0
B5: 2020_Lắp đặt TBA 3 pha 250KVA HĐ số 2503/2020/HDXD/TNTV-MĐ | C5: 761386060 | D5: 721066187 | E5: =C5-D5 -> 40319873
B6: 2020_Thi công trụ 7.3m | C6: 7000000 | D6: 4200000 | E6: =C6-D6 -> 2800000
B7: 2020_Thay dây cáp CV3x22 mm2 | C7: 10560000 | D7: 8436000 | E7: =C7-D7 -> 2124000
B8: 2020_TCXD: Đường dây 22kv và trạm biến áp 3x25kvA Trung tâm hành chính xã Long Toàn theo HĐ số 06/2020/HĐ-TCXD ngày 30/07/2020 | C8: 354545455 | D8: 296203402 | E8: =C8-D8 -> 58342053
B9: 2020_Doanh thu thay đèn led, dựng trụ BTLT | C9: 14500000 | D9: 13404301 | E9: =C9-D9 -> 1095699
B10: 2020_Thi công trụ 7.3m | C10: 3000000 | D10: 1700000 | E10: =C10-D10 -> 1300000
B11: Thi công công trình Xóa câu phụ khu vực huyện Châu Thành | C11: 754920091 | D11: 403280061 | E11: =C11-D11 -> 351640030
B12: TC nâng cấp sửa chữa điện chiếu sáng khu vực chợ Khóm 5 | C12: 345454545 | D12: 305559162 | E12: =C12-D12 -> 39895383
B13: 2020_TC lắp đặt hệ thống giám sát và hệ thống chống sét Line Pin nhà máy: Nhà máy điện mặt trời Trung Nam Trà Vinh 0503/2020/HĐLĐ/TNE&C-MĐ/TNTV | C13: 521723275 | D13: 248869136 | E13: =C13-D13 -> 272854139
B14: Nâng cấp, sửa chữa hệ thống chiếu sáng đoạn từ bến phà tới trung tâm hành chính thị trấn Long Thành 15/2020/HDSC kí ngày 01/12/2020 | C14: 109090909 | D14: 94940680 | E14: =C14-D14 -> 14150229
B15: SCTC Xử lí sạt lỡ đường vào dự án Điện Mặt Trời Trung Nam Trà Vinh 12HDDKT-MĐ-TNTV kí ngày 25/08/2020 | C15: 72217273 | D15: 49026284 | E15: =C15-D15 -> 23190989
B16: ĐỊA BÀN KHÓ KHĂN | C16: =SUM(C17:C30) -> 1949071875 | D16: =SUM(D17:D30) -> 1787021877 | E16: =SUM(E17:E30) -> 162049998
B17: 2020_Vận chuyển máy biến áp theo hợp đồng số 18/HĐTV 2020/DLDH - MĐ ngày 19/05/2020 | C17: 2700000 | D17: 1620000 | E17: =C17-D17 -> 1080000
B18: 2020_Sửa chữa hệ thống chiếu sáng và các cổng hoa trên địa bàn thị xã theo HĐ số 18/HĐKT-2020 ngày 10/06/2020 | C18: 89260821 | D18: 81276907 | E18: =C18-D18 -> 7983914
B19: 2020_Sửa chữa hệ thống chiếu sáng trên địa bàn thị xã Duyên Hải và sửa chữa các cổng hoa trên địa bàn Phường 1 theo HĐ 01/HĐKT/2020/MĐ/QLĐT ngày 09/01/2020 | C19: 168181818 | D19: 158598363 | E19: =C19-D19 -> 9583455
B20: Thay 162 bóng đèn cao áp bằng đèn led các tuyến đường Phường 1 thị xã Duyên Hải 19/2020/HĐ-TC kí ngày 29/09/2020 | C20: 898181818 | D20: 850360925 | E20: =C20-D20 -> 47820893
B21: Sửa chữa và di dời điện phục vụ thi công QL53 trên địa bàn thị xã Duyên Hải 21/HDKT-2020 kí ngày 27/10/2020 | C21: 146240909 | D21: 135096031 | E21: =C21-D21 -> 11144878
B22: Hạ trạm biến áp tuyến đường số 01, phường 1, thị xã Duyên Hải theo hợp đồng 20/HDKT-2020 kí ngày 27/10/2020 | C22: 109090909 | D22: 94551173 | E22: =C22-D22 -> 14539736
B23: Lắp đặt trạm biến áp 3x25KVA công viên thị xã Duyên Hải 22/HĐKT-2020 kí ngày 26/06/2020 | C23: 163636364 | D23: 143431114 | E23: =C23-D23 -> 20205250
B24: SC đường dây HĐ 01/HĐKT/2020/MĐ-KGSG 05/05/2020 | C24: 16207000 | D24: 11200000 | E24: =C24-D24 -> 5007000
B25: Di dời trụ điện thuộc dự án Đường nhựa ấp Khoán Tiền xã Trường Long Hòa 09/2020/HD-TCXD kí ngày 24/06/2020 | C25: 13636364 | D25: 9100000 | E25: =C25-D25 -> 4536364
B26: Đóng, cắt điện chiếu sáng trên địa bàn thị xã Duyên Hải | C26: 25090909 | D26: 16300000 | E26: =C26-D26 -> 8790909
B27: 2020_TC dựng trụ 7.3m, 6m | C27: 8000000 | D27: 5600000 | E27: =C27-D27 -> 2400000
B28: 2020_TCXD: Di dời trụ điện hạ thế thuộc dự án Đường nhựa Trường THPT Long Hữu theo HĐ số 07/2020/HĐ-TCXD ngày 27/04/2020 | C28: 87272727 | D28: 71839120 | E28: =C28-D28 -> 15433607
... B30: 2018_CT:lắp đặt và CC vật tư phụ đường dây trung thế và trạm biến áp trên địa bàn H. Đông Hải | C30: 12350000 | D30: 11596244 | E30: =C30-D30 -> 753756
C31: =C16+C3 -> 5767105847 | D31: =D16+D3 -> 4797343454 | E31: =E16+E3 -> 969762393
B32: Trà Vinh, ngày 31 tháng 12 năm 2020
B33: GIÁM ĐỐC

Sheet TINH THUE TNDN 2020
A1: CÔNG TY TNHH XD ĐIỆN MINH ĐẠT
A2: MST: 2100619679
A3: BẢNG XÁC ĐỊNH THU NHẬP CHỊU THUẾ TNDN NĂM 2020
A5: Doanh thu | B5: Tỉ lệ / DT | C5: Doanh thu | D5: Giá Vốn | E5: Chi Phí Quản Lý | F5: CHI PHÍ LÃI | G5: CP KHÔNG ĐƯỢC TRỪ | H5: Lợi nhuận | I5: Kết chuyển lỗ | J5: LN sau kết chuyển | K5: TS | L5: Thuế TNDN | M5: MIỄN 50% | N5: Số thuế phải nộp | O5: GIẢM 30%
A6: Địa bàn không ưu đãi | B6: =C6/C18 -> 0 | C6: =+C7 -> 0 | H6: =+B6*H18 -> 0 | K6: 0.2 | L6: =+K6*H6 -> 0 | M6: 0 | N6: =+L6-M6 -> 0
A8: DT ĐỊA BÀN ĐẶT BIỆT KHÓ KHĂN | B8: =C8/C18 -> 0.66015046 | C8: =SUM(C9:C12) -> 3823490591 | D8: =SUM(D9:D12) -> 3010321577 | E8: =E18*B8 -> 3.2381673e+08 | F8: =F18*B8 -> 93122734 | G8: =G18*B8 -> 6639378.8 | H8: =C8-D8-E8-F8+G8-G8+F8 -> 4.8935229e+08 | I8: 0 | J8: =H8-I8 -> 4.8935229e+08 | K8: 0.1 | L8: =J8*K8 -> 48935229 | M8: =L8*100% -> 48935229 | N8: =L8-M8 -> 0
A9: 5111 | N9: =L9-M9 -> 0
A10: 5112 | C10: ='BANG KE DOANH THU CT 2020'!C3 -> 3818033972 | D10: ='BANG KE DOANH THU CT 2020'!D3 -> 3010321577 | N10: =L10-M10 -> 0
A11: 5151 | C11: 77167 | N11: =L11-M11 -> 0
A12: 5152 | C12: 5379452 | N12: =L12-M12 -> 0
A13: DT ĐỊA BÀN KHÓ KHĂN | B13: =C13/C18 -> 0.33984954 | C13: =+C14+C16+C17+C15 -> 1968356575 | D13: =SUM(D14:D17) -> 1787021877 | E13: =E18*B13 -> 1.6670285e+08 | F13: =F18*B13 -> 47940158 | G13: =G18*B13 -> 3417993.2 | H13: =C13-D13-E13-F13+G13-G13+F13 -> 14631847 | I13: 0 | J13: =H13-I13 -> 14631847 | K13: 0.17 | L13: =J13*K13 -> 2487414.1 | M13: 0 | N13: =L13-M13 -> 2487414.1 | O13: =N13*30% -> 746224.22 | P13: =N13-O13 -> 1741189.8
A14: 5112 | C14: ='BANG KE DOANH THU CT 2020'!C16 -> 1949071875 | D14: ='BANG KE DOANH THU CT 2020'!D16 -> 1787021877 | R14: =N13*30% -> 746224.22
A15: 5151 | R15: =N13-R14 -> 1741189.8
A16: 5112
A17: 711 | C17: 19284700
A18: Tổng cộng | B18: =B8+B13 -> 1 | C18: =C8+C13 -> 5791847166 | D18: =D8+D13 -> 4797343454 | E18: 490519576 | F18: 141062892 | G18: 10057372 | H18: =H8+H13 -> 503984136 | J18: =J8+J13 -> 503984136 | L18: =L8+L13 -> 51422643 | M18: =M8+M13 -> 48935229 | N18: =N13+N8 -> 2487414.1 | P18: =SUM(P13:P17) -> 1741189.8
H19: =+C18-#REF!-#REF!-#REF! -> #REF!
C20: 10793007946 | H20: 720227155 | M20: 74441349
C21: 454939007 | H21: =H20-H18 -> 216243019 | M21: =+M20-N18 -> 71953935
C22: 781954 | L22: 54680132
C23: =+C22+C21+C20 -> 11248728907 | L23: =+L22-L6 -> 54680132
L24: Trà Vinh, ngày 31 tháng 12 năm 2020 | R24: =N13*30% -> 746224.22
A25: LẬP BẢNG | C25: 4485290597 | F25: =J18*20% -> 1.0079683e+08 | L25: GIÁM ĐỐC
F26: =L8 -> 48935229
F27: =L13 -> 2487414.1 | R27: =N13-R24 -> 1741189.8
F28: =F26+F27 -> 51422643
F29: =F25-F28 -> 49374184 | M29: Nguyễn Thị Bước

Sheet BANG KE DOANH THU CT 2021
A1: BẢNG KÊ DOANH THU CÁC CÔNG TRÌNH NĂM 2020
A2: STT | B2: TÊN CÔNG TRÌNH | C2: DT THUẦN | D2: GIÁ THÀNH | E2: LỢI NHUẬN TRƯỚC PHÂN BỔ CPQL
B3: DOANH THU Ở ĐỊA BÀN ĐẶC BIỆT KHÓ KHĂN | C3: =SUM(C4:C10) -> 3811991196 | D3: =SUM(D4:D10) -> 3341983032 | E3: =SUM(E4:E10) -> 470008164
B4: 2021_Gói Thầu số 12: Thi Công xây dựng đường dây 22KV và trạm biến áp 3X25KVA thuộc dự án công viên văn hoá xã Dân Thành (HĐ số 12/2021/ HĐ-TCXD) | C4: 268181818 | D4: 245270305 | E4: =C4-D4 -> 22911513
B5: 2021_Sửa chữa hệ thống chiếu sáng HL81 (Đoạn từ cầu Kênh Xáng đến ngã ba Dân Thành) Số: 17/HĐKT-2021 | C5: 43636364 | D5: 42874258 | E5: =C5-D5 -> 762106
B6: Thi công công trình cung cấp điện huyện Châu Thành | C6: 572727272 | D6: 550000000 | E6: =C6-D6 -> 22727272
B7: 2021_Sửa chữa hệ thống chiếu sáng HL81 (Đoạn giao QL53 đến cầu Kênh Xáng) theo hợp đồng số 22/HĐKT-2021 ký ngày 10/06/2021 | C7: 36584182 | D7: 33239007 | E7: =C7-D7 -> 3345175
B8: 2021_Sửa chữa hệ thống chiếu sáng khu vực cầu kênh Xáng, xã Dân Thành, thị xã Duyên Hải theo HĐ số 28/HĐKT-2021 ký ngày 15/10/2021 | C8: 79450000 | D8: 78298172 | E8: =C8-D8 -> 1151828
B9: Gói thầu SPC-KfW3-W-BL2: Xây lắp đường dây và trạm biến áp phân phối các huyện Hoà Bình, Vĩnh Lợi, Phước Long, Đông Hải tỉnh Bạc Liêu thuộc dự án: Lưới điện hiệu quả tại các Thành phố vừa và nhỏ, sử dụng vốn vay ODA của chính Phủ Đức (DỰ án Thành 3 phần, GĐ 1, GĐ2) theo HĐ số 029/HĐXL | C9: 1249503570 | D9: 1010000000 | E9: =C9-D9 -> 239503570
B10: 2021_Thi công gói thầu SPC-2081CM-2021-05XL.1: Xây lắp đường dây trung, hạ áp, trạm biến áp và trụ móng đỡ nhánh rẽ vào nhà huyện Đầm Dơi, tỉnh Cà Mau theo Hợp đồng số 28/HĐ-XD ngày 01/10/2021 | C10: 1561907990 | D10: 1382301290 | E10: =C10-D10 -> 179606700
B11: ĐỊA BÀN KHÓ KHĂN | C11: =SUM(C12:C39) -> 6361724948 | D11: =SUM(D12:D39) -> 5831597194 | E11: =SUM(E12:E39) -> 530127754
B12: 2021_Lắp đặt TBA 3 pha KVA theo hợp đồng số 2904/2021/HĐTC/TNE&C _MINHDAT ký ngày 29/04/2021 | C12: 251433129 | D12: 241225911 | E12: =C12-D12 -> 10207218
B13: 2021_Sữa chữa hệ thống chiếu sáng QL53B (Đoạn từ cầu láng chim đến ngã 4 trường THCS Trường Long Hoà) theo HĐ số 22/HĐKT-2021 ký ngày 08/07/2021 | C13: 44857273 | D13: 38869847 | E13: =C13-D13 -> 5987426
B14: 2021_Sửa chữa hệ thống chiếu sáng khu vực cầu Ba Động , xã Trường Long Hòa, thị xã Duyên Hải theo HĐ số 27/HDKT-2021 ký ngày 12/10/2021 | C14: 23325455 | D14: 19458933 | E14: =C14-D14 -> 3866522
B15: 2021_Thi công XDCT Nâng cấp đường dây hạ áp 3 pha hỗn hợp đoạn cầu Sông Khoen đến cầu Kinh Xáng ấp Cây Cồng, xã Đôn Xuân theo hợp đồng số 22/2021/HĐTC ký ngày 04/11/2021 | C15: 182727273 | D15: 125402987 | E15: =C15-D15 -> 57324286
B16: 2021_Sửa chữa hệ thống chiếu sáng khu vực cầu Lãng Chim xã Trường Long Hoà, thị xã Duyên Hải theo hợp đồng số 29/HĐKT-2021 ký ngày 15/10/2021 | C16: 213242727 | D16: 205289628 | E16: =C16-D16 -> 7953099
B17: 2021_TCXDCT lắp đặt hệ thống điện chiếu sáng đường tạm vào khu hành chính huyện Duyên Hải theo hợp đồng số 40/2021/HĐTC ký ngày 14/12/2021 | C17: 91925454 | D17: 87616152 | E17: =C17-D17 -> 4309302
B18: 01/HDKT-2021: Sửa chữa hệ thống chiếu sáng trên tuyến đường 19/5, Phường 1, TX Duyên Hải, TV | C18: 43636364 | D18: 40864757 | E18: =C18-D18 -> 2771607
B19: 02/HDKT/2021-Sửa chữa hệ thống chiếu sáng đường vào Công an Phường 1 | C19: 44090909 | D19: 37505914 | E19: =C19-D19 -> 6584995
B20: 03/HDKT/2021_Sửa chữa hệ thống chiếu sáng khu vực Miễu Bà, xã Long Hữu | C20: 38181818 | D20: 38930476 | E20: =C20-D20 -> -748658
B21: 04/HDKT/2021_Sửa chữa và thu hồi hệ thống chiếu sáng đường 2/9, đường Điện Biên Phủ và đường 30/4, phường 1 | C21: 44545455 | D21: 41716105 | E21: =C21-D21 -> 2829350
B22: 05/HDKT/2021_Di dời đường dây hạ thế trong khuôn viên Ủy ban nhân dân thị xã Duyên Hải | C22: 45090909 | D22: 30899642 | E22: =C22-D22 -> 14191267
B23: 06/HDKT/2021 Sửa chữa hệ thống chiếu sáng các tuyến đường trên địa bàn TX Duyên Hải | C23: 136363636 | D23: 118823345 | E23: =C23-D23 -> 17540291
... B39: 2021_Đóng, mở cầu dao các tuyến đường trên địa bàn thị xã Duyên Hải | C39: 30545455 | D39: 18300000 | E39: =C39-D39 -> 12245455
C40: =C11+C3 -> 10173716144 | D40: =D11+D3 -> 9173580226 | E40: =E11+E3 -> 1000135918
B41: Trà Vinh, ngày 31 tháng 12 năm 2020
B42: GIÁM ĐỐC

Sheet TINH THUE TNDN 2021
A1: CÔNG TY TNHH XD ĐIỆN MINH ĐẠT
A2: MST: 2100619679
A3: BẢNG XÁC ĐỊNH THU NHẬP CHỊU THUẾ TNDN NĂM 2021
A5: Doanh thu | B5: Tỉ lệ / DT | C5: Doanh thu | D5: Giá Vốn | E5: Chi Phí Quản Lý | F5: CHI PHÍ LÃI | G5: CP KHÔNG ĐƯỢC TRỪ | H5: Lợi nhuận | I5: Kết chuyển lỗ | J5: LN sau kết chuyển | K5: TS | L5: Thuế TNDN | M5: MIỄN 50% | N5: Số thuế phải nộp
A6: Địa bàn không ưu đãi | B6: =C6/C17 -> 0 | C6: =+C7 -> 0 | H6: =+B6*H17 -> 0 | K6: 0.2 | L6: =+K6*H6 -> 0 | M6: 0 | N6: =+L6-M6 -> 0
A8: DT ĐỊA BÀN ĐẶT BIỆT KHÓ KHĂN | B8: =C8/C17 -> 0.37600629 | C8: =SUM(C9:C12) -> 3833449931 | D8: =SUM(D9:D12) -> 3341983032 | E8: =E17*B8 -> 2.1877498e+08 | F8: =F17*B8 -> 48082994 | G8: =G17*B8 -> 5894064.9 | H8: =C8-D8-E8-F8+G8-G8+F8 -> 2.7269192e+08 | I8: 0 | J8: =H8-I8 -> 2.7269192e+08 | K8: 0.1 | L8: =J8*K8 -> 27269192 | M8: =L8*50% -> 13634596 | N8: =L8-M8 -> 13634596
A9: 5111 | N9: =L9-M9 -> 0
A10: 5112 | C10: ='BANG KE DOANH THU CT 2021'!C3 -> 3811991196 | D10: ='BANG KE DOANH THU CT 2021'!D3 -> 3341983032 | N10: =L10-M10 -> 0
A11: 5151 | C11: 63187 | N11: =L11-M11 -> 0
A12: 5152 | C12: 21395548 | N12: =L12-M12 -> 0
A13: DT ĐỊA BÀN KHÓ KHĂN | B13: =C13/C17 -> 0.62399371 | C13: =+C14+C15+C16 -> 6361724948 | D13: =SUM(D14:D16) -> 5831597194 | E13: =E17*B13 -> 3.6306363e+08 | F13: =F17*B13 -> 79795167 | G13: =G17*B13 -> 9781377.1 | H13: =C13-D13-E13-F13+G13-G13+F13 -> 1.6706413e+08 | I13: 0 | J13: =H13-I13 -> 1.6706413e+08 | K13: 0.17 | L13: =J13*K13 -> 28400902 | N13: =L13-M13 -> 28400902
A14: 5112 | C14: ='BANG KE DOANH THU CT 2021'!C11 -> 6361724948 | D14: ='BANG KE DOANH THU CT 2021'!D11 -> 5831597194
A15: 5151
A16: 5152
A17: Tổng cộng | B17: =B8+B13 -> 1 | C17: =C8+C13 -> 10195174879 | D17: =D8+D13 -> 9173580226 | E17: 581838604 | F17: 127878161 | G17: 15675442 | H17: =H8+H13 -> 439756049 | J17: =J8+J13 -> 439756049 | L17: =L8+L13 -> 55670094 | M17: =M8+M13 -> 13634596 | N17: =N13+N8 -> 42035498
H18: =+C17-#REF!-#REF!-#REF! -> #REF!
C19: 10793007946 | H19: 720227155 | M19: 74441349
C20: 454939007 | H20: =H19-H17 -> 280471106 | M20: =+M19-N17 -> 32405851
C21: 781954 | L21: 54680132
C22: =+C21+C20+C19 -> 11248728907 | L22: =+L21-L6 -> 54680132
L23: Trà Vinh, ngày 31 tháng 12 năm 2021 | P23: =N13*30% -> 8520270.5
A24: LẬP BẢNG | F24: =J17*20% -> 87951210 | L24: GIÁM ĐỐC
F25: =L8 -> 27269192
F26: =L13 -> 28400902 | P26: =N13-P23 -> 19880631
F27: =F25+F26 -> 55670094
F28: =F24-F27 -> 32281116 | M28: Nguyễn Thị Bước

Sheet BANG KE DT CT 2022
A1: BẢNG KÊ DOANH THU CÁC CÔNG TRÌNH NĂM 2022
A2: STT | B2: TÊN CÔNG TRÌNH | C2: DT THUẦN | D2: GIÁ THÀNH | E2: LỢI NHUẬN TRƯỚC PHÂN BỔ CPQL
B3: DOANH THU Ở ĐỊA BÀN ĐẶC BIỆT KHÓ KHĂN | C3: =SUM(C4:C8) -> 4199112539 | D3: =SUM(D4:D8) -> 4070594256 | E3: =SUM(E4:E8) -> 128518283
A4: DBKK-077 | B4: Gói thầu SPC-KfW3-W-BL2: Xây lắp đường dây và trạm biến áp phân phối các huyện Hoà Bình, Vĩnh Lợi, Phước Long, Đông Hải tỉnh Bạc Liêu thuộc dự án: Lưới điện hiệu quả tại các Thành phố vừa và nhỏ, sử dụng vốn vay ODA của chính Phủ Đức (DỰ án Thành 3 phần, GĐ 1, GĐ2) theo HĐ số 029/HĐXL | C4: 803905000 | D4: 707885000 | E4: =+C4-D4 -> 96020000
A5: DBKK-078 | B5: 2021_Thi công gói thầu SPC-2081CM-2021-05XL.1: Xây lắp đường dây trung, hạ áp, trạm biến áp và trụ móng đỡ nhánh rẽ vào nhà huyện Đầm Dơi , tỉnh Cà Mau theo Hợp đồng số 28/HĐ-XD ngày 01/10/2021 | C5: 1185236700 | D5: 1179236700 | E5: =+C5-D5 -> 6000000
B6: Gói thầu số 35: Thi công xây lắp một số tuyến ưu tiên địa bàn các huyện: Đông Hải, Phước Long, Hồng Dân và Hòa Binh (bao gồm chi phí nhà tạm) thuộc dự án: Cấp điện nông thôn từ lưới điện quốc gia tỉnh Bạc Liêu giai đoạn 2015-2020; Hạng mục: Nhân công xây dựng bao gồm lắp đặt trụ, cột, móng, trạm biến áp, lắp đặt biển báo và dán bảng tên trạm (bao gồm vật tư và công | C6: 1343244474 | D6: 1324454796 | E6: =+C6-D6 -> 18789678
B7: 2021_TCXDCT Gói thầu số 18: Thi công trạm biến áp thuộc dự án Xây dựng Khu liên hợp thể dục - thể thao tỉnh Bạc Liêu theo HĐ 46/2021/HĐ-XD | C7: 316726366 | D7: 313614760 | E7: =+C7-D7 -> 3111606
B8: 2022_TCXDCT Gói thầu số 18: Thi công trạm biến áp thuộc dự án Xây dựng Khu liên hợp thể dục - thể thao tỉnh Bạc Liêu theo HĐ 21/2021/HĐ-TC kí ngày 01/02/2022 | C8: 549999999 | D8: 545403000 | E8: =+C8-D8 -> 4596999
B9: ĐỊA BÀN KHÓ KHĂN | C9: =SUM(C10:C48) -> 12112920105 | D9: =SUM(D10:D48) -> 11310917362 | E9: =SUM(E10:E48) -> 802002743
B10: Sửa chữa hệ thống chiếu sáng QL53 (đoạn từ vòng xoay ngã 5 đến Nghĩa trang liệt sĩ) theo hợp đồng số 08/HĐKT - 2022 ngày 12/04/2022 | C10: 44696296 | D10: 21501516 | E10: =+C10-D10 -> 23194780
B11: Sửa chữa hệ thống chiếu sáng QL53 (đoạn từ cầu Láng Chim đến trường THCS Trường Long Hòa) theo hợp đồng số 07/HĐKT-2022 ngày 11/04/2022 | C11: 44864815 | D11: 18512833 | E11: =+C11-D11 -> 26351982
B12: Sửa chữa hệ thống chiếu sáng tuyến đường 3/2 nối dài, Phường 1, TX Duyên Hải theo hợp đồng số 15/HĐKT-2022 ngày 26/05/2022 | C12: 45833333 | D12: 28677872 | E12: =+C12-D12 -> 17155461
B13: Sửa chữa hệ thống chiếu sáng tuyến đường Ngô Quyền, P1, TX Duyên Hải theo hợp đồng số 14/HĐKT-2022 ngày 20/05/2022 | C13: 45740741 | D13: 24571654 | E13: =+C13-D13 -> 21169087
B14: Sửa chữa hệ thống chiếu sáng các tuyến đường trong khuôn viên chợ TX Duyên Hải theo hợp đồng số 16/HĐKT-2022 ký ngày 01/06/2022 | C14: 45462963 | D14: 26546783 | E14: =+C14-D14 -> 18916180
B15: Sửa chữa hệ thống chiếu sáng các tuyến đườngtrên địa bàn Phường 1 và xã Long Toàn, thị xãDuyên Hải theo hợp đồng số 18/HĐKT-2022ngày 07/6/2022 | C15: 41574074 | D15: 24291848 | E15: =+C15-D15 -> 17282226
B16: Thi công xây dựng Trạm biến áp 3x25KVAthuộc dự án Quảng trường thị xã Duyên Hải theo hợp đồng số 24/2022/ HĐ-TCXD ngày07/6/2022 | C16: 280133352 | D16: 260013988 | E16: =+C16-D16 -> 20119364
B17: Sửa chữa hệ thống chiếu sáng đường Lý TựTrọng, phường 1, thị xã Duyên Hải theo hợpđồng số 22/HĐKT-2022 ngày 19/7/2022 | C17: 91944444 | D17: 67624398 | E17: =+C17-D17 -> 24320046
B18: Sửa chữa hệ thống chiếu sáng các tuyến đườngPhường 1 và Phường 2, thị xã Duyên Hải theohợp đồng số 25/HĐKT-2022 ngày 29/7/2022 | C18: 45462963 | D18: 25253001 | E18: =+C18-D18 -> 20209962
B19: Sửa chữa hệ thống chiếu sáng các tuyến đườngPhường 1, thị xã Duyên Hải theo hợp đồng số32/HĐKT-2022 ngày 20/10/2022 | C19: 45611111 | D19: 25662949 | E19: =+C19-D19 -> 19948162
B20: Sửa chữa vỉa hè đường30/4 (đoạn từ đường Lý Tự Trọng đến đườngnhựa khóm 3), phường 1, thị xã Duyên Hải theohợp đồng số 29/2022/ HĐ-TC ngày 30/9/2022 | C20: 924073148 | D20: 889917491 | E20: =+C20-D20 -> 34155657
B21: Gói thầu số 05: Thi côngcông trình Sửa chữa cổng hoa các tuyến đườngtrên địa bàn phường 1, thị xã Duyên Hải theohợp đồng số 32/2022/HĐ-TC ký ngày07/10/2022 | C21: 921296296 | D21: 910337062 | E21: =+C21-D21 -> 10959234
... B48: Thi công công tác lắp đặt trụ đèn 14m, đèn trang trí, đi dây nguồn... theo hợp đồng số : 30/2022/HĐTký ngày 18/10/2022 | C48: 16203704 | D48: 12138137 | E48: =+C48-D48 -> 4065567
C49: =C9+C3 -> 16312032644 | D49: =D9+D3 -> 15381511618 | E49: =E9+E3 -> 930521026
B50: Trà Vinh, ngày 31 tháng 12 năm 2020
B51: GIÁM ĐỐC

Sheet TINH THUẾ TNDN 2022
A1: CÔNG TY TNHH XD ĐIỆN MINH ĐẠT
A2: MST: 2100619679
A3: BẢNG XÁC ĐỊNH THU NHẬP CHỊU THUẾ TNDN NĂM 2022
A5: Doanh thu | B5: Tỉ lệ / DT | C5: Doanh thu | D5: Giá Vốn | E5: Chi Phí Quản Lý | F5: CHI PHÍ LÃI | G5: CP KHÔNG ĐƯỢC TRỪ | H5: Lợi nhuận | I5: Kết chuyển lỗ | J5: LN sau kết chuyển | K5: TS | L5: Thuế TNDN | M5: MIỄN 50% | N5: Số thuế phải nộp
A6: Địa bàn không ưu đãi | B6: =C6/C17 -> 0 | C6: =+C7 -> 0 | H6: =+B6*H17 -> 0 | K6: 0.2 | L6: =+K6*H6 -> 0 | M6: 0 | N6: =+L6-M6 -> 0
A8: DT ĐỊA BÀN ĐẶT BIỆT KHÓ KHĂN | B8: =C8/C17 -> 0.25742658 | C8: =SUM(C9:C12) -> 4199163952 | D8: =SUM(D9:D12) -> 4070594256 | E8: =E17*B8 -> 1.4870887e+08 | F8: =F17*B8 -> 32670362 | G8: =G17*B8 -> 1236294.7 | H8: =C8-D8-E8-F8+G8-G8+F8 -> -20139176 | I8: 0 | J8: =H8-I8 -> -20139176 | K8: 0.1 | L8: =J8*K8 -> -2013917.6 | M8: =L8*50% -> -1006958.8 | N8: =L8-M8 -> -1006958.8
A9: 5111 | N9: =L9-M9 -> 0
A10: 5112 | C10: =+'BANG KE DT CT 2022'!C3 -> 4199112539 | D10: =+'BANG KE DT CT 2022'!D3 -> 4070594256 | N10: =L10-M10 -> 0
A11: 5151 | C11: 51413 | N11: =L11-M11 -> 0
A12: 711 | C12: 0 | N12: =L12-M12 -> 0
A13: DT ĐỊA BÀN KHÓ KHĂN | B13: =C13/C17 -> 0.74257342 | C13: =+C14+C15+C16 -> 12112920105 | D13: =SUM(D14:D16) -> 11310917362 | E13: =E17*B13 -> 4.2896603e+08 | F13: =F17*B13 -> 94241018 | G13: =G17*B13 -> 3566219.3 | H13: =C13-D13-E13-F13+G13-G13+F13 -> 3.7303671e+08 | I13: 0 | J13: =H13-I13 -> 3.7303671e+08 | K13: 0.17 | L13: =J13*K13 -> 63416241 | N13: =L13-M13 -> 63416241
A14: 5112 | C14: =+'BANG KE DT CT 2022'!C9 -> 12112920105 | D14: =+'BANG KE DT CT 2022'!D9 -> 11310917362
A15: 5151
A16: 711
A17: Tổng cộng | B17: =B8+B13 -> 1 | C17: =C8+C13 -> 16312084057 | D17: =D8+D13 -> 15381511618 | E17: 577674902 | F17: 126911380 | G17: 4802514 | H17: =H8+H13 -> 3.5289754e+08 | J17: =J8+J13 -> 3.5289754e+08 | L17: =L8+L13 -> 61402324 | M17: =M8+M13 -> -1006958.8 | N17: =N13+N8 -> 62409282
H19: =+H17*20% -> 70579507 | L19: =+H19-L17 -> 9177183.8
G20: =F17+G17 -> 131713894 | H20: =H19-L17 -> 9177183.8
L23: Trà Vinh, ngày 31 tháng 12 năm 2021 | P23: =N13*30% -> 19024872
A24: LẬP BẢNG | F24: =J17*20% -> 70579507 | L24: GIÁM ĐỐC
F25: =L8 -> -2013917.6
F26: =L13 -> 63416241 | P26: =N13-P23 -> 44391369
F27: =F25+F26 -> 61402324
F28: =F24-F27 -> 9177183.8 | M28: Nguyễn Thị Bước
D31: 10173716144 | F31: 381500000
D32: =D31-C17 -> -6138367913 | F32: =F31-70000000 -> 311500000

Sheet BANG KE DT CT 2023
A1: BẢNG KÊ DOANH THU CÁC CÔNG TRÌNH NĂM 2023
A2: STT | B2: TÊN CÔNG TRÌNH | C2: DT THUẦN | D2: GIÁ THÀNH | E2: LỢI NHUẬN TRƯỚC PHÂN BỔ CPQL
B3: DOANH THU Ở ĐỊA BÀN ĐẶC BIỆT KHÓ KHĂN | C3: =SUM(C4:C7) -> 1883780685 | D3: =SUM(D4:D7) -> 1429322325 | E3: =SUM(E4:E7) -> 454458360
A4: 1 | B4: Gói thầu số 35: Thi công xây lắp một số tuyến ưu tiên địa bàn các huyện: Đông Hải, Phước Long, Hồng Dân và Hòa Binh (bao gồm chi phí nhà tạm) thuộc dự án: Cấp điện nông thôn từ lưới điện quốc gia tỉnh Bạc Liêu giai đoạn 2015-2020; Hạng mục: Nhân công xây dựng bao gồm lắp đặt trụ, cột, móng, trạm biến áp, lắp đặt biển báo và dán bảng tên trạm (bao gồm vật tư và công | C4: 721932789 | D4: 607538412 | E4: =+C4-D4 -> 114394377
A5: 2 | B5: Sửa chữa hệ thống điện khu hành chính xã Long Toàn, thị xã Duyên Hải theo hợp đồng số 02/HĐKT-2023 ký ngày 02/02/2023 | C5: 41636364 | D5: 37886564 | E5: =+C5-D5 -> 3749800
B6: Sửa chữa, di dời cổng đèn hoa huyện Trà Cú theo hợp đồng số 53/2023/HĐ-XD ngày 04/10/2023 | C6: 447484259 | D6: 255104938 | E6: =+C6-D6 -> 192379321
A7: 3 | B7: Gói thầu số 04: Thi công xây dựng công trình Đường nhựa Giồng Ổi đến sông Lương Sen theo hợp đồng số 03/2023/HĐTCXD ngày 08/02/2023 | C7: 672727273 | D7: 528792411 | E7: =+C7-D7 -> 143934862
B8: ĐỊA BÀN KHÓ KHĂN | C8: =SUM(C9:C38) -> 13726818203 | D8: =SUM(D9:D38) -> 13015023429 | E8: =SUM(E9:E38) -> 711794774
B9: Sửa chữa hệ thống chiếu sáng vòng xoay ngã 5, thị xã Duyên Hải theo hợp đồng số 05/HĐKT2023 ngày 13/02/2023 | C9: 43909091 | D9: 35083587 | E9: =C9-D9 -> 8825504
B10: Dự án: Hạ tầng phục vụ nuôi trồng thủy sản các xã Dân Thành, Trường Long Hòa, thị xã Duyên Hải, tỉnh Trà Vinh. Hạng mục: Thi công xây dựng toàn bộ phần điện xã Trường Long Hòa HĐGK số 19/HĐGK/2023 ngày 22/03/2023 | C10: 3991569922 | D10: 3927952978 | E10: =C10-D10 -> 63616944
B11: Sửa chữa hệ thống chiếu sáng các tuyến đường xã Long Toàn, Phường 1, thị xã Duyên Hải theo hợp đồng số 46/HĐKT-2023 ngày 13/11/2023 | C11: 44314815 | D11: 29165347 | E11: =C11-D11 -> 15149468
B12: Gói thầu số 11: Muasắm, lắp đặt trang thiết bị thuộc dự án Xây dựngCông viên xã Trường Long Hòa theo hợp đồngsố 32/2023/HĐ-LĐTB ngày 11/7/2023 | C12: 665133409 | D12: 660378617 | E12: =C12-D12 -> 4754792
B13: Sửa chữa hệ thống chiếu sáng các tuyến đường thuộc các xã Long Toàn, xã Long Hữu và Trường Long Hòa, thị xã Duyên Hải theo hợp đồng số 37/HĐKT-2023 ngày 24/8/2023 | C13: 45740741 | D13: 45756260 | E13: =C13-D13 -> -15519
B14: Sửa chữa hệ thống chiếu sáng các tuyến đườngthuộc xã Dân Thành và Trường Long Hòa, thị xãDuyên Hải theo hợp đồng số 30/HĐKT-2023ngày 20/7/2023 | C14: 45925926 | D14: 44953362 | E14: =C14-D14 -> 972564
B15: Gói thầu số 07: Di dời hệ thống điện công trình Nâng cấp, mở rộng đường nhựa từ Ủy ban xã đến Quốc lộ 53 theo hợp đồng số 14/2023/HĐ-TCXD ký ngày 23/3/2023 | C15: 54545455 | D15: 20960594 | E15: =C15-D15 -> 33584861
B16: Gói thầu Thi công đènchiếu sáng các tuyến đường còn lại của dự ánthuộc công trình Hệ thống chiếu sáng xã LongĐức theo hợp đồng số 40 /2022/HĐXD ngày01/12/2022 | C16: 1565386364 | D16: 1434163094 | E16: =C16-D16 -> 131223270
B17: Gói thầu số 08: Thi công công trình sửa chữa, gắn hệ thống chiếu sáng thông minh các tuyến đường trên thị xã Duyên Hải theo HĐ số 45/2022/HDXD ngày 27/12/2022 | C17: 1925594960 | D17: 1919349957 | E17: =C17-D17 -> 6245003
B18: Thi công hạng mục: Kéo mới thêm 02 dây pha trên lưới điện trung thế 1 pha hiện hữu, xây dựng mới đường dây 22kV và TBA 3 pha - 2.000kVA Công ty Cổ phần Tân Tân Trà Vinh theo hợp đồng số 21- 03/2023/HĐKT/TTTV-ĐH ngày 21/3/2023 | C18: 862682418 | D18: 842708453 | E18: =C18-D18 -> 19973965 | F18: 25000000
B19: Sửa chữa hệ thống chiếu sáng các tuyến đường trên địa bàn thị xã Duyên Hải theo hợp đồng số 16/HĐKT-2023 ngày 05/5/2023 | C19: 188090909 | D19: 177559839 | E19: =C19-D19 -> 10531070
B20: Sửa chữa hệ thống chiếu sáng tuyến đườngvào Trung tâm Y tếthị xã Duyên Hải theo hợp đồng số 07/HĐKT2023 ngày 16/3/2023 | C20: 82909091 | D20: 74652579 | E20: =C20-D20 -> 8256512
B21: Sửa chữa hệ thống đường dây điện bị cắt trộm trên địa bàn thị xã Duyên Hải theo hợp đồng số 18/HĐKT-2023 ngày 22/5/2023 | C21: 106589091 | D21: 88779935 | E21: =C21-D21 -> 17809156
B22: Sửa chữa hệ thống đèn chiếu sáng trên địa bàn huyện theo hợp đồng 42/HĐKT/2023 ký ngày 05/9/2023 | C22: 45480556 | D22: 42065217 | E22: =C22-D22 -> 3415339
B23: Sửa chữa hệ thống đèn chiếu sáng trên địa bànhuyện theo hợp đồng 52/HĐKT/2023 ngày06/11/2023 | C23: 43433333 | D23: 31144544 | E23: =C23-D23 -> 12288789
B24: Sửa chữa hệ thống chiếu sáng các tuyến đường trên đại bàn thị xã Duyên Hải (Hạng mục: Phường 2 và các xã Dân Thành, Long Hữu, Trường Long hòa, Hiệp Thạnh) theo hợp đồng số 52/HĐKT-2023 ngày 13/12/2023 | C24: 44351852 | D24: 44231598 | E24: =C24-D24 -> 120254
B25: Sửa chữa hệ thống chiếu sáng tuyến đường khóm 3 và đường 2/9, phường 1, thị xã Duyên Hải theo họp đồng số 47/HĐKT-2023 ngày 23/11/2023 | C25: 41574074 | D25: 41626520 | E25: =C25-D25 -> -52446
B26: Gói thầu 06: Thi công di dời điện công trình Sân vận động xã Hiệp Thạnh theo hợp đồng số 52/2023/HĐ-TCXD ngày 20/12/2023 | C26: 92592593 | D26: 81705022 | E26: =C26-D26 -> 10887571
B27: Chi phí nhân công thi công lắp đặt thang máng cáp ,tủ điện, kéo dây, đấu nối Dự án: NHÀ XƯỞNG SẢN XUẤT BÌNH KHÍ ĐỐT HONG VINA theo biên bản nghiệm thu khối lượng hoàn thành ngày 27/12/2023 của hợp đồng số 0806.2023/HĐGK/DXMD ngày 08 tháng 06 năm 2023 | C27: 278463219 | D27: 220050887 | E27: =C27-D27 -> 58412332 | F27: 20000000
B28: Sửa chữa đèn tín hiệu giao thông vị trí nút giao QL53 với đường 2/9, phường 1 thị xã DuyênHải theo hợp đồng số 41/HĐKT-2023 ngày15/11/2023 | C28: 46279630 | D28: 45190420 | E28: =C28-D28 -> 1089210
B29: Sửa chữa hệ thống đèn chiếu sáng trên địa bàn huyện theo hợp đồng số 58/HĐKT/2023 ký ngày15/12/2023 | C29: 75000000 | D29: 69715361 | E29: =C29-D29 -> 5284639
B30: Sửa chữa hệ thống đèn chiếu sáng trên địa bànhuyện theo hợp đồng số 62/HĐKT/2023 ký ngày20/12/2023 | C30: 26962963 | D30: 19193158 | E30: =C30-D30 -> 7769805
B31: Sửa chữa hệ thống chiếu sáng các tuyến đường thuộc phường 1, phường 2 và xã Long Toàn, thị xã Duyên Hải theo hợp đồng số 31/HĐKT-2023 ngày 27/7/2023 | C31: 44537037 | D31: 44092426 | E31: =C31-D31 -> 444611
B32: Sửa chữa hệ thống chiếu sáng các tuyến đường trên địa bàn thị xã Duyên Hải (Hạng mục: Phường 2 và các xã Dân Thành, Long Hữu, Long Toàn) theo hợp đồng số 29/HĐKT-2023 ngày 30/6/2023 | C32: 44644444 | D32: 35532365 | E32: =C32-D32 -> 9112079
B33: Sửa chữa hệ thống chiếu sáng các tuyến đườngtrên đại bàn thị xã Duyên Hải (Hạng mục:Phường 1 và các xã Dân Thành, Trường LongHòa) theo hợp đồng số 22/HĐKT-2023 ngày20/6/2023 | C33: 44363636 | D33: 27760596 | E33: =C33-D33 -> 16603040
B34: Thi công xây dựng công trình điện và cung cấp vật tư phụ Gói thầu SPC-KfW3.2-W-TV - Xây lắp đường dây và trạm biến áp phân phối tỉnh Trà Vinh - khu vực huyện Duyên Hải - Trà Vinh theo phụ lục 01-12.6/2022/HĐKT-PN-MĐ của hợp đồng 12.6/2022/HĐKT-PN-MĐ ký ngày 06/12/2022 | C34: 718533980 | D34: 690537036 | E34: =C34-D34 -> 27996944
B35: Thi công hạng mục công trình: "đường dây 22kV" - Trạm biến áp 220kV Duyên Hải - Trà Vinh theo hợp đồng số 44/2022/HĐXL/SĐ-MĐ ngày 14/11/2022 | C35: 261328074 | D35: 191658073 | E35: =C35-D35 -> 69670001
B36: Doanh thu xe cẩu dựng trụ | C36: 4500000 | D36: 3813036 | E36: =C36-D36 -> 686964
B37: Doanh thu công trình: Thi công công tác lắp đặt trụ đèn 14m, đèn trang trí, đi dây nguồn...theo hợp đồng số: 30/2022/HĐT ký ngày 18/10/2022 | C37: 6944444 | D37: 5200000 | E37: =C37-D37 -> 1744444
B38: Doanh thu bán gạch+ đèn năng lượng mặt trời | C38: 2285436176 | D38: 2120042568 | E38: =C38-D38 -> 165393608
C39: =C8+C3 -> 15610598888 | D39: =D8+D3 -> 14444345754 | E39: =E8+E3 -> 1166253134
B40: Trà Vinh, ngày 31 tháng 12 năm 2020
...

Sheet TIN THUE TNDN 2023
A1: CÔNG TY TNHH XD ĐIỆN MINH ĐẠT
A2: MST: 2100619679
A3: BẢNG XÁC ĐỊNH THU NHẬP CHỊU THUẾ TNDN NĂM 2023
A5: Doanh thu | B5: Tỉ lệ / DT | C5: Doanh thu | D5: Giá Vốn | E5: Chi Phí Quản Lý | F5: CHI PHÍ LÃI | G5: CP KHÔNG ĐƯỢC TRỪ | H5: Lợi nhuận | I5: Kết chuyển lỗ | J5: LN sau kết chuyển | K5: TS | L5: Thuế TNDN | M5: MIỄN 50% | N5: Số thuế phải nộp
A6: Địa bàn không ưu đãi | B6: =C6/C17 -> 0 | C6: =+C7 -> 0 | H6: =+B6*H17 -> 0 | K6: 0.2 | L6: =+K6*H6 -> 0 | M6: 0 | N6: =+L6-M6 -> 0
A8: DT ĐỊA BÀN ĐẶT BIỆT KHÓ KHĂN | B8: =C8/C17 -> 0.12068745 | C8: =SUM(C9:C12) -> 1884033909 | D8: =SUM(D9:D12) -> 1429322325 | E8: =E17*B8 -> 57241526 | F8: =F17*B8 -> 16462811 | G8: =G17*B8 -> 1777968.6 | H8: =C8-D8-E8-F8-G8+F8+G8 -> 3.9747006e+08 | I8: 0 | J8: =H8-I8 -> 3.9747006e+08 | K8: 0.1 | L8: =J8*K8 -> 39747006 | M8: =L8*50% -> 19873503 | N8: =L8-M8 -> 19873503
A9: 5111 | N9: =L9-M9 -> 0
A10: 5112 | C10: ='BANG KE DT CT 2023'!C3 -> 1883780685 | D10: ='BANG KE DT CT 2023'!D3 -> 1429322325 | N10: =L10-M10 -> 0
A11: 5151 | C11: 253224 | N11: =L11-M11 -> 0
A12: 711 | C12: 0 | N12: =L12-M12 -> 0
A13: DT ĐỊA BÀN KHÓ KHĂN | B13: =C13/C17 -> 0.87931255 | C13: =+C14+C15+C16 -> 13726818203 | D13: =SUM(D14:D16) -> 13015023429 | E13: =E17*B13 -> 4.1705408e+08 | F13: =F17*B13 -> 1.1994583e+08 | G13: =G17*B13 -> 12954040 | H13: =C13-D13-E13-F13-G13+G13+F13 -> 2.9474069e+08 | I13: 0 | J13: =H13-I13 -> 2.9474069e+08 | K13: 0.17 | L13: =J13*K13 -> 50105918 | N13: =L13-M13 -> 50105918
A14: 5112 | C14: ='BANG KE DT CT 2023'!C8 -> 13726818203 | D14: ='BANG KE DT CT 2023'!D8 -> 13015023429
A15: 5151
A16: 51111
A17: Tổng cộng | B17: =B8+B13 -> 1 | C17: =C8+C13 -> 15610852112 | D17: =D8+D13 -> 14444345754 | E17: 474295606 | F17: 136408642 | G17: 14732009 | H17: =H8+H13 -> 692210752 | J17: =J8+J13 -> 692210752 | L17: =L8+L13 -> 89852924 | M17: =M8+M13 -> 19873503 | N17: =N13+N8 -> 69979421
H20: =F17+G17 -> 151140651
C21: 15610598888 | J21: =J17*20% -> 1.3844215e+08
C22: =C21-C17 -> -253224 | J22: =J21-L17 -> 48589227
L23: Trà Vinh, ngày 31 tháng 12 năm 2021 | P23: =N13*30% -> 15031775
A24: LẬP BẢNG | L24: GIÁM ĐỐC
P26: =N13-P23 -> 35074143
A28: =C29-C28 -> 0 | M28: Nguyễn Thị Bước
