Workbook

Sheet THONG TIN
A3: Tên doanh nghiệp: | C3: Công ty TNHH Thuận An
A4: Trụ sở chính : | C4: Ấp Chồng Nô 3, Xã Hòa Tân, Huyện Cầu Kè, Tỉnh Trà Vinh
A5: Mã số thuế : | C5: 2 1 0 0 4 0 6 8 1 8

Sheet  SL 2020
A1: Tên doanh nghiệp: | C1: ='THONG TIN'!C3 -> Công ty TNHH Thuận An
A2: Trụ sở chính: | C2: ='THONG TIN'!C4 -> Ấp Chồng Nô 3, Xã Hòa Tân, Huyện Cầu Kè, Tỉnh Trà Vinh
A3: BẢNG BÁO CÁO SẢN LƯỢNG SẢN XUẤT VÀ TIÊU THỤ ĐIỆN SOLAR
A4: HÒA TÂN
B5: Công suất dự án : | D5: 62,3 Kw | E5: Năm | F5: 2020
A7: Thời gian | C7: Sản lượng phát | D7: Sản lượng bán | E7: Sản lượng phát bỏ | F7: Sản lượng tiêu dùng
A8: Tháng 1
A9: Tháng 2
A10: Tháng 3
A11: Quý I | C11: =SUM(C8:C10) -> 0
A12: Tháng 4
A13: Tháng 5
A14: Tháng 6
A15: Quý II | C15: =SUM(C12:C14) -> 0
A16: Tháng 7
A17: Tháng 8
A18: Tháng 9
A19: Quý III | C19: =SUM(C16:C18) -> 0
A20: Tháng 10
A21: Tháng 11 | C21: =5800+4750 -> 10550 | E21: 40 | F21: 180
A22: Tháng 12 | C22: =5360+3570 -> 8930 | D22: 12650 | E22: 30 | F22: 150 | G22: Hóa đơn Số 3 | H22: =D22*1940 -> 24541000
A23: Quý IV | C23: =SUM(C20:C22) -> 19480 | G23: =C23-E21-D22-E22-F21-F22 -> 6430 | H23: Hóa đơn Số 7
A25: Hướng dẫn | C25: Sản lượng phát ghi số liệu từ phần mềm quản lý Solar
C26: Sản lượng bán ghi số liệu từ cơ quan điện lực chốt sổ + SL nội suy đến cuối cuối tháng
C27: Sản lượng phát bỏ ghi nhận điện lực không mua và những ngày cúp điện
C28: Sản lượng tiêu dùng là chênh lệch còn lại
A31: Tên doanh nghiệp: | C31: ='THONG TIN'!C3 -> Công ty TNHH Thuận An
A32: Trụ sở chính: | C32: ='THONG TIN'!C4 -> Ấp Chồng Nô 3, Xã Hòa Tân, Huyện Cầu Kè, Tỉnh Trà Vinh
A33: BẢNG BÁO CÁO SẢN LƯỢNG SẢN XUẤT VÀ TIÊU THỤ ĐIỆN SOLAR
A34: HÒA ÂN
B35: Công suất dự án : | D35: 142,4 Kw | E35: Năm | F35: 2020
A37: Thời gian | C37: Sản lượng phát | D37: Sản lượng bán | E37: Sản lượng phát bỏ | F37: Sản lượng tiêu dùng
A38: Tháng 1
A39: Tháng 2
A40: Tháng 3
A41: Quý I | C41: =SUM(C38:C40) -> 0
A42: Tháng 4
A43: Tháng 5
A44: Tháng 6
A45: Quý II | C45: =SUM(C42:C44) -> 0
...

Sheet 11 2020
A1: ='THONG TIN'!C3 -> Công ty TNHH Thuận An | E1: Mẫu số : S 25 - SKT/DNN
A2: ='THONG TIN'!C4 -> Ấp Chồng Nô 3, Xã Hòa Tân, Huyện Cầu Kè, Tỉnh Trà Vinh | E2: Ban hành theo quyết định số
E3: 133/2016/TT-BTC ngày 14/06/2016
E4: của bộ tài chính
A6: THẺ TÍNH GIÁ THÀNH SẢN PHẨM
A7: Tháng 11/2020
B8: ĐỊA ĐIỂM : | C8: HÒA TÂN
B9: Tên sản phẩm , dịch vụ : Điện năng lượng mặt trời
B10: Số lượng sản phẩm , dịch vụ hoàn thành trong kỳ : | E10: =' SL 2020'!C21 -> 10550
B11: Phương pháp tính giá thành : Giá thành thực tế
A13: Khoản mục chi phí sản xuất kinh doanh | B13: Chi phí SXKD dở dang đầu kỳ | C13: Chi phí SXKD phát sinh trong kỳ | D13: Chi phí SXKD dở dang cuối kỳ | E13: Giá thành sản phẩm dịch vụ trong kỳ
E14: Giá thành | F14: Giá thành đơn vị
A15: 1. Vật liệu
A17: 2. Nhân công
A19: 3. Máy
A21: 4. Chi phí chung
A22: Chi phí khấu hao hệ thống pin năng lượng mặt trời | C22: =11541233+(B22/12) -> 11541233 | D22: =B22-(B22/12)*2 -> 0 | E22: =B22+C22-D22 -> 11541233 | F22: =E22/E10 -> 1093.9557
A24: Cộng | B24: =B22 -> 0 | C24: =C22 -> 11541233 | D24: =D22 -> 0 | E24: =E22 -> 11541233 | F24: =F22 -> 1093.9557
A26: Người ghi sổ | C26: Kế toán trưởng | E26: Giám đốc
A27: (Ký , họ tên) | C27: (Ký , họ tên) | E27: (Ký , họ tên,đóng dấu)
A28: =A1 -> Công ty TNHH Thuận An | E28: Mẫu số : S 25 - SKT/DNN
A29: =A2 -> Ấp Chồng Nô 3, Xã Hòa Tân, Huyện Cầu Kè, Tỉnh Trà Vinh | E29: Ban hành theo quyết định số
E30: 133/2016/TT-BTC ngày 14/06/2016
E31: của bộ tài chính
A33: THẺ TÍNH GIÁ THÀNH SẢN PHẨM
A34: Tháng 11/2020
B35: ĐỊA ĐIỂM : | C35: HÒA ÂN
B36: Tên sản phẩm , dịch vụ : Điện năng lượng mặt trời
B37: Số lượng sản phẩm , dịch vụ hoàn thành trong kỳ : | E37: 0
B38: Phương pháp tính giá thành : Giá thành thực tế
A40: Khoản mục chi phí sản xuất kinh doanh | B40: Chi phí SXKD dở dang đầu kỳ | C40: Chi phí SXKD phát sinh trong kỳ | D40: Chi phí SXKD dở dang cuối kỳ | E40: Giá thành sản phẩm dịch vụ trong kỳ
E41: Giá thành | F41: Giá thành đơn vị
A42: 1. Vật liệu
A44: 2. Nhân công
A46: 3. Máy
A48: 4. Chi phí chung
A49: Chi phí khấu hao hệ thống pin năng lượng mặt trời | D49: =B49-(B49/12)*2 -> 0 | E49: =B49+C49-D49 -> 0
A51: Cộng | B51: =SUM(B49) -> 0 | C51: =SUM(C49) -> 0 | D51: =SUM(D49) -> 0 | E51: =SUM(E49) -> 0 | F51: =SUM(F49) -> 0
A53: Người ghi sổ | C53: Kế toán trưởng | E53: Giám đốc
A54: (Ký , họ tên) | C54: (Ký , họ tên) | E54: (Ký , họ tên,đóng dấu)

Sheet 12 2020
A1: ='THONG TIN'!C3 -> Công ty TNHH Thuận An | E1: Mẫu số : S 25 - SKT/DNN
A2: ='THONG TIN'!C4 -> Ấp Chồng Nô 3, Xã Hòa Tân, Huyện Cầu Kè, Tỉnh Trà Vinh | E2: Ban hành theo quyết định số
E3: 133/2016/TT-BTC ngày 14/06/2016
E4: của bộ tài chính
A6: THẺ TÍNH GIÁ THÀNH SẢN PHẨM
A7: Tháng 12/2020
B8: ĐỊA ĐIỂM : | C8: HÒA TÂN
B9: Tên sản phẩm , dịch vụ : Điện năng lượng mặt trời
B10: Số lượng sản phẩm , dịch vụ hoàn thành trong kỳ : | E10: =' SL 2020'!C22 -> 8930
B11: Phương pháp tính giá thành : Giá thành thực tế
A13: Khoản mục chi phí sản xuất kinh doanh | B13: Chi phí SXKD dở dang đầu kỳ | C13: Chi phí SXKD phát sinh trong kỳ | D13: Chi phí SXKD dở dang cuối kỳ | E13: Giá thành sản phẩm dịch vụ trong kỳ
E14: Giá thành | F14: Giá thành đơn vị
A15: 1. Vật liệu
A17: 2. Nhân công
A19: 3. Máy
A21: 4. Chi phí chung
A22: Chi phí khấu hao hệ thống pin năng lượng mặt trời | C22: =12823592+(B22/12) -> 12823592 | D22: =B22-(B22/12)*2 -> 0 | E22: =B22+C22-D22 -> 12823592 | F22: =E22/E10 -> 1436.0125
A24: Cộng | B24: =B22 -> 0 | C24: =C22 -> 12823592 | D24: =D22 -> 0 | E24: =E22 -> 12823592 | F24: =F22 -> 1436.0125
A26: Người ghi sổ | C26: Kế toán trưởng | E26: Giám đốc
A27: (Ký , họ tên) | C27: (Ký , họ tên) | E27: (Ký , họ tên,đóng dấu)
A28: =A1 -> Công ty TNHH Thuận An | E28: Mẫu số : S 25 - SKT/DNN
A29: =A2 -> Ấp Chồng Nô 3, Xã Hòa Tân, Huyện Cầu Kè, Tỉnh Trà Vinh | E29: Ban hành theo quyết định số
E30: 133/2016/TT-BTC ngày 14/06/2016
E31: của bộ tài chính
A33: THẺ TÍNH GIÁ THÀNH SẢN PHẨM
A34: Tháng 12/2020
B35: ĐỊA ĐIỂM : | C35: HÒA ÂN
B36: Tên sản phẩm , dịch vụ : Điện năng lượng mặt trời
B37: Số lượng sản phẩm , dịch vụ hoàn thành trong kỳ : | E37: =' SL 2020'!C52 -> 14000
B38: Phương pháp tính giá thành : Giá thành thực tế
A40: Khoản mục chi phí sản xuất kinh doanh | B40: Chi phí SXKD dở dang đầu kỳ | C40: Chi phí SXKD phát sinh trong kỳ | D40: Chi phí SXKD dở dang cuối kỳ | E40: Giá thành sản phẩm dịch vụ trong kỳ
E41: Giá thành | F41: Giá thành đơn vị
A42: 1. Vật liệu
A44: 2. Nhân công
A46: 3. Máy
A48: 4. Chi phí chung
A49: Chi phí khấu hao hệ thống pin năng lượng mặt trời | C49: =17159650+(B49/12) -> 17159650 | D49: =B49-(B49/12)*2 -> 0 | E49: =B49+C49-D49 -> 17159650 | F49: =E49/E37 -> 1225.6893
A51: Cộng | B51: =B49 -> 0 | C51: =C49 -> 17159650 | D51: =D49 -> 0 | E51: =E49 -> 17159650 | F51: =F49 -> 1225.6893
A53: Người ghi sổ | C53: Kế toán trưởng | E53: Giám đốc
A54: (Ký , họ tên) | C54: (Ký , họ tên) | E54: (Ký , họ tên,đóng dấu)

Sheet SL 2021
A1: Tên doanh nghiệp: | C1: ='THONG TIN'!C3 -> Công ty TNHH Thuận An
A2: Trụ sở chính: | C2: ='THONG TIN'!C4 -> Ấp Chồng Nô 3, Xã Hòa Tân, Huyện Cầu Kè, Tỉnh Trà Vinh
A3: BẢNG BÁO CÁO SẢN LƯỢNG SẢN XUẤT VÀ TIÊU THỤ ĐIỆN SOLAR
A4: HÒA TÂN
B5: Công suất dự án : | D5: 62,3 Kw | E5: Năm | F5: 2021
A7: Thời gian | C7: Sản lượng phát | D7: Sản lượng bán | E7: Sản lượng phát bỏ | F7: Sản lượng tiêu dùng | I7: Giá thành
A8: Sản lượng còn lại 12/2020 | C8: 6430
A9: Tháng 1 | C9: 11212.59 | D9: =6430+2180 -> 8610 | E9: 30 | F9: 175 | G9: Hóa đơn Số 7 + 9 | I9: ='T1'!F23 -> 1263.497
A10: Tháng 2 | C10: 11393.189 | D10: 11170 | E10: 35 | F10: 185 | G10: Hóa đơn Số 12 | I10: ='T2'!F23 -> 1243.5348
A11: Tháng 3 | C11: 12848.297 | D11: 12090 | E11: 40 | F11: 160 | G11: Hóa đơn Số 16 | I11: ='T3'!F23 -> 1102.708
A12: Quý I | C12: =SUM(C8:C11) -> 41884.076 | D12: =SUM(D9:D11) -> 31870 | E12: =SUM(E9:E11) -> 105 | F12: =SUM(F9:F11) -> 520
A13: Tháng 4 | C13: 8973.1682 | D13: 11500 | E13: 30 | F13: 155 | G13: Hóa đơn Số 17 | I13: ='T4'!F23 -> 1578.9136
A14: Tháng 5 | C14: 7781.2178 | D14: 8430 | E14: 34 | F14: 150 | G14: Hóa đơn Số 21 | I14: ='T5'!F23 -> 1820.7932
A15: Tháng 6 | C15: 8034.0557 | D15: 7510 | E15: 45 | F15: 170 | G15: Hóa đơn Số 26 | I15: ='T6'!F23 -> 1763.4543
A16: Quý II | C16: =SUM(C13:C15) -> 24788.442 | D16: =SUM(D13:D15) -> 27440 | E16: =SUM(E13:E15) -> 109 | F16: =SUM(F13:F15) -> 475
A17: Tháng 7 | C17: 7254.902 | D17: 7870 | E17: 42 | F17: 150 | G17: Hóa đơn Số 27 | I17: ='T7'!F23 -> 1952.8039
A18: Tháng 8 | C18: 8271.4138 | D18: 7090 | E18: 35 | F18: 200 | G18: Hóa đơn Số 29 | I18: ='T8'!F23 -> 1712.9237
A19: Tháng 9 | C19: 7105.2632 | D19: 7090 | E19: 44 | F19: 196 | G19: Hóa đơn Số 32 | I19: ='T9'!F23 -> 1994.0312
A20: Quý III | C20: =SUM(C17:C19) -> 22631.579 | D20: =SUM(D17:D19) -> 22050 | E20: =SUM(E17:E19) -> 121 | F20: =SUM(F17:F19) -> 546
A21: Tháng 10 | C21: 7285.8617 | D21: 7830 | E21: 48 | F21: 202 | G21: Hóa đơn Số 36 | I21: ='T10'!F23 -> 1944.4952
A22: Tháng 11 | C22: 6744.066 | D22: 7680 | E22: 45 | F22: 200 | G22: Hóa đơn Số 40 | I22: ='T11'!F23 -> 2100.7699
A23: Tháng 12 | C23: 7621.259 | D23: =6330+5160 -> 11490 | E23: 43 | F23: 180 | G23: Hóa đơn Số 43 + Hóa đơn Số 48 | I23: ='T12'!F23 -> 1859.0201
A24: Quý IV | C24: =SUM(C21:C23) -> 21651.187 | D24: =SUM(D21:D23) -> 27000 | E24: =SUM(E21:E23) -> 136 | F24: =SUM(F21:F23) -> 582
C25: =C12+C16+C20+C24 -> 110955.28 | D25: =D12+D16+D20+D24 -> 108360 | E25: =SUM(E12+E16+E20+E24) -> 471 | F25: =SUM(F12+F16+F20+F24) -> 2123 | G25: =E25+F25 -> 2594 | H25: =C25-D25 -> 2595.2838
A27: Hướng dẫn | C27: Sản lượng phát ghi số liệu từ phần mềm quản lý Solar
C28: Sản lượng bán ghi số liệu từ cơ quan điện lực chốt sổ + SL nội suy đến cuối cuối tháng
C29: Sản lượng phát bỏ ghi nhận điện lực không mua và những ngày cúp điện
C30: Sản lượng tiêu dùng là chênh lệch còn lại
A34: Tên doanh nghiệp: | C34: ='THONG TIN'!C3 -> Công ty TNHH Thuận An
A35: Trụ sở chính: | C35: ='THONG TIN'!C4 -> Ấp Chồng Nô 3, Xã Hòa Tân, Huyện Cầu Kè, Tỉnh Trà Vinh
A36: BẢNG BÁO CÁO SẢN LƯỢNG SẢN XUẤT VÀ TIÊU THỤ ĐIỆN SOLAR
A37: HÒA ÂN
B38: Công suất dự án : | D38: 142,4 Kw | E38: Năm | F38: 2021
A40: Thời gian | C40: Sản lượng phát | D40: Sản lượng bán | E40: Sản lượng phát bỏ | F40: Sản lượng tiêu dùng | I40: Giá thành
A41: Sản lượng còn lại 12/2020 | C41: 14000
A42: Tháng 1 | C42: 18500 | D42: =9124+4674 -> 13798 | E42: 50 | G42: Hóa đơn Số 6+ 8 | I42: ='T1'!F50 -> 1062.4676
A43: Tháng 2 | C43: 19000 | D43: 18336 | E43: 45 | G43: Hóa đơn Số 13 | I43: ='T2'!F50 -> 1034.5079
A44: Tháng 3 | C44: 17000 | D44: 16631 | E44: 60 | G44: Hóa đơn Số 15 | I44: ='T3'!F51 -> 1204.8016
A45: Quý I | C45: =SUM(C41:C44) -> 68500 | D45: =SUM(D41:D44) -> 48765 | E45: =SUM(E42:E44) -> 155
A46: Tháng 4 | C46: =6540+3690 -> 10230 | D46: 22267 | E46: 54 | G46: Hóa đơn Số 19 | I46: ='T4'!F51 -> 2002.1142
...

Sheet T1
A1: ='THONG TIN'!C3 -> Công ty TNHH Thuận An | E1: Mẫu số : S 25 - SKT/DNN
A2: ='THONG TIN'!C4 -> Ấp Chồng Nô 3, Xã Hòa Tân, Huyện Cầu Kè, Tỉnh Trà Vinh | E2: Ban hành theo quyết định số
E3: 133/2016/TT-BTC ngày 14/06/2016
E4: của bộ tài chính
A5: THẺ TÍNH GIÁ THÀNH SẢN PHẨM
A6: Tháng 1/2021
B7: ĐỊA ĐIỂM : | C7: HÒA TÂN
B8: Tên sản phẩm , dịch vụ : Điện năng lượng mặt trời
B9: Số lượng sản phẩm , dịch vụ hoàn thành trong kỳ : | E9: 11213
B10: Phương pháp tính giá thành : Giá thành thực tế
A12: Khoản mục chi phí sản xuất kinh doanh | B12: Chi phí SXKD dở dang đầu kỳ | C12: Chi phí SXKD phát sinh trong kỳ | D12: Chi phí SXKD dở dang cuối kỳ | E12: Giá thành sản phẩm dịch vụ trong kỳ
E13: Giá thành | F13: Giá thành đơn vị
A14: 1. Vật liệu
A16: 2. Nhân công | C16: =16128000/12 -> 1344000 | E16: =C16 -> 1344000 | F16: =E16/E9 -> 119.86088
A18: 3. Máy
A20: 4. Chi phí chung
A21: Chi phí khấu hao hệ thống pin năng lượng mặt trời | C21: =12823592+(B21/12) -> 12823592 | D21: =B21-(B21/12) -> 0 | E21: =B21+C21-D21 -> 12823592 | F21: =E21/E9 -> 1143.6361
A23: Cộng | B23: =B21+B22 -> 0 | C23: =C21+C22 -> 12823592 | D23: =D21+D22 -> 0 | E23: =E21+E22 -> 12823592 | F23: =F16+F21 -> 1263.497
A25: Người ghi sổ | C25: Kế toán trưởng | E25: Giám đốc
A26: (Ký , họ tên) | C26: (Ký , họ tên) | E26: (Ký , họ tên,đóng dấu)
A28: =A1 -> Công ty TNHH Thuận An | E28: Mẫu số : S 25 - SKT/DNN
A29: =A2 -> Ấp Chồng Nô 3, Xã Hòa Tân, Huyện Cầu Kè, Tỉnh Trà Vinh | E29: Ban hành theo quyết định số
E30: 133/2016/TT-BTC ngày 14/06/2016
E31: của bộ tài chính
A32: THẺ TÍNH GIÁ THÀNH SẢN PHẨM
A33: Tháng 1/2021
B34: ĐỊA ĐIỂM : | C34: HÒA ÂN
B35: Tên sản phẩm , dịch vụ : Điện năng lượng mặt trời
B36: Số lượng sản phẩm , dịch vụ hoàn thành trong kỳ : | E36: 18500
B37: Phương pháp tính giá thành : Giá thành thực tế
A39: Khoản mục chi phí sản xuất kinh doanh | B39: Chi phí SXKD dở dang đầu kỳ | C39: Chi phí SXKD phát sinh trong kỳ | D39: Chi phí SXKD dở dang cuối kỳ | E39: Giá thành sản phẩm dịch vụ trong kỳ
E40: Giá thành | F40: Giá thành đơn vị
A41: 1. Vật liệu
A43: 2. Nhân công | C43: =29952000/12 -> 2496000 | E43: =C43 -> 2496000 | F43: =E43/E36 -> 134.91892
A45: 3. Máy
A47: 4. Chi phí chung
A48: Chi phí khấu hao hệ thống pin năng lượng mặt trời | C48: =17159650+(B48/12) -> 17159650 | D48: =B48-(B48/12)*3 -> 0 | E48: =B48+C48-D48 -> 17159650 | F48: =E48/E36 -> 927.54865
A49: Chi phí khấu hao sửa chửa hệ thống ĐMT | C49: =(0*1)+(B49/12)*1 -> 0 | E49: =B49+C49-D49 -> 0 | F49: =E49/E36 -> 0
A50: Cộng | B50: =B48+B49 -> 0 | C50: =C48+C49 -> 17159650 | D50: =D48+D49 -> 0 | E50: =E48+E49 -> 17159650 | F50: =F43+F48+F49 -> 1062.4676
A52: Người ghi sổ | C52: Kế toán trưởng | E52: Giám đốc
...

Sheet T2
A1: ='THONG TIN'!C3 -> Công ty TNHH Thuận An | E1: Mẫu số : S 25 - SKT/DNN
A2: ='THONG TIN'!C4 -> Ấp Chồng Nô 3, Xã Hòa Tân, Huyện Cầu Kè, Tỉnh Trà Vinh | E2: Ban hành theo quyết định số
E3: 133/2016/TT-BTC ngày 14/06/2016
E4: của bộ tài chính
A5: THẺ TÍNH GIÁ THÀNH SẢN PHẨM
A6: Tháng 2/2021
B7: ĐỊA ĐIỂM : | C7: HÒA TÂN
B8: Tên sản phẩm , dịch vụ : Điện năng lượng mặt trời
B9: Số lượng sản phẩm , dịch vụ hoàn thành trong kỳ : | E9: 11393
B10: Phương pháp tính giá thành : Giá thành thực tế
A12: Khoản mục chi phí sản xuất kinh doanh | B12: Chi phí SXKD dở dang đầu kỳ | C12: Chi phí SXKD phát sinh trong kỳ | D12: Chi phí SXKD dở dang cuối kỳ | E12: Giá thành sản phẩm dịch vụ trong kỳ
E13: Giá thành | F13: Giá thành đơn vị
A14: 1. Vật liệu
A16: 2. Nhân công | C16: =16128000/12 -> 1344000 | E16: =C16 -> 1344000 | F16: =E16/E9 -> 117.96717
A18: 3. Máy
A20: 4. Chi phí chung
A21: Chi phí khấu hao hệ thống pin năng lượng mặt trời | C21: =12823592+(B21/12) -> 12823592 | D21: =B21-(B21/12)*3 -> 0 | E21: =B21+C21-D21 -> 12823592 | F21: =E21/E9 -> 1125.5676
A23: Cộng | B23: =B21+B22 -> 0 | C23: =C21+C22 -> 12823592 | D23: =D21+D22 -> 0 | E23: =E21+E22 -> 12823592 | F23: =F16+F21 -> 1243.5348
A25: Người ghi sổ | C25: Kế toán trưởng | E25: Giám đốc
A26: (Ký , họ tên) | C26: (Ký , họ tên) | E26: (Ký , họ tên,đóng dấu)
A28: =A1 -> Công ty TNHH Thuận An | E28: Mẫu số : S 25 - SKT/DNN
A29: =A2 -> Ấp Chồng Nô 3, Xã Hòa Tân, Huyện Cầu Kè, Tỉnh Trà Vinh | E29: Ban hành theo quyết định số
E30: 133/2016/TT-BTC ngày 14/06/2016
E31: của bộ tài chính
A32: THẺ TÍNH GIÁ THÀNH SẢN PHẨM
A33: Tháng 2/2021
B34: ĐỊA ĐIỂM : | C34: HÒA ÂN
B35: Tên sản phẩm , dịch vụ : Điện năng lượng mặt trời
B36: Số lượng sản phẩm , dịch vụ hoàn thành trong kỳ : | E36: 19000
B37: Phương pháp tính giá thành : Giá thành thực tế
A39: Khoản mục chi phí sản xuất kinh doanh | B39: Chi phí SXKD dở dang đầu kỳ | C39: Chi phí SXKD phát sinh trong kỳ | D39: Chi phí SXKD dở dang cuối kỳ | E39: Giá thành sản phẩm dịch vụ trong kỳ
E40: Giá thành | F40: Giá thành đơn vị
A41: 1. Vật liệu
A43: 2. Nhân công | C43: =29952000/12 -> 2496000 | E43: =C43 -> 2496000 | F43: =E43/E36 -> 131.36842
A45: 3. Máy
A47: 4. Chi phí chung
A48: Chi phí khấu hao hệ thống pin năng lượng mặt trời | C48: =17159650+(B48/12) -> 17159650 | D48: =B48-(B48/12)*3 -> 0 | E48: =B48+C48-D48 -> 17159650 | F48: =E48/E36 -> 903.13947
A49: Chi phí khấu hao sửa chửa hệ thống ĐMT | C49: =(0*1)+(B49/12)*1 -> 0 | E49: =B49+C49-D49 -> 0 | F49: =E49/E36 -> 0
A50: Cộng | B50: =B48+B49 -> 0 | C50: =C48+C49 -> 17159650 | D50: =D48+D49 -> 0 | E50: =E48+E49 -> 17159650 | F50: =F43+F48+F49 -> 1034.5079
A52: Người ghi sổ | C52: Kế toán trưởng | E52: Giám đốc
...

Sheet T3
A1: ='THONG TIN'!C3 -> Công ty TNHH Thuận An | E1: Mẫu số : S 25 - SKT/DNN
A2: ='THONG TIN'!C4 -> Ấp Chồng Nô 3, Xã Hòa Tân, Huyện Cầu Kè, Tỉnh Trà Vinh | E2: Ban hành theo quyết định số
E3: 133/2016/TT-BTC ngày 14/06/2016
E4: của bộ tài chính
A5: THẺ TÍNH GIÁ THÀNH SẢN PHẨM
A6: Tháng 3/2021
B7: ĐỊA ĐIỂM : | C7: HÒA TÂN
B8: Tên sản phẩm , dịch vụ : Điện năng lượng mặt trời
B9: Số lượng sản phẩm , dịch vụ hoàn thành trong kỳ : | E9: 12848
B10: Phương pháp tính giá thành : Giá thành thực tế
A12: Khoản mục chi phí sản xuất kinh doanh | B12: Chi phí SXKD dở dang đầu kỳ | C12: Chi phí SXKD phát sinh trong kỳ | D12: Chi phí SXKD dở dang cuối kỳ | E12: Giá thành sản phẩm dịch vụ trong kỳ
E13: Giá thành | F13: Giá thành đơn vị
A14: 1. Vật liệu
A16: 2. Nhân công | C16: =16128000/12 -> 1344000 | E16: =C16 -> 1344000 | F16: =E16/E9 -> 104.60772
A18: 3. Máy
A20: 4. Chi phí chung
A21: Chi phí khấu hao hệ thống pin năng lượng mặt trời | C21: =12823592+(B21/12) -> 12823592 | D21: =B21-(B21/12)*3 -> 0 | E21: =B21+C21-D21 -> 12823592 | F21: =E21/E9 -> 998.10025
A23: Cộng | B23: =B21+B22 -> 0 | C23: =C21+C22 -> 12823592 | D23: =D21+D22 -> 0 | E23: =E21+E22 -> 12823592 | F23: =SUM(F16+F21) -> 1102.708
A25: Người ghi sổ | C25: Kế toán trưởng | E25: Giám đốc
A26: (Ký , họ tên) | C26: (Ký , họ tên) | E26: (Ký , họ tên,đóng dấu)
A28: =A1 -> Công ty TNHH Thuận An | E28: Mẫu số : S 25 - SKT/DNN
A29: =A2 -> Ấp Chồng Nô 3, Xã Hòa Tân, Huyện Cầu Kè, Tỉnh Trà Vinh | E29: Ban hành theo quyết định số
E30: 133/2016/TT-BTC ngày 14/06/2016
E31: của bộ tài chính
A32: THẺ TÍNH GIÁ THÀNH SẢN PHẨM
A33: Tháng 3/2021
B34: ĐỊA ĐIỂM : | C34: HÒA ÂN
B35: Tên sản phẩm , dịch vụ : Điện năng lượng mặt trời
B36: Số lượng sản phẩm , dịch vụ hoàn thành trong kỳ : | E36: 17000
B37: Phương pháp tính giá thành : Giá thành thực tế
A39: Khoản mục chi phí sản xuất kinh doanh | B39: Chi phí SXKD dở dang đầu kỳ | C39: Chi phí SXKD phát sinh trong kỳ | D39: Chi phí SXKD dở dang cuối kỳ | E39: Giá thành sản phẩm dịch vụ trong kỳ
E40: Giá thành | F40: Giá thành đơn vị
A41: 1. Vật liệu
A43: 2. Nhân công | C43: =29952000/12 -> 2496000 | E43: =C43 -> 2496000 | F43: =E43/E36 -> 146.82353
A45: 3. Máy
A47: 4. Chi phí chung
A48: Chi phí khấu hao hệ thống pin năng lượng mặt trời | C48: =17159650+(B48/12) -> 17159650 | D48: =B48-(B48/12)*3 -> 0 | E48: =B48+C48-D48 -> 17159650 | F48: =E48/E36 -> 1009.3912
A49: Chi phí khấu hao sửa chửa hệ thống ĐMT | C49: =825978+(B49/12) -> 825978 | E49: =B49+C49-D49 -> 825978 | F49: =E49/E36 -> 48.586941
A51: Cộng | B51: =B48+B49 -> 0 | C51: =C48+C49 -> 17985628 | D51: =D48+D49 -> 0 | E51: =E48+E49 -> 17985628 | F51: =F43+F48+F49 -> 1204.8016
A53: Người ghi sổ | C53: Kế toán trưởng | E53: Giám đốc
...

Sheet T4
A1: ='THONG TIN'!C3 -> Công ty TNHH Thuận An | E1: Mẫu số : S 25 - SKT/DNN
A2: ='THONG TIN'!C4 -> Ấp Chồng Nô 3, Xã Hòa Tân, Huyện Cầu Kè, Tỉnh Trà Vinh | E2: Ban hành theo quyết định số
E3: 133/2016/TT-BTC ngày 14/06/2016
E4: của bộ tài chính
A5: THẺ TÍNH GIÁ THÀNH SẢN PHẨM
A6: Tháng 4/2021
B7: ĐỊA ĐIỂM : | C7: HÒA TÂN
B8: Tên sản phẩm , dịch vụ : Điện năng lượng mặt trời
B9: Số lượng sản phẩm , dịch vụ hoàn thành trong kỳ : | E9: 8973
B10: Phương pháp tính giá thành : Giá thành thực tế
A12: Khoản mục chi phí sản xuất kinh doanh | B12: Chi phí SXKD dở dang đầu kỳ | C12: Chi phí SXKD phát sinh trong kỳ | D12: Chi phí SXKD dở dang cuối kỳ | E12: Giá thành sản phẩm dịch vụ trong kỳ
E13: Giá thành | F13: Giá thành đơn vị
A14: 1. Vật liệu
A16: 2. Nhân công | C16: =16128000/12 -> 1344000 | E16: =C16 -> 1344000 | F16: =E16/E9 -> 149.78268
A18: 3. Máy
A20: 4. Chi phí chung
A21: Chi phí khấu hao hệ thống pin năng lượng mặt trời | C21: =12823592+(B21/12) -> 12823592 | D21: =B21-(B21/12)*3 -> 0 | E21: =B21+C21-D21 -> 12823592 | F21: =E21/E9 -> 1429.1309
A23: Cộng | B23: =B21+B22 -> 0 | C23: =C21+C22 -> 12823592 | D23: =D21+D22 -> 0 | E23: =E21+E22 -> 12823592 | F23: =F16+F21 -> 1578.9136
A25: Người ghi sổ | C25: Kế toán trưởng | E25: Giám đốc
A26: (Ký , họ tên) | C26: (Ký , họ tên) | E26: (Ký , họ tên,đóng dấu)
A28: =A1 -> Công ty TNHH Thuận An | E28: Mẫu số : S 25 - SKT/DNN
A29: =A2 -> Ấp Chồng Nô 3, Xã Hòa Tân, Huyện Cầu Kè, Tỉnh Trà Vinh | E29: Ban hành theo quyết định số
E30: 133/2016/TT-BTC ngày 14/06/2016
E31: của bộ tài chính
A32: THẺ TÍNH GIÁ THÀNH SẢN PHẨM
A33: Tháng 4/2021
B34: ĐỊA ĐIỂM : | C34: HÒA ÂN
B35: Tên sản phẩm , dịch vụ : Điện năng lượng mặt trời
B36: Số lượng sản phẩm , dịch vụ hoàn thành trong kỳ : | E36: 10230
B37: Phương pháp tính giá thành : Giá thành thực tế
A39: Khoản mục chi phí sản xuất kinh doanh | B39: Chi phí SXKD dở dang đầu kỳ | C39: Chi phí SXKD phát sinh trong kỳ | D39: Chi phí SXKD dở dang cuối kỳ | E39: Giá thành sản phẩm dịch vụ trong kỳ
E40: Giá thành | F40: Giá thành đơn vị
A41: 1. Vật liệu
A43: 2. Nhân công | C43: =29952000/12 -> 2496000 | E43: =C43 -> 2496000 | F43: =E43/E36 -> 243.98827
A45: 3. Máy
A47: 4. Chi phí chung
A48: Chi phí khấu hao hệ thống pin năng lượng mặt trời | C48: =17159650+(B48/12) -> 17159650 | D48: =B48-(B48/12)*3 -> 0 | E48: =B48+C48-D48 -> 17159650 | F48: =E48/E36 -> 1677.3851
A49: Chi phí khấu hao sửa chửa hệ thống ĐMT | C49: =825978+(B49/12) -> 825978 | E49: =B49+C49-D49 -> 825978 | F49: =E49/E36 -> 80.740762
A51: Cộng | B51: =B48+B49 -> 0 | C51: =C48+C49+C50 -> 17985628 | D51: =D48+D49 -> 0 | E51: =E48+E49+E50 -> 17985628 | F51: =F43+F48+F49+F50 -> 2002.1142
A53: Người ghi sổ | C53: Kế toán trưởng | E53: Giám đốc
...

Sheet T5
A1: ='THONG TIN'!C3 -> Công ty TNHH Thuận An | E1: Mẫu số : S 25 - SKT/DNN
A2: ='THONG TIN'!C4 -> Ấp Chồng Nô 3, Xã Hòa Tân, Huyện Cầu Kè, Tỉnh Trà Vinh | E2: Ban hành theo quyết định số
E3: 133/2016/TT-BTC ngày 14/06/2016
E4: của bộ tài chính
A5: THẺ TÍNH GIÁ THÀNH SẢN PHẨM
A6: Tháng 5/2021
B7: ĐỊA ĐIỂM : | C7: HÒA TÂN
B8: Tên sản phẩm , dịch vụ : Điện năng lượng mặt trời
B9: Số lượng sản phẩm , dịch vụ hoàn thành trong kỳ : | E9: 7781
B10: Phương pháp tính giá thành : Giá thành thực tế
A12: Khoản mục chi phí sản xuất kinh doanh | B12: Chi phí SXKD dở dang đầu kỳ | C12: Chi phí SXKD phát sinh trong kỳ | D12: Chi phí SXKD dở dang cuối kỳ | E12: Giá thành sản phẩm dịch vụ trong kỳ
E13: Giá thành | F13: Giá thành đơn vị
A14: 1. Vật liệu
A16: 2. Nhân công | C16: =16128000/12 -> 1344000 | E16: =C16 -> 1344000 | F16: =E16/E9 -> 172.72844
A18: 3. Máy
A20: 4. Chi phí chung
A21: Chi phí khấu hao hệ thống pin năng lượng mặt trời | C21: =12823592+(B21/12) -> 12823592 | D21: =B21-(B21/12)*3 -> 0 | E21: =B21+C21-D21 -> 12823592 | F21: =E21/E9 -> 1648.0648
A23: Cộng | B23: =B21+B22 -> 0 | C23: =C21+C22 -> 12823592 | D23: =D21+D22 -> 0 | E23: =E21+E22 -> 12823592 | F23: =F16+F21 -> 1820.7932
A25: Người ghi sổ | C25: Kế toán trưởng | E25: Giám đốc
A26: (Ký , họ tên) | C26: (Ký , họ tên) | E26: (Ký , họ tên,đóng dấu)
A28: =A1 -> Công ty TNHH Thuận An | E28: Mẫu số : S 25 - SKT/DNN
A29: =A2 -> Ấp Chồng Nô 3, Xã Hòa Tân, Huyện Cầu Kè, Tỉnh Trà Vinh | E29: Ban hành theo quyết định số
E30: 133/2016/TT-BTC ngày 14/06/2016
E31: của bộ tài chính
A32: THẺ TÍNH GIÁ THÀNH SẢN PHẨM
A33: Tháng 5 /2021
B34: ĐỊA ĐIỂM : | C34: HÒA ÂN
B35: Tên sản phẩm , dịch vụ : Điện năng lượng mặt trời
B36: Số lượng sản phẩm , dịch vụ hoàn thành trong kỳ : | E36: 17440
B37: Phương pháp tính giá thành : Giá thành thực tế
A39: Khoản mục chi phí sản xuất kinh doanh | B39: Chi phí SXKD dở dang đầu kỳ | C39: Chi phí SXKD phát sinh trong kỳ | D39: Chi phí SXKD dở dang cuối kỳ | E39: Giá thành sản phẩm dịch vụ trong kỳ
E40: Giá thành | F40: Giá thành đơn vị
A41: 1. Vật liệu
A43: 2. Nhân công | C43: =29952000/12 -> 2496000 | E43: =C43 -> 2496000 | F43: =E43/E36 -> 143.11927
A45: 3. Máy
A47: 4. Chi phí chung
A48: Chi phí khấu hao hệ thống pin năng lượng mặt trời | C48: =17159650+(B48/12) -> 17159650 | D48: =B48-(B48/12)*3 -> 0 | E48: =B48+C48-D48 -> 17159650 | F48: =E48/E36 -> 983.92489
A49: Chi phí khấu hao sửa chửa hệ thống ĐMT | C49: =825978+(B49/12) -> 825978 | E49: =B49+C49-D49 -> 825978 | F49: =E49/E36 -> 47.361124
A51: Cộng | B51: =B48+B49 -> 0 | C51: =C48+C49+C50 -> 17985628 | D51: =D48+D49 -> 0 | E51: =E48+E49+E50 -> 17985628 | F51: =F43+F48+F49 -> 1174.4053
A53: Người ghi sổ | C53: Kế toán trưởng | E53: Giám đốc
...

Sheet T6
A1: ='THONG TIN'!C3 -> Công ty TNHH Thuận An | E1: Mẫu số : S 25 - SKT/DNN
A2: ='THONG TIN'!C4 -> Ấp Chồng Nô 3, Xã Hòa Tân, Huyện Cầu Kè, Tỉnh Trà Vinh | E2: Ban hành theo quyết định số
E3: 133/2016/TT-BTC ngày 14/06/2016
E4: của bộ tài chính
A5: THẺ TÍNH GIÁ THÀNH SẢN PHẨM
A6: Tháng 6/2021
B7: ĐỊA ĐIỂM : | C7: HÒA TÂN
B8: Tên sản phẩm , dịch vụ : Điện năng lượng mặt trời
B9: Số lượng sản phẩm , dịch vụ hoàn thành trong kỳ : | E9: 8034
B10: Phương pháp tính giá thành : Giá thành thực tế
A12: Khoản mục chi phí sản xuất kinh doanh | B12: Chi phí SXKD dở dang đầu kỳ | C12: Chi phí SXKD phát sinh trong kỳ | D12: Chi phí SXKD dở dang cuối kỳ | E12: Giá thành sản phẩm dịch vụ trong kỳ
E13: Giá thành | F13: Giá thành đơn vị
A14: 1. Vật liệu
A16: 2. Nhân công | C16: =16128000/12 -> 1344000 | E16: =C16 -> 1344000 | F16: =E16/E9 -> 167.28902
A18: 3. Máy
A20: 4. Chi phí chung
A21: Chi phí khấu hao hệ thống pin năng lượng mặt trời | C21: =12823592+(B21/12) -> 12823592 | D21: =B21-(B21/12)*3 -> 0 | E21: =B21+C21-D21 -> 12823592 | F21: =E21/E9 -> 1596.1653
A23: Cộng | B23: =B21+B22 -> 0 | C23: =C21+C22 -> 12823592 | D23: =D21+D22 -> 0 | E23: =E21+E22 -> 12823592 | F23: =F16+F21 -> 1763.4543
A25: Người ghi sổ | C25: Kế toán trưởng | E25: Giám đốc
A26: (Ký , họ tên) | C26: (Ký , họ tên) | E26: (Ký , họ tên,đóng dấu)
A28: =A1 -> Công ty TNHH Thuận An | E28: Mẫu số : S 25 - SKT/DNN
A29: =A2 -> Ấp Chồng Nô 3, Xã Hòa Tân, Huyện Cầu Kè, Tỉnh Trà Vinh | E29: Ban hành theo quyết định số
E30: 133/2016/TT-BTC ngày 14/06/2016
E31: của bộ tài chính
A32: THẺ TÍNH GIÁ THÀNH SẢN PHẨM
A33: Tháng 6 /2021
B34: ĐỊA ĐIỂM : | C34: HÒA ÂN
B35: Tên sản phẩm , dịch vụ : Điện năng lượng mặt trời
B36: Số lượng sản phẩm , dịch vụ hoàn thành trong kỳ : | E36: 17520
B37: Phương pháp tính giá thành : Giá thành thực tế
A39: Khoản mục chi phí sản xuất kinh doanh | B39: Chi phí SXKD dở dang đầu kỳ | C39: Chi phí SXKD phát sinh trong kỳ | D39: Chi phí SXKD dở dang cuối kỳ | E39: Giá thành sản phẩm dịch vụ trong kỳ
E40: Giá thành | F40: Giá thành đơn vị
A41: 1. Vật liệu
A43: 2. Nhân công | C43: =29952000/12 -> 2496000 | E43: =C43 -> 2496000 | F43: =E43/E36 -> 142.46575
A45: 3. Máy
A47: 4. Chi phí chung
A48: Chi phí khấu hao hệ thống pin năng lượng mặt trời | C48: =17159650+(B48/12) -> 17159650 | D48: =B48-(B48/12)*3 -> 0 | E48: =B48+C48-D48 -> 17159650 | F48: =E48/E36 -> 979.43208
A49: Chi phí khấu hao sửa chửa hệ thống ĐMT | C49: =825978+(B49/12) -> 825978 | E49: =B49+C49-D49 -> 825978 | F49: =E49/E36 -> 47.144863
A51: Cộng | B51: =B48+B49 -> 0 | C51: =C48+C49+C50 -> 17985628 | D51: =D48+D49 -> 0 | E51: =E48+E49+E50 -> 17985628 | F51: =F43+F48+F49 -> 1169.0427
A53: Người ghi sổ | C53: Kế toán trưởng | E53: Giám đốc
...

Sheet T7
A1: ='THONG TIN'!C3 -> Công ty TNHH Thuận An | E1: Mẫu số : S 25 - SKT/DNN
A2: ='THONG TIN'!C4 -> Ấp Chồng Nô 3, Xã Hòa Tân, Huyện Cầu Kè, Tỉnh Trà Vinh | E2: Ban hành theo quyết định số
E3: 133/2016/TT-BTC ngày 14/06/2016
E4: của bộ tài chính
A5: THẺ TÍNH GIÁ THÀNH SẢN PHẨM
A6: Tháng 7/2021
B7: ĐỊA ĐIỂM : | C7: HÒA TÂN
B8: Tên sản phẩm , dịch vụ : Điện năng lượng mặt trời
B9: Số lượng sản phẩm , dịch vụ hoàn thành trong kỳ : | E9: 7255
B10: Phương pháp tính giá thành : Giá thành thực tế
A12: Khoản mục chi phí sản xuất kinh doanh | B12: Chi phí SXKD dở dang đầu kỳ | C12: Chi phí SXKD phát sinh trong kỳ | D12: Chi phí SXKD dở dang cuối kỳ | E12: Giá thành sản phẩm dịch vụ trong kỳ
E13: Giá thành | F13: Giá thành đơn vị
A14: 1. Vật liệu
A16: 2. Nhân công | C16: =16128000/12 -> 1344000 | E16: =C16 -> 1344000 | F16: =E16/E9 -> 185.25155
A18: 3. Máy
A20: 4. Chi phí chung
A21: Chi phí khấu hao hệ thống pin năng lượng mặt trời | C21: =12823592+(B21/12) -> 12823592 | D21: =B21-(B21/12)*3 -> 0 | E21: =B21+C21-D21 -> 12823592 | F21: =E21/E9 -> 1767.5523
A23: Cộng | B23: =B21+B22 -> 0 | C23: =C21+C22 -> 12823592 | D23: =D21+D22 -> 0 | E23: =E21+E22 -> 12823592 | F23: =F16+F21 -> 1952.8039
A25: Người ghi sổ | C25: Kế toán trưởng | E25: Giám đốc
A26: (Ký , họ tên) | C26: (Ký , họ tên) | E26: (Ký , họ tên,đóng dấu)
A28: =A1 -> Công ty TNHH Thuận An | E28: Mẫu số : S 25 - SKT/DNN
A29: =A2 -> Ấp Chồng Nô 3, Xã Hòa Tân, Huyện Cầu Kè, Tỉnh Trà Vinh | E29: Ban hành theo quyết định số
E30: 133/2016/TT-BTC ngày 14/06/2016
E31: của bộ tài chính
A32: THẺ TÍNH GIÁ THÀNH SẢN PHẨM
A33: Tháng 7 /2021
B34: ĐỊA ĐIỂM : | C34: HÒA ÂN
B35: Tên sản phẩm , dịch vụ : Điện năng lượng mặt trời
B36: Số lượng sản phẩm , dịch vụ hoàn thành trong kỳ : | E36: 15640
B37: Phương pháp tính giá thành : Giá thành thực tế
A39: Khoản mục chi phí sản xuất kinh doanh | B39: Chi phí SXKD dở dang đầu kỳ | C39: Chi phí SXKD phát sinh trong kỳ | D39: Chi phí SXKD dở dang cuối kỳ | E39: Giá thành sản phẩm dịch vụ trong kỳ
E40: Giá thành | F40: Giá thành đơn vị
A41: 1. Vật liệu
A43: 2. Nhân công | C43: =29952000/12 -> 2496000 | E43: =C43 -> 2496000 | F43: =E43/E36 -> 159.59079
A45: 3. Máy
A47: 4. Chi phí chung
A48: Chi phí khấu hao hệ thống pin năng lượng mặt trời | C48: =17159650+(B48/12) -> 17159650 | D48: =B48-(B48/12)*3 -> 0 | E48: =B48+C48-D48 -> 17159650 | F48: =E48/E36 -> 1097.1643
A49: Chi phí khấu hao sửa chửa hệ thống ĐMT | C49: =825978+(B49/12) -> 825978 | E49: =B49+C49-D49 -> 825978 | F49: =E49/E36 -> 52.811893
A51: Cộng | B51: =B48+B49 -> 0 | C51: =C48+C49+C50 -> 17985628 | D51: =D48+D49 -> 0 | E51: =E48+E49+E50 -> 17985628 | F51: =F43+F48+F49 -> 1309.567
A53: Người ghi sổ | C53: Kế toán trưởng | E53: Giám đốc
...

Sheet T8
A1: ='THONG TIN'!C3 -> Công ty TNHH Thuận An | E1: Mẫu số : S 25 - SKT/DNN
A2: ='THONG TIN'!C4 -> Ấp Chồng Nô 3, Xã Hòa Tân, Huyện Cầu Kè, Tỉnh Trà Vinh | E2: Ban hành theo quyết định số
E3: 133/2016/TT-BTC ngày 14/06/2016
E4: của bộ tài chính
A5: THẺ TÍNH GIÁ THÀNH SẢN PHẨM
A6: Tháng 8/2021
B7: ĐỊA ĐIỂM : | C7: HÒA TÂN
B8: Tên sản phẩm , dịch vụ : Điện năng lượng mặt trời
B9: Số lượng sản phẩm , dịch vụ hoàn thành trong kỳ : | E9: 8271
B10: Phương pháp tính giá thành : Giá thành thực tế
A12: Khoản mục chi phí sản xuất kinh doanh | B12: Chi phí SXKD dở dang đầu kỳ | C12: Chi phí SXKD phát sinh trong kỳ | D12: Chi phí SXKD dở dang cuối kỳ | E12: Giá thành sản phẩm dịch vụ trong kỳ
E13: Giá thành | F13: Giá thành đơn vị
A14: 1. Vật liệu
A16: 2. Nhân công | C16: =16128000/12 -> 1344000 | E16: =C16 -> 1344000 | F16: =E16/E9 -> 162.49547
A18: 3. Máy
A20: 4. Chi phí chung
A21: Chi phí khấu hao hệ thống pin năng lượng mặt trời | C21: =12823592+(B21/12) -> 12823592 | D21: =B21-(B21/12)*3 -> 0 | E21: =B21+C21-D21 -> 12823592 | F21: =E21/E9 -> 1550.4282
A23: Cộng | B23: =B21+B22 -> 0 | C23: =C21+C22 -> 12823592 | D23: =D21+D22 -> 0 | E23: =E21+E22 -> 12823592 | F23: =F16+F21 -> 1712.9237
A25: Người ghi sổ | C25: Kế toán trưởng | E25: Giám đốc
A26: (Ký , họ tên) | C26: (Ký , họ tên) | E26: (Ký , họ tên,đóng dấu)
A28: =A1 -> Công ty TNHH Thuận An | E28: Mẫu số : S 25 - SKT/DNN
A29: =A2 -> Ấp Chồng Nô 3, Xã Hòa Tân, Huyện Cầu Kè, Tỉnh Trà Vinh | E29: Ban hành theo quyết định số
E30: 133/2016/TT-BTC ngày 14/06/2016
E31: của bộ tài chính
A32: THẺ TÍNH GIÁ THÀNH SẢN PHẨM
A33: Tháng 8 /2021
B34: ĐỊA ĐIỂM : | C34: HÒA ÂN
B35: Tên sản phẩm , dịch vụ : Điện năng lượng mặt trời
B36: Số lượng sản phẩm , dịch vụ hoàn thành trong kỳ : | E36: 18060
B37: Phương pháp tính giá thành : Giá thành thực tế
A39: Khoản mục chi phí sản xuất kinh doanh | B39: Chi phí SXKD dở dang đầu kỳ | C39: Chi phí SXKD phát sinh trong kỳ | D39: Chi phí SXKD dở dang cuối kỳ | E39: Giá thành sản phẩm dịch vụ trong kỳ
E40: Giá thành | F40: Giá thành đơn vị
A41: 1. Vật liệu
A43: 2. Nhân công | C43: =29952000/12 -> 2496000 | E43: =C43 -> 2496000 | F43: =E43/E36 -> 138.20598
A45: 3. Máy
A47: 4. Chi phí chung
A48: Chi phí khấu hao hệ thống pin năng lượng mặt trời | C48: =17159650+(B48/12) -> 17159650 | D48: =B48-(B48/12)*3 -> 0 | E48: =B48+C48-D48 -> 17159650 | F48: =E48/E36 -> 950.14673
A49: Chi phí khấu hao sửa chửa hệ thống ĐMT | C49: =825978+(B49/12) -> 825978 | E49: =B49+C49-D49 -> 825978 | F49: =E49/E36 -> 45.735216
A51: Cộng | B51: =B48+B49 -> 0 | C51: =C48+C49+C50 -> 17985628 | D51: =D48+D49 -> 0 | E51: =E48+E49+E50 -> 17985628 | F51: =F43+F48+F49 -> 1134.0879
A53: Người ghi sổ | C53: Kế toán trưởng | E53: Giám đốc
...

Sheet T9
A1: ='THONG TIN'!C3 -> Công ty TNHH Thuận An | E1: Mẫu số : S 25 - SKT/DNN
A2: ='THONG TIN'!C4 -> Ấp Chồng Nô 3, Xã Hòa Tân, Huyện Cầu Kè, Tỉnh Trà Vinh | E2: Ban hành theo quyết định số
E3: 133/2016/TT-BTC ngày 14/06/2016
E4: của bộ tài chính
A5: THẺ TÍNH GIÁ THÀNH SẢN PHẨM
A6: Tháng 9/2021
B7: ĐỊA ĐIỂM : | C7: HÒA TÂN
B8: Tên sản phẩm , dịch vụ : Điện năng lượng mặt trời
B9: Số lượng sản phẩm , dịch vụ hoàn thành trong kỳ : | E9: 7105
B10: Phương pháp tính giá thành : Giá thành thực tế
A12: Khoản mục chi phí sản xuất kinh doanh | B12: Chi phí SXKD dở dang đầu kỳ | C12: Chi phí SXKD phát sinh trong kỳ | D12: Chi phí SXKD dở dang cuối kỳ | E12: Giá thành sản phẩm dịch vụ trong kỳ
E13: Giá thành | F13: Giá thành đơn vị
A14: 1. Vật liệu
A16: 2. Nhân công | C16: =16128000/12 -> 1344000 | E16: =C16 -> 1344000 | F16: =E16/E9 -> 189.16256
A18: 3. Máy
A20: 4. Chi phí chung
A21: Chi phí khấu hao hệ thống pin năng lượng mặt trời | C21: =12823592+(B21/12) -> 12823592 | D21: =B21-(B21/12)*3 -> 0 | E21: =B21+C21-D21 -> 12823592 | F21: =E21/E9 -> 1804.8687
A23: Cộng | B23: =B21+B22 -> 0 | C23: =C21+C22 -> 12823592 | D23: =D21+D22 -> 0 | E23: =E21+E22 -> 12823592 | F23: =F16+F21 -> 1994.0312
A25: Người ghi sổ | C25: Kế toán trưởng | E25: Giám đốc
A26: (Ký , họ tên) | C26: (Ký , họ tên) | E26: (Ký , họ tên,đóng dấu)
A28: =A1 -> Công ty TNHH Thuận An | E28: Mẫu số : S 25 - SKT/DNN
A29: =A2 -> Ấp Chồng Nô 3, Xã Hòa Tân, Huyện Cầu Kè, Tỉnh Trà Vinh | E29: Ban hành theo quyết định số
E30: 133/2016/TT-BTC ngày 14/06/2016
E31: của bộ tài chính
A32: THẺ TÍNH GIÁ THÀNH SẢN PHẨM
A33: Tháng 9 /2021
B34: ĐỊA ĐIỂM : | C34: HÒA ÂN
B35: Tên sản phẩm , dịch vụ : Điện năng lượng mặt trời
B36: Số lượng sản phẩm , dịch vụ hoàn thành trong kỳ : | E36: 14610
B37: Phương pháp tính giá thành : Giá thành thực tế
A39: Khoản mục chi phí sản xuất kinh doanh | B39: Chi phí SXKD dở dang đầu kỳ | C39: Chi phí SXKD phát sinh trong kỳ | D39: Chi phí SXKD dở dang cuối kỳ | E39: Giá thành sản phẩm dịch vụ trong kỳ
E40: Giá thành | F40: Giá thành đơn vị
A41: 1. Vật liệu
A43: 2. Nhân công | C43: =29952000/12 -> 2496000 | E43: =C43 -> 2496000 | F43: =E43/E36 -> 170.84189
A45: 3. Máy
A47: 4. Chi phí chung
A48: Chi phí khấu hao hệ thống pin năng lượng mặt trời | C48: =17159650+(B48/12) -> 17159650 | D48: =B48-(B48/12)*3 -> 0 | E48: =B48+C48-D48 -> 17159650 | F48: =E48/E36 -> 1174.514
A49: Chi phí khấu hao sửa chửa hệ thống ĐMT | C49: =825978+(B49/12) -> 825978 | E49: =B49+C49-D49 -> 825978 | F49: =E49/E36 -> 56.535113
A51: Cộng | B51: =B48+B49 -> 0 | C51: =C48+C49+C50 -> 17985628 | D51: =D48+D49 -> 0 | E51: =E48+E49+E50 -> 17985628 | F51: =F43+F48+F49 -> 1401.891
A53: Người ghi sổ | C53: Kế toán trưởng | E53: Giám đốc
...

Sheet T10
A1: ='THONG TIN'!C3 -> Công ty TNHH Thuận An | E1: Mẫu số : S 25 - SKT/DNN
A2: ='THONG TIN'!C4 -> Ấp Chồng Nô 3, Xã Hòa Tân, Huyện Cầu Kè, Tỉnh Trà Vinh | E2: Ban hành theo quyết định số
E3: 133/2016/TT-BTC ngày 14/06/2016
E4: của bộ tài chính
A5: THẺ TÍNH GIÁ THÀNH SẢN PHẨM
A6: Tháng 10/2021
B7: ĐỊA ĐIỂM : | C7: HÒA TÂN
B8: Tên sản phẩm , dịch vụ : Điện năng lượng mặt trời
B9: Số lượng sản phẩm , dịch vụ hoàn thành trong kỳ : | E9: 7286
B10: Phương pháp tính giá thành : Giá thành thực tế
A12: Khoản mục chi phí sản xuất kinh doanh | B12: Chi phí SXKD dở dang đầu kỳ | C12: Chi phí SXKD phát sinh trong kỳ | D12: Chi phí SXKD dở dang cuối kỳ | E12: Giá thành sản phẩm dịch vụ trong kỳ
E13: Giá thành | F13: Giá thành đơn vị
A14: 1. Vật liệu
A16: 2. Nhân công | C16: =16128000/12 -> 1344000 | E16: =C16 -> 1344000 | F16: =E16/E9 -> 184.46335
A18: 3. Máy
A20: 4. Chi phí chung
A21: Chi phí khấu hao hệ thống pin năng lượng mặt trời | C21: =12823592+(B21/12) -> 12823592 | D21: =B21-(B21/12)*3 -> 0 | E21: =B21+C21-D21 -> 12823592 | F21: =E21/E9 -> 1760.0318
A23: Cộng | B23: =B21+B22 -> 0 | C23: =C21+C22 -> 12823592 | D23: =D21+D22 -> 0 | E23: =E21+E22 -> 12823592 | F23: =F16+F21 -> 1944.4952
A25: Người ghi sổ | C25: Kế toán trưởng | E25: Giám đốc
A26: (Ký , họ tên) | C26: (Ký , họ tên) | E26: (Ký , họ tên,đóng dấu)
A28: =A1 -> Công ty TNHH Thuận An | E28: Mẫu số : S 25 - SKT/DNN
A29: =A2 -> Ấp Chồng Nô 3, Xã Hòa Tân, Huyện Cầu Kè, Tỉnh Trà Vinh | E29: Ban hành theo quyết định số
E30: 133/2016/TT-BTC ngày 14/06/2016
E31: của bộ tài chính
A32: THẺ TÍNH GIÁ THÀNH SẢN PHẨM
A33: Tháng 10 /2021
B34: ĐỊA ĐIỂM : | C34: HÒA ÂN
B35: Tên sản phẩm , dịch vụ : Điện năng lượng mặt trời
B36: Số lượng sản phẩm , dịch vụ hoàn thành trong kỳ : | E36: 15080
B37: Phương pháp tính giá thành : Giá thành thực tế
A39: Khoản mục chi phí sản xuất kinh doanh | B39: Chi phí SXKD dở dang đầu kỳ | C39: Chi phí SXKD phát sinh trong kỳ | D39: Chi phí SXKD dở dang cuối kỳ | E39: Giá thành sản phẩm dịch vụ trong kỳ
E40: Giá thành | F40: Giá thành đơn vị
A41: 1. Vật liệu
A43: 2. Nhân công | C43: =29952000/12 -> 2496000 | E43: =C43 -> 2496000 | F43: =E43/E36 -> 165.51724
A45: 3. Máy
A47: 4. Chi phí chung
A48: Chi phí khấu hao hệ thống pin năng lượng mặt trời | C48: =17159650+(B48/12) -> 17159650 | D48: =B48-(B48/12)*3 -> 0 | E48: =B48+C48-D48 -> 17159650 | F48: =E48/E36 -> 1137.9078
A49: Chi phí khấu hao sửa chửa hệ thống ĐMT | C49: =825978+(B49/12) -> 825978 | E49: =B49+C49-D49 -> 825978 | F49: =E49/E36 -> 54.773077
A51: Cộng | B51: =B48+B49 -> 0 | C51: =C48+C49+C50 -> 17985628 | D51: =D48+D49 -> 0 | E51: =E48+E49+E50 -> 17985628 | F51: =F43+F48+F49 -> 1358.1981
A53: Người ghi sổ | C53: Kế toán trưởng | E53: Giám đốc
...

Sheet T11
A1: ='THONG TIN'!C3 -> Công ty TNHH Thuận An | E1: Mẫu số : S 25 - SKT/DNN
A2: ='THONG TIN'!C4 -> Ấp Chồng Nô 3, Xã Hòa Tân, Huyện Cầu Kè, Tỉnh Trà Vinh | E2: Ban hành theo quyết định số
E3: 133/2016/TT-BTC ngày 14/06/2016
E4: của bộ tài chính
A5: THẺ TÍNH GIÁ THÀNH SẢN PHẨM
A6: Tháng 11/2021
B7: ĐỊA ĐIỂM : | C7: HÒA TÂN
B8: Tên sản phẩm , dịch vụ : Điện năng lượng mặt trời
B9: Số lượng sản phẩm , dịch vụ hoàn thành trong kỳ : | E9: 6744
B10: Phương pháp tính giá thành : Giá thành thực tế
A12: Khoản mục chi phí sản xuất kinh doanh | B12: Chi phí SXKD dở dang đầu kỳ | C12: Chi phí SXKD phát sinh trong kỳ | D12: Chi phí SXKD dở dang cuối kỳ | E12: Giá thành sản phẩm dịch vụ trong kỳ
E13: Giá thành | F13: Giá thành đơn vị
A14: 1. Vật liệu
A16: 2. Nhân công | C16: =16128000/12 -> 1344000 | E16: =C16 -> 1344000 | F16: =E16/E9 -> 199.28826
A18: 3. Máy
A20: 4. Chi phí chung
A21: Chi phí khấu hao hệ thống pin năng lượng mặt trời | C21: =12823592+(B21/12) -> 12823592 | D21: =B21-(B21/12)*3 -> 0 | E21: =B21+C21-D21 -> 12823592 | F21: =E21/E9 -> 1901.4816
A23: Cộng | B23: =B21+B22 -> 0 | C23: =C21+C22 -> 12823592 | D23: =D21+D22 -> 0 | E23: =E21+E22 -> 12823592 | F23: =F16+F21 -> 2100.7699
A25: Người ghi sổ | C25: Kế toán trưởng | E25: Giám đốc
A26: (Ký , họ tên) | C26: (Ký , họ tên) | E26: (Ký , họ tên,đóng dấu)
A28: =A1 -> Công ty TNHH Thuận An | E28: Mẫu số : S 25 - SKT/DNN
A29: =A2 -> Ấp Chồng Nô 3, Xã Hòa Tân, Huyện Cầu Kè, Tỉnh Trà Vinh | E29: Ban hành theo quyết định số
E30: 133/2016/TT-BTC ngày 14/06/2016
E31: của bộ tài chính
A32: THẺ TÍNH GIÁ THÀNH SẢN PHẨM
A33: Tháng 11 /2021
B34: ĐỊA ĐIỂM : | C34: HÒA ÂN
B35: Tên sản phẩm , dịch vụ : Điện năng lượng mặt trời
B36: Số lượng sản phẩm , dịch vụ hoàn thành trong kỳ : | E36: 13280
B37: Phương pháp tính giá thành : Giá thành thực tế
A39: Khoản mục chi phí sản xuất kinh doanh | B39: Chi phí SXKD dở dang đầu kỳ | C39: Chi phí SXKD phát sinh trong kỳ | D39: Chi phí SXKD dở dang cuối kỳ | E39: Giá thành sản phẩm dịch vụ trong kỳ
E40: Giá thành | F40: Giá thành đơn vị
A41: 1. Vật liệu
A43: 2. Nhân công | C43: =29952000/12 -> 2496000 | E43: =C43 -> 2496000 | F43: =E43/E36 -> 187.95181
A45: 3. Máy
A47: 4. Chi phí chung
A48: Chi phí khấu hao hệ thống pin năng lượng mặt trời | C48: =17159650+(B48/12) -> 17159650 | D48: =B48-(B48/12)*3 -> 0 | E48: =B48+C48-D48 -> 17159650 | F48: =E48/E36 -> 1292.1423
A49: Chi phí khấu hao sửa chửa hệ thống ĐMT | C49: =825978+(B49/12) -> 825978 | E49: =B49+C49-D49 -> 825978 | F49: =E49/E36 -> 62.197139
A51: Cộng | B51: =B48+B49 -> 0 | C51: =C48+C49+C50 -> 17985628 | D51: =D48+D49 -> 0 | E51: =E48+E49+E50 -> 17985628 | F51: =F43+F48+F49 -> 1542.2913
A53: Người ghi sổ | C53: Kế toán trưởng | E53: Giám đốc
...

Sheet T12
A1: ='THONG TIN'!C3 -> Công ty TNHH Thuận An | E1: Mẫu số : S 25 - SKT/DNN
A2: ='THONG TIN'!C4 -> Ấp Chồng Nô 3, Xã Hòa Tân, Huyện Cầu Kè, Tỉnh Trà Vinh | E2: Ban hành theo quyết định số
E3: 133/2016/TT-BTC ngày 14/06/2016
E4: của bộ tài chính
A5: THẺ TÍNH GIÁ THÀNH SẢN PHẨM
A6: Tháng 12/2021
B7: ĐỊA ĐIỂM : | C7: HÒA TÂN
B8: Tên sản phẩm , dịch vụ : Điện năng lượng mặt trời
B9: Số lượng sản phẩm , dịch vụ hoàn thành trong kỳ : | E9: 7621
B10: Phương pháp tính giá thành : Giá thành thực tế
A12: Khoản mục chi phí sản xuất kinh doanh | B12: Chi phí SXKD dở dang đầu kỳ | C12: Chi phí SXKD phát sinh trong kỳ | D12: Chi phí SXKD dở dang cuối kỳ | E12: Giá thành sản phẩm dịch vụ trong kỳ
E13: Giá thành | F13: Giá thành đơn vị
A14: 1. Vật liệu
A16: 2. Nhân công | C16: =16128000/12 -> 1344000 | E16: =C16 -> 1344000 | F16: =E16/E9 -> 176.35481
A18: 3. Máy
A20: 4. Chi phí chung
A21: Chi phí khấu hao hệ thống pin năng lượng mặt trời | C21: =12823592+(B21/12) -> 12823592 | D21: =B21-(B21/12)*3 -> 0 | E21: =B21+C21-D21 -> 12823592 | F21: =E21/E9 -> 1682.6653
A23: Cộng | B23: =B21+B22 -> 0 | C23: =C21+C22 -> 12823592 | D23: =D21+D22 -> 0 | E23: =E21+E22 -> 12823592 | F23: =F16+F21 -> 1859.0201
A25: Người ghi sổ | C25: Kế toán trưởng | E25: Giám đốc
A26: (Ký , họ tên) | C26: (Ký , họ tên) | E26: (Ký , họ tên,đóng dấu)
A28: =A1 -> Công ty TNHH Thuận An | E28: Mẫu số : S 25 - SKT/DNN
A29: =A2 -> Ấp Chồng Nô 3, Xã Hòa Tân, Huyện Cầu Kè, Tỉnh Trà Vinh | E29: Ban hành theo quyết định số
E30: 133/2016/TT-BTC ngày 14/06/2016
E31: của bộ tài chính
A32: THẺ TÍNH GIÁ THÀNH SẢN PHẨM
A33: Tháng 12 /2021
B34: ĐỊA ĐIỂM : | C34: HÒA ÂN
B35: Tên sản phẩm , dịch vụ : Điện năng lượng mặt trời
B36: Số lượng sản phẩm , dịch vụ hoàn thành trong kỳ : | E36: 15380
B37: Phương pháp tính giá thành : Giá thành thực tế
A39: Khoản mục chi phí sản xuất kinh doanh | B39: Chi phí SXKD dở dang đầu kỳ | C39: Chi phí SXKD phát sinh trong kỳ | D39: Chi phí SXKD dở dang cuối kỳ | E39: Giá thành sản phẩm dịch vụ trong kỳ
E40: Giá thành | F40: Giá thành đơn vị
A41: 1. Vật liệu
A43: 2. Nhân công | C43: =29952000/12 -> 2496000 | E43: =C43 -> 2496000 | F43: =E43/E36 -> 162.28869
A45: 3. Máy
A47: 4. Chi phí chung
A48: Chi phí khấu hao hệ thống pin năng lượng mặt trời | C48: =17159650+(B48/12) -> 17159650 | D48: =B48-(B48/12)*3 -> 0 | E48: =B48+C48-D48 -> 17159650 | F48: =E48/E36 -> 1115.712
A49: Chi phí khấu hao sửa chửa hệ thống ĐMT | C49: =825978+(B49/12) -> 825978 | E49: =B49+C49-D49 -> 825978 | F49: =E49/E36 -> 53.704681
A51: Cộng | B51: =B48+B49 -> 0 | C51: =C48+C49+C50 -> 17985628 | D51: =D48+D49 -> 0 | E51: =E48+E49+E50 -> 17985628 | F51: =F43+F48+F49 -> 1331.7053
A53: Người ghi sổ | C53: Kế toán trưởng | E53: Giám đốc
...
