Workbook

Sheet THONG TIN
A3: Tên doanh nghiệp: | C3: Công ty TNHH Thuận An
A4: Trụ sở chính : | C4: Ấp Chồng Nô 3, Xã Hòa Tân, Huyện Cầu Kè, Tỉnh Trà Vinh
A5: Mã số thuế : | C5: 2 1 0 0 4 0 6 8 1 8

Sheet SL 2023
A1: Tên doanh nghiệp: | C1: ='THONG TIN'!C3 -> Công ty TNHH Thuận An
A2: Trụ sở chính: | C2: ='THONG TIN'!C4 -> Ấp Chồng Nô 3, Xã Hòa Tân, Huyện Cầu Kè, Tỉnh Trà Vinh
A3: BẢNG BÁO CÁO SẢN LƯỢNG SẢN XUẤT VÀ TIÊU THỤ ĐIỆN SOLAR
A4: HÒA TÂN
B5: Công suất dự án : | D5: 62,3 Kw | E5: Năm | F5: 2023
A7: Thời gian | C7: Sản lượng phát | D7: Sản lượng bán | E7: Sản lượng phát bỏ | F7: Sản lượng tiêu dùng | I7: Giá thành
A8: Sản lượng còn lại 12/2022 | C8: 0 | D8: 5720 | G8: Hóa đơn 1
A9: Tháng 1 | C9: =D9+E9+F9 -> 8400 | D9: =1410+6850 -> 8260 | E9: 100 | F9: 40 | G9: Hóa đơn 3 và 5 | I9: ='T1'!F24 -> 1800.1423
A10: Tháng 2 | C10: =D10+E10+F10 -> 6950 | D10: 6900 | E10: 10 | F10: 40 | G10: Hóa đơn số 8 | I10: ='T2'!F24 -> 2175.7115
A11: Tháng 3 | C11: =D11+E11+F11 -> 9143 | D11: 9080 | E11: 10 | F11: 53 | G11: Hóa đơn Số 13 | I11: ='T3'!F24 -> 1653.8549
A12: Quý I | C12: =SUM(C8:C11) -> 24493 | D12: =SUM(D9:D11) -> 24240 | E12: =SUM(E9:E11) -> 120 | F12: =SUM(F9:F11) -> 133
A13: Tháng 4 | C13: =D13+E13+F13 -> 8240 | D13: 8070 | E13: 50 | F13: 120 | G13: Hóa đơn Số 15 | I13: ='T4'!F24 -> 1835.0965
A14: Tháng 5 | C14: =D14+E14+F14 -> 6781 | D14: 6680 | E14: 50 | F14: 51 | G14: Hóa đơn Số 18 | I14: ='T5'!F24 -> 2229.9359
A15: Tháng 6 | C15: =D15+E15+F15 -> 7690 | D15: 7530 | E15: 100 | F15: 60 | G15: Hóa đơn Số 21 | I15: ='T6'!F24 -> 1966.3453
A16: Quý II | C16: =SUM(C13:C15) -> 22711 | D16: =SUM(D13:D15) -> 22280 | E16: =SUM(E13:E15) -> 200 | F16: =SUM(F13:F15) -> 231
A17: Tháng 7 | C17: =D17+E17+F17 -> 6494 | D17: 6405 | E17: 10 | F17: 79 | G17: Hóa đơn Số 26 | I17: ='T7'!F24 -> 2328.4871
A18: Tháng 8 | C18: =D18+E18+F18 -> 6405 | D18: 6405 | G18: Hóa đơn Số 26 | I18: ='T8'!F24 -> 2360.8423
A19: Tháng 9 | C19: =D19+E19+F19 -> 6440 | D19: 6330 | E19: 50 | F19: 60 | G19: Hóa đơn Số 27 | I19: ='T9'!F24 -> 2348.0116
A20: Quý III | C20: =SUM(C17:C19) -> 19339 | D20: =SUM(D17:D19) -> 19140 | E20: =SUM(E17:E19) -> 60 | F20: =SUM(F17:F19) -> 139
A21: Tháng 10 | C21: =D21+E21+F21 -> 7785 | D21: 7630 | E21: 100 | F21: 55 | G21: Hóa đơn Số 32 | I21: ='T10'!F24 -> 1942.35
A22: Tháng 11 | C22: =D22+E22+F22 -> 7303 | D22: 7160 | E22: 55 | F22: 88 | G22: Hóa đơn Số 34 | I22: ='T11'!F24 -> 2070.5457
A23: Tháng 12 | C23: =D23+E23+F23 -> 7872 | D23: 7770 | E23: 10 | F23: 92 | G23: Hóa đơn Số 01/2024 | I23: ='T12'!F24 -> 1920.8835
A25: Quý IV | C25: =SUM(C21:C24) -> 22960 | D25: =SUM(D21:D24) -> 22560 | E25: =SUM(E21:E24) -> 165 | F25: =SUM(F21:F24) -> 235
C26: =C12+C16+C20+C25 -> 89503 | D26: =D12+D16+D20+D25 -> 88220 | E26: =SUM(E12+E16+E20+E25) -> 545 | F26: =SUM(F12+F16+F20+F25) -> 738 | G26: =E26+F26 -> 1283
H27: =D23+E26+F26 -> 9053
A28: Hướng dẫn | C28: Sản lượng phát ghi số liệu từ phần mềm quản lý Solar
C29: Sản lượng bán ghi số liệu từ cơ quan điện lực chốt sổ + SL nội suy đến cuối cuối tháng
C30: Sản lượng phát bỏ ghi nhận điện lực không mua và những ngày cúp điện
C31: Sản lượng tiêu dùng là chênh lệch còn lại
A35: Tên doanh nghiệp: | C35: ='THONG TIN'!C3 -> Công ty TNHH Thuận An
A36: Trụ sở chính: | C36: ='THONG TIN'!C4 -> Ấp Chồng Nô 3, Xã Hòa Tân, Huyện Cầu Kè, Tỉnh Trà Vinh
A37: BẢNG BÁO CÁO SẢN LƯỢNG SẢN XUẤT VÀ TIÊU THỤ ĐIỆN SOLAR
A38: HÒA ÂN
B39: Công suất dự án : | D39: 142,4 Kw | E39: Năm | F39: 2023
A41: Thời gian | C41: Sản lượng phát | D41: Sản lượng bán | E41: Sản lượng phát bỏ | F41: Sản lượng tiêu dùng | I41: Giá thành
A42: Sản lượng còn lại 12/2022 | C42: 0 | D42: 16228 | G42: Hóa đơn Số 02 san luong 2022
A43: Tháng 1 | C43: =D43+E43+F43 -> 18398 | D43: 15698 | E43: 1700 | F43: 1000 | G43: Hóa đơn Số 04 | I43: ='T1'!F53 -> 1519.071
A44: Tháng 2 | C44: =D44+E44+F44 -> 19030 | D44: 17330 | E44: 1300 | F44: 400 | G44: Hóa đơn Số 07 | I44: ='T2'!F53 -> 1468.6216
A45: Tháng 3 | C45: =D45+E45+F45 -> 23798 | D45: 22798 | E45: 700 | F45: 300 | G45: Hóa đơn Số 11 | I45: ='T3'!F53 -> 1174.3789
A46: Quý I | C46: =SUM(C42:C45) -> 61226 | D46: =SUM(D43:D45) -> 55826 | E46: =SUM(E43:E45) -> 3700 | F46: =SUM(F43:F45) -> 1700
...

Sheet T1
A1: ='THONG TIN'!C3 -> Công ty TNHH Thuận An | E1: Mẫu số : S 25 - SKT/DNN
A2: ='THONG TIN'!C4 -> Ấp Chồng Nô 3, Xã Hòa Tân, Huyện Cầu Kè, Tỉnh Trà Vinh | E2: Ban hành theo quyết định số
E3: 133/2016/TT-BTC ngày 14/06/2016
E4: của bộ tài chính
A5: THẺ TÍNH GIÁ THÀNH SẢN PHẨM
A6: Tháng 1/2023
B7: ĐỊA ĐIỂM : | C7: HÒA TÂN
B8: Tên sản phẩm , dịch vụ : Điện năng lượng mặt trời
B9: Số lượng sản phẩm , dịch vụ hoàn thành trong kỳ : | E9: 8400
B10: Phương pháp tính giá thành : Giá thành thực tế
A12: Khoản mục chi phí sản xuất kinh doanh | B12: Chi phí SXKD dở dang đầu kỳ | C12: Chi phí SXKD phát sinh trong kỳ | D12: Chi phí SXKD dở dang cuối kỳ | E12: Giá thành sản phẩm dịch vụ trong kỳ
E13: Giá thành | F13: Giá thành đơn vị
A14: 1. Vật liệu
A16: 2. Nhân công | C16: 1400000 | E16: =C16 -> 1400000 | F16: =E16/E9 -> 166.66667
A18: 3. Máy
A20: 4. Chi phí chung
A21: Chi phí khấu hao hệ thống pin năng lượng mặt trời | C21: =12823592+(B21/12) -> 12823592 | D21: =B21-(B21/12) -> 0 | E21: =B21+C21-D21 -> 12823592 | F21: =E21/E9 -> 1526.6181
A22: Chi phí khấu hao thay tấm pin sửa chửa hệ thống | C22: 897603 | D22: =B22-(B22/12) -> 0 | E22: =B22+C22-D22 -> 897603 | F22: =E22/E9 -> 106.8575
A24: Cộng | B24: =B21+B23 -> 0 | C24: =C16+C21+C22 -> 15121195 | D24: =D16+D21+D22 -> 0 | E24: =E16+E21+E22 -> 15121195 | F24: =F16+F21+F22 -> 1800.1423
A26: Người ghi sổ | C26: Kế toán trưởng | E26: Giám đốc
A27: (Ký , họ tên) | C27: (Ký , họ tên) | E27: (Ký , họ tên,đóng dấu)
A29: =A1 -> Công ty TNHH Thuận An | E29: Mẫu số : S 25 - SKT/DNN
A30: =A2 -> Ấp Chồng Nô 3, Xã Hòa Tân, Huyện Cầu Kè, Tỉnh Trà Vinh | E30: Ban hành theo quyết định số
E31: 133/2016/TT-BTC ngày 14/06/2016
E32: của bộ tài chính
A33: THẺ TÍNH GIÁ THÀNH SẢN PHẨM
A34: Tháng 1/2023
B35: ĐỊA ĐIỂM : | C35: HÒA ÂN
B36: Tên sản phẩm , dịch vụ : Điện năng lượng mặt trời
B37: Số lượng sản phẩm , dịch vụ hoàn thành trong kỳ : | E37: 18398
B38: Phương pháp tính giá thành : Giá thành thực tế
A40: Khoản mục chi phí sản xuất kinh doanh | B40: Chi phí SXKD dở dang đầu kỳ | C40: Chi phí SXKD phát sinh trong kỳ | D40: Chi phí SXKD dở dang cuối kỳ | E40: Giá thành sản phẩm dịch vụ trong kỳ
E41: Giá thành | F41: Giá thành đơn vị
A42: 1. Vật liệu
A44: 2. Nhân công | C44: 2800000 | E44: =C44 -> 2800000 | F44: =E44/E37 -> 152.19046
A46: 3. Máy
A48: 4. Chi phí chung
A49: Chi phí khấu hao hệ thống pin năng lượng mặt trời | C49: 21449563 | D49: =B49-(B49/12)*3 -> 0 | E49: =B49+C49-D49 -> 21449563 | F49: =E49/E37 -> 1165.8638
A50: Chi phí khấu hao thay tấm pin sửa chửa hệ thống | C50: 2872328 | E50: =B50+C50-D50 -> 2872328 | F50: =E50/E37 -> 156.12175
A51: Chi phí khấu hao sửa chửa hệ thống ĐMT | C51: 825978 | E51: =B51+C51-D51 -> 825978 | F51: =E51/E37 -> 44.894989
...

Sheet T2
A1: ='THONG TIN'!C3 -> Công ty TNHH Thuận An | E1: Mẫu số : S 25 - SKT/DNN
A2: ='THONG TIN'!C4 -> Ấp Chồng Nô 3, Xã Hòa Tân, Huyện Cầu Kè, Tỉnh Trà Vinh | E2: Ban hành theo quyết định số
E3: 133/2016/TT-BTC ngày 14/06/2016
E4: của bộ tài chính
A5: THẺ TÍNH GIÁ THÀNH SẢN PHẨM
A6: Tháng 2/2023
B7: ĐỊA ĐIỂM : | C7: HÒA TÂN
B8: Tên sản phẩm , dịch vụ : Điện năng lượng mặt trời
B9: Số lượng sản phẩm , dịch vụ hoàn thành trong kỳ : | E9: 6950
B10: Phương pháp tính giá thành : Giá thành thực tế
A12: Khoản mục chi phí sản xuất kinh doanh | B12: Chi phí SXKD dở dang đầu kỳ | C12: Chi phí SXKD phát sinh trong kỳ | D12: Chi phí SXKD dở dang cuối kỳ | E12: Giá thành sản phẩm dịch vụ trong kỳ
E13: Giá thành | F13: Giá thành đơn vị
A14: 1. Vật liệu
A16: 2. Nhân công | C16: =1400000 -> 1400000 | E16: =C16 -> 1400000 | F16: =E16/E9 -> 201.43885
A18: 3. Máy
A20: 4. Chi phí chung
A21: Chi phí khấu hao hệ thống pin năng lượng mặt trời | C21: =12823592+(B21/12) -> 12823592 | D21: =B21-(B21/12)*3 -> 0 | E21: =B21+C21-D21 -> 12823592 | F21: =E21/E9 -> 1845.1212
A22: Chi phí khấu hao thay tấm pin sửa chửa hệ thống | C22: 897603 | D22: =B22-(B22/12)*3 -> 0 | E22: =B22+C22-D22 -> 897603 | F22: =E22/E9 -> 129.15151
A24: Cộng | B24: =B21+B23 -> 0 | C24: =C16+C21+C22 -> 15121195 | D24: =D16+D21+D22 -> 0 | E24: =E16+E21+E22 -> 15121195 | F24: =F16+F21+F22 -> 2175.7115
A26: Người ghi sổ | C26: Kế toán trưởng | E26: Giám đốc
A27: (Ký , họ tên) | C27: (Ký , họ tên) | E27: (Ký , họ tên,đóng dấu)
A29: =A1 -> Công ty TNHH Thuận An | E29: Mẫu số : S 25 - SKT/DNN
A30: =A2 -> Ấp Chồng Nô 3, Xã Hòa Tân, Huyện Cầu Kè, Tỉnh Trà Vinh | E30: Ban hành theo quyết định số
E31: 133/2016/TT-BTC ngày 14/06/2016
E32: của bộ tài chính
A33: THẺ TÍNH GIÁ THÀNH SẢN PHẨM
A34: Tháng 2/2023
B35: ĐỊA ĐIỂM : | C35: HÒA ÂN
B36: Tên sản phẩm , dịch vụ : Điện năng lượng mặt trời
B37: Số lượng sản phẩm , dịch vụ hoàn thành trong kỳ : | E37: 19030
B38: Phương pháp tính giá thành : Giá thành thực tế
A40: Khoản mục chi phí sản xuất kinh doanh | B40: Chi phí SXKD dở dang đầu kỳ | C40: Chi phí SXKD phát sinh trong kỳ | D40: Chi phí SXKD dở dang cuối kỳ | E40: Giá thành sản phẩm dịch vụ trong kỳ
E41: Giá thành | F41: Giá thành đơn vị
A42: 1. Vật liệu
A44: 2. Nhân công | C44: 2800000 | E44: =C44 -> 2800000 | F44: =E44/E37 -> 147.1361
A46: 3. Máy
A48: 4. Chi phí chung
A49: Chi phí khấu hao hệ thống pin năng lượng mặt trời | C49: 21449563 | D49: =B49-(B49/12)*3 -> 0 | E49: =B49+C49-D49 -> 21449563 | F49: =E49/E37 -> 1127.1447
A50: Chi phí khấu hao thay tấm pin sửa chửa hệ thống | C50: 2872328 | E50: =B50+C50-D50 -> 2872328 | F50: =E50/E37 -> 150.93684
A51: Chi phí khấu hao sửa chửa hệ thống ĐMT | C51: 825978 | E51: =B51+C51-D51 -> 825978 | F51: =E51/E37 -> 43.403994
...

Sheet T3
A1: ='THONG TIN'!C3 -> Công ty TNHH Thuận An | E1: Mẫu số : S 25 - SKT/DNN
A2: ='THONG TIN'!C4 -> Ấp Chồng Nô 3, Xã Hòa Tân, Huyện Cầu Kè, Tỉnh Trà Vinh | E2: Ban hành theo quyết định số
E3: 133/2016/TT-BTC ngày 14/06/2016
E4: của bộ tài chính
A5: THẺ TÍNH GIÁ THÀNH SẢN PHẨM
A6: Tháng 3/2023
B7: ĐỊA ĐIỂM : | C7: HÒA TÂN
B8: Tên sản phẩm , dịch vụ : Điện năng lượng mặt trời
B9: Số lượng sản phẩm , dịch vụ hoàn thành trong kỳ : | E9: 9143
B10: Phương pháp tính giá thành : Giá thành thực tế
A12: Khoản mục chi phí sản xuất kinh doanh | B12: Chi phí SXKD dở dang đầu kỳ | C12: Chi phí SXKD phát sinh trong kỳ | D12: Chi phí SXKD dở dang cuối kỳ | E12: Giá thành sản phẩm dịch vụ trong kỳ
E13: Giá thành | F13: Giá thành đơn vị
A14: 1. Vật liệu
A16: 2. Nhân công | C16: =1400000 -> 1400000 | E16: =C16 -> 1400000 | F16: =E16/E9 -> 153.12261
A18: 3. Máy
A20: 4. Chi phí chung
A21: Chi phí khấu hao hệ thống pin năng lượng mặt trời | C21: =12823592+(B21/12) -> 12823592 | D21: =B21-(B21/12)*3 -> 0 | E21: =B21+C21-D21 -> 12823592 | F21: =E21/E9 -> 1402.5585
A22: Chi phí khấu hao thay tấm pin sửa chửa hệ thống | C22: 897603 | D22: =B22-(B22/12)*3 -> 0 | E22: =B22+C22-D22 -> 897603 | F22: =E22/E9 -> 98.173794
A24: Cộng | B24: =B21+B23 -> 0 | C24: =C16+C21+C22 -> 15121195 | D24: =D16+D21+D22 -> 0 | E24: =E16+E21+E22 -> 15121195 | F24: =F16+F21+F22 -> 1653.8549
A26: Người ghi sổ | C26: Kế toán trưởng | E26: Giám đốc
A27: (Ký , họ tên) | C27: (Ký , họ tên) | E27: (Ký , họ tên,đóng dấu)
A29: =A1 -> Công ty TNHH Thuận An | E29: Mẫu số : S 25 - SKT/DNN
A30: =A2 -> Ấp Chồng Nô 3, Xã Hòa Tân, Huyện Cầu Kè, Tỉnh Trà Vinh | E30: Ban hành theo quyết định số
E31: 133/2016/TT-BTC ngày 14/06/2016
E32: của bộ tài chính
A33: THẺ TÍNH GIÁ THÀNH SẢN PHẨM
A34: Tháng 3/2023
B35: ĐỊA ĐIỂM : | C35: HÒA ÂN
B36: Tên sản phẩm , dịch vụ : Điện năng lượng mặt trời
B37: Số lượng sản phẩm , dịch vụ hoàn thành trong kỳ : | E37: 23798
B38: Phương pháp tính giá thành : Giá thành thực tế
A40: Khoản mục chi phí sản xuất kinh doanh | B40: Chi phí SXKD dở dang đầu kỳ | C40: Chi phí SXKD phát sinh trong kỳ | D40: Chi phí SXKD dở dang cuối kỳ | E40: Giá thành sản phẩm dịch vụ trong kỳ
E41: Giá thành | F41: Giá thành đơn vị
A42: 1. Vật liệu
A44: 2. Nhân công | C44: 2800000 | E44: =C44 -> 2800000 | F44: =E44/E37 -> 117.65695
A46: 3. Máy
A48: 4. Chi phí chung
A49: Chi phí khấu hao hệ thống pin năng lượng mặt trời | C49: 21449563 | D49: =B49-(B49/12)*3 -> 0 | E49: =B49+C49-D49 -> 21449563 | F49: =E49/E37 -> 901.31788
A50: Chi phí khấu hao thay tấm pin sửa chửa hệ thống | C50: 2872328 | E50: =B50+C50-D50 -> 2872328 | F50: =E50/E37 -> 120.69619
A51: Chi phí khấu hao sửa chửa hệ thống ĐMT | C51: =825978+(B51/12) -> 825978 | E51: =B51+C51-D51 -> 825978 | F51: =E51/E37 -> 34.707875
...

Sheet T4
A1: ='THONG TIN'!C3 -> Công ty TNHH Thuận An | E1: Mẫu số : S 25 - SKT/DNN
A2: ='THONG TIN'!C4 -> Ấp Chồng Nô 3, Xã Hòa Tân, Huyện Cầu Kè, Tỉnh Trà Vinh | E2: Ban hành theo quyết định số
E3: 133/2016/TT-BTC ngày 14/06/2016
E4: của bộ tài chính
A5: THẺ TÍNH GIÁ THÀNH SẢN PHẨM
A6: Tháng 4/2023
B7: ĐỊA ĐIỂM : | C7: HÒA TÂN
B8: Tên sản phẩm , dịch vụ : Điện năng lượng mặt trời
B9: Số lượng sản phẩm , dịch vụ hoàn thành trong kỳ : | E9: 8240
B10: Phương pháp tính giá thành : Giá thành thực tế
A12: Khoản mục chi phí sản xuất kinh doanh | B12: Chi phí SXKD dở dang đầu kỳ | C12: Chi phí SXKD phát sinh trong kỳ | D12: Chi phí SXKD dở dang cuối kỳ | E12: Giá thành sản phẩm dịch vụ trong kỳ
E13: Giá thành | F13: Giá thành đơn vị
A14: 1. Vật liệu
A16: 2. Nhân công | C16: =1400000 -> 1400000 | E16: =C16 -> 1400000 | F16: =E16/E9 -> 169.90291
A18: 3. Máy
A20: 4. Chi phí chung
A21: Chi phí khấu hao hệ thống pin năng lượng mặt trời | C21: =12823592+(B21/12) -> 12823592 | D21: =B21-(B21/12)*3 -> 0 | E21: =B21+C21-D21 -> 12823592 | F21: =E21/E9 -> 1556.2612
A22: Chi phí khấu hao thay tấm pin sửa chửa hệ thống | C22: 897603 | D22: =B22-(B22/12)*3 -> 0 | E22: =B22+C22-D22 -> 897603 | F22: =E22/E9 -> 108.9324
A24: Cộng | B24: =B21+B23 -> 0 | C24: =C16+C21+C22 -> 15121195 | D24: =D16+D21+D22 -> 0 | E24: =E16+E21+E22 -> 15121195 | F24: =F16+F21+F22 -> 1835.0965
A26: Người ghi sổ | C26: Kế toán trưởng | E26: Giám đốc
A27: (Ký , họ tên) | C27: (Ký , họ tên) | E27: (Ký , họ tên,đóng dấu)
A29: =A1 -> Công ty TNHH Thuận An | E29: Mẫu số : S 25 - SKT/DNN
A30: =A2 -> Ấp Chồng Nô 3, Xã Hòa Tân, Huyện Cầu Kè, Tỉnh Trà Vinh | E30: Ban hành theo quyết định số
E31: 133/2016/TT-BTC ngày 14/06/2016
E32: của bộ tài chính
A33: THẺ TÍNH GIÁ THÀNH SẢN PHẨM
A34: Tháng 4/2023
B35: ĐỊA ĐIỂM : | C35: HÒA ÂN
B36: Tên sản phẩm , dịch vụ : Điện năng lượng mặt trời
B37: Số lượng sản phẩm , dịch vụ hoàn thành trong kỳ : | E37: 20553
B38: Phương pháp tính giá thành : Giá thành thực tế
A40: Khoản mục chi phí sản xuất kinh doanh | B40: Chi phí SXKD dở dang đầu kỳ | C40: Chi phí SXKD phát sinh trong kỳ | D40: Chi phí SXKD dở dang cuối kỳ | E40: Giá thành sản phẩm dịch vụ trong kỳ
E41: Giá thành | F41: Giá thành đơn vị
A42: 1. Vật liệu
A44: 2. Nhân công | C44: 2800000 | E44: =C44 -> 2800000 | F44: =E44/E37 -> 136.23315
A46: 3. Máy
A48: 4. Chi phí chung
A49: Chi phí khấu hao hệ thống pin năng lượng mặt trời | C49: 21449563 | D49: =B49-(B49/12)*3 -> 0 | E49: =B49+C49-D49 -> 21449563 | F49: =E49/E37 -> 1043.622
A50: Chi phí khấu hao thay tấm pin sửa chửa hệ thống | C50: 2872328 | E50: =B50+C50-D50 -> 2872328 | F50: =E50/E37 -> 139.75225
A51: Chi phí khấu hao sửa chửa hệ thống ĐMT | C51: =825978+(B51/12) -> 825978 | E51: =B51+C51-D51 -> 825978 | F51: =E51/E37 -> 40.18771
...

Sheet T5
A1: ='THONG TIN'!C3 -> Công ty TNHH Thuận An | E1: Mẫu số : S 25 - SKT/DNN
A2: ='THONG TIN'!C4 -> Ấp Chồng Nô 3, Xã Hòa Tân, Huyện Cầu Kè, Tỉnh Trà Vinh | E2: Ban hành theo quyết định số
E3: 133/2016/TT-BTC ngày 14/06/2016
E4: của bộ tài chính
A5: THẺ TÍNH GIÁ THÀNH SẢN PHẨM
A6: Tháng 5/2023
B7: ĐỊA ĐIỂM : | C7: HÒA TÂN
B8: Tên sản phẩm , dịch vụ : Điện năng lượng mặt trời
B9: Số lượng sản phẩm , dịch vụ hoàn thành trong kỳ : | E9: 6781
B10: Phương pháp tính giá thành : Giá thành thực tế
A12: Khoản mục chi phí sản xuất kinh doanh | B12: Chi phí SXKD dở dang đầu kỳ | C12: Chi phí SXKD phát sinh trong kỳ | D12: Chi phí SXKD dở dang cuối kỳ | E12: Giá thành sản phẩm dịch vụ trong kỳ
E13: Giá thành | F13: Giá thành đơn vị
A14: 1. Vật liệu
A16: 2. Nhân công | C16: =1400000 -> 1400000 | E16: =C16 -> 1400000 | F16: =E16/E9 -> 206.45922
A18: 3. Máy
A20: 4. Chi phí chung
A21: Chi phí khấu hao hệ thống pin năng lượng mặt trời | C21: =12823592+(B21/12) -> 12823592 | D21: =B21-(B21/12)*3 -> 0 | E21: =B21+C21-D21 -> 12823592 | F21: =E21/E9 -> 1891.1063
A22: Chi phí khấu hao thay tấm pin sửa chửa hệ thống | C22: 897603 | D22: =B22-(B22/12)*3 -> 0 | E22: =B22+C22-D22 -> 897603 | F22: =E22/E9 -> 132.3703
A24: Cộng | B24: =B21+B23 -> 0 | C24: =C16+C21+C22 -> 15121195 | D24: =D16+D21+D22 -> 0 | E24: =E16+E21+E22 -> 15121195 | F24: =F16+F21+F22 -> 2229.9359
A26: Người ghi sổ | C26: Kế toán trưởng | E26: Giám đốc
A27: (Ký , họ tên) | C27: (Ký , họ tên) | E27: (Ký , họ tên,đóng dấu)
A29: =A1 -> Công ty TNHH Thuận An | E29: Mẫu số : S 25 - SKT/DNN
A30: =A2 -> Ấp Chồng Nô 3, Xã Hòa Tân, Huyện Cầu Kè, Tỉnh Trà Vinh | E30: Ban hành theo quyết định số
E31: 133/2016/TT-BTC ngày 14/06/2016
E32: của bộ tài chính
A33: THẺ TÍNH GIÁ THÀNH SẢN PHẨM
A34: Tháng 5 /2023
B35: ĐỊA ĐIỂM : | C35: HÒA ÂN
B36: Tên sản phẩm , dịch vụ : Điện năng lượng mặt trời
B37: Số lượng sản phẩm , dịch vụ hoàn thành trong kỳ : | E37: 17170
B38: Phương pháp tính giá thành : Giá thành thực tế
A40: Khoản mục chi phí sản xuất kinh doanh | B40: Chi phí SXKD dở dang đầu kỳ | C40: Chi phí SXKD phát sinh trong kỳ | D40: Chi phí SXKD dở dang cuối kỳ | E40: Giá thành sản phẩm dịch vụ trong kỳ
E41: Giá thành | F41: Giá thành đơn vị
A42: 1. Vật liệu
A44: 2. Nhân công | C44: 2800000 | E44: =C44 -> 2800000 | F44: =E44/E37 -> 163.07513
A46: 3. Máy
A48: 4. Chi phí chung
A49: Chi phí khấu hao hệ thống pin năng lượng mặt trời | C49: 21449563 | D49: =B49-(B49/12)*3 -> 0 | E49: =B49+C49-D49 -> 21449563 | F49: =E49/E37 -> 1249.2465
A50: Chi phí khấu hao thay tấm pin sửa chửa hệ thống | C50: 2872328 | E50: =B50+C50-D50 -> 2872328 | F50: =E50/E37 -> 167.28759
A51: Chi phí khấu hao sửa chửa hệ thống ĐMT | C51: =825978+(B51/12) -> 825978 | E51: =B51+C51-D51 -> 825978 | F51: =E51/E37 -> 48.105882
...

Sheet T6
A1: ='THONG TIN'!C3 -> Công ty TNHH Thuận An | E1: Mẫu số : S 25 - SKT/DNN
A2: ='THONG TIN'!C4 -> Ấp Chồng Nô 3, Xã Hòa Tân, Huyện Cầu Kè, Tỉnh Trà Vinh | E2: Ban hành theo quyết định số
E3: 133/2016/TT-BTC ngày 14/06/2016
E4: của bộ tài chính
A5: THẺ TÍNH GIÁ THÀNH SẢN PHẨM
A6: Tháng 6/2023
B7: ĐỊA ĐIỂM : | C7: HÒA TÂN
B8: Tên sản phẩm , dịch vụ : Điện năng lượng mặt trời
B9: Số lượng sản phẩm , dịch vụ hoàn thành trong kỳ : | E9: 7690
B10: Phương pháp tính giá thành : Giá thành thực tế
A12: Khoản mục chi phí sản xuất kinh doanh | B12: Chi phí SXKD dở dang đầu kỳ | C12: Chi phí SXKD phát sinh trong kỳ | D12: Chi phí SXKD dở dang cuối kỳ | E12: Giá thành sản phẩm dịch vụ trong kỳ
E13: Giá thành | F13: Giá thành đơn vị
A14: 1. Vật liệu
A16: 2. Nhân công | C16: =1400000 -> 1400000 | E16: =C16 -> 1400000 | F16: =E16/E9 -> 182.05462
A18: 3. Máy
A20: 4. Chi phí chung
A21: Chi phí khấu hao hệ thống pin năng lượng mặt trời | C21: =12823592+(B21/12) -> 12823592 | D21: =B21-(B21/12)*3 -> 0 | E21: =B21+C21-D21 -> 12823592 | F21: =E21/E9 -> 1667.5672
A22: Chi phí khấu hao thay tấm pin sửa chửa hệ thống | C22: 897603 | D22: =B22-(B22/12)*3 -> 0 | E22: =B22+C22-D22 -> 897603 | F22: =E22/E9 -> 116.72341
A24: Cộng | B24: =B21+B23 -> 0 | C24: =C16+C21+C22 -> 15121195 | D24: =D16+D21+D22 -> 0 | E24: =E16+E21+E22 -> 15121195 | F24: =F16+F21+F22 -> 1966.3453
A26: Người ghi sổ | C26: Kế toán trưởng | E26: Giám đốc
A27: (Ký , họ tên) | C27: (Ký , họ tên) | E27: (Ký , họ tên,đóng dấu)
A29: =A1 -> Công ty TNHH Thuận An | E29: Mẫu số : S 25 - SKT/DNN
A30: =A2 -> Ấp Chồng Nô 3, Xã Hòa Tân, Huyện Cầu Kè, Tỉnh Trà Vinh | E30: Ban hành theo quyết định số
E31: 133/2016/TT-BTC ngày 14/06/2016
E32: của bộ tài chính
A33: THẺ TÍNH GIÁ THÀNH SẢN PHẨM
A34: Tháng 6 /2023
B35: ĐỊA ĐIỂM : | C35: HÒA ÂN
B36: Tên sản phẩm , dịch vụ : Điện năng lượng mặt trời
B37: Số lượng sản phẩm , dịch vụ hoàn thành trong kỳ : | E37: 16936
B38: Phương pháp tính giá thành : Giá thành thực tế
A40: Khoản mục chi phí sản xuất kinh doanh | B40: Chi phí SXKD dở dang đầu kỳ | C40: Chi phí SXKD phát sinh trong kỳ | D40: Chi phí SXKD dở dang cuối kỳ | E40: Giá thành sản phẩm dịch vụ trong kỳ
E41: Giá thành | F41: Giá thành đơn vị
A42: 1. Vật liệu
A44: 2. Nhân công | C44: 2800000 | E44: =C44 -> 2800000 | F44: =E44/E37 -> 165.32829
A46: 3. Máy
A48: 4. Chi phí chung
A49: Chi phí khấu hao hệ thống pin năng lượng mặt trời | C49: 21449563 | D49: =B49-(B49/12)*3 -> 0 | E49: =B49+C49-D49 -> 21449563 | F49: =E49/E37 -> 1266.507
A50: Chi phí khấu hao thay tấm pin sửa chửa hệ thống | C50: 2872328 | E50: =B50+C50-D50 -> 2872328 | F50: =E50/E37 -> 169.59896
A51: Chi phí khấu hao sửa chửa hệ thống ĐMT | C51: =825978+(B51/12) -> 825978 | E51: =B51+C51-D51 -> 825978 | F51: =E51/E37 -> 48.770548
...

Sheet T7
A1: ='THONG TIN'!C3 -> Công ty TNHH Thuận An | E1: Mẫu số : S 25 - SKT/DNN
A2: ='THONG TIN'!C4 -> Ấp Chồng Nô 3, Xã Hòa Tân, Huyện Cầu Kè, Tỉnh Trà Vinh | E2: Ban hành theo quyết định số
E3: 133/2016/TT-BTC ngày 14/06/2016
E4: của bộ tài chính
A5: THẺ TÍNH GIÁ THÀNH SẢN PHẨM
A6: Tháng 7/2023
B7: ĐỊA ĐIỂM : | C7: HÒA TÂN
B8: Tên sản phẩm , dịch vụ : Điện năng lượng mặt trời
B9: Số lượng sản phẩm , dịch vụ hoàn thành trong kỳ : | E9: 6494
B10: Phương pháp tính giá thành : Giá thành thực tế
A12: Khoản mục chi phí sản xuất kinh doanh | B12: Chi phí SXKD dở dang đầu kỳ | C12: Chi phí SXKD phát sinh trong kỳ | D12: Chi phí SXKD dở dang cuối kỳ | E12: Giá thành sản phẩm dịch vụ trong kỳ
E13: Giá thành | F13: Giá thành đơn vị
A14: 1. Vật liệu
A16: 2. Nhân công | C16: =1400000 -> 1400000 | E16: =C16 -> 1400000 | F16: =E16/E9 -> 215.58362
A18: 3. Máy
A20: 4. Chi phí chung
A21: Chi phí khấu hao hệ thống pin năng lượng mặt trời | C21: =12823592+(B21/12) -> 12823592 | D21: =B21-(B21/12)*3 -> 0 | E21: =B21+C21-D21 -> 12823592 | F21: =E21/E9 -> 1974.6831
A22: Chi phí khấu hao thay tấm pin sửa chửa hệ thống | C22: 897603 | D22: =B22-(B22/12)*3 -> 0 | E22: =B22+C22-D22 -> 897603 | F22: =E22/E9 -> 138.22036
A24: Cộng | B24: =B21+B23 -> 0 | C24: =C16+C21+C22 -> 15121195 | D24: =D16+D21+D22 -> 0 | E24: =E16+E21+E22 -> 15121195 | F24: =F16+F21+F22 -> 2328.4871
A26: Người ghi sổ | C26: Kế toán trưởng | E26: Giám đốc
A27: (Ký , họ tên) | C27: (Ký , họ tên) | E27: (Ký , họ tên,đóng dấu)
A29: =A1 -> Công ty TNHH Thuận An | E29: Mẫu số : S 25 - SKT/DNN
A30: =A2 -> Ấp Chồng Nô 3, Xã Hòa Tân, Huyện Cầu Kè, Tỉnh Trà Vinh | E30: Ban hành theo quyết định số
E31: 133/2016/TT-BTC ngày 14/06/2016
E32: của bộ tài chính
A33: THẺ TÍNH GIÁ THÀNH SẢN PHẨM
A34: Tháng 7 /2023
B35: ĐỊA ĐIỂM : | C35: HÒA ÂN
B36: Tên sản phẩm , dịch vụ : Điện năng lượng mặt trời
B37: Số lượng sản phẩm , dịch vụ hoàn thành trong kỳ : | E37: 16130
B38: Phương pháp tính giá thành : Giá thành thực tế
A40: Khoản mục chi phí sản xuất kinh doanh | B40: Chi phí SXKD dở dang đầu kỳ | C40: Chi phí SXKD phát sinh trong kỳ | D40: Chi phí SXKD dở dang cuối kỳ | E40: Giá thành sản phẩm dịch vụ trong kỳ
E41: Giá thành | F41: Giá thành đơn vị
A42: 1. Vật liệu
A44: 2. Nhân công | C44: 2800000 | E44: =C44 -> 2800000 | F44: =E44/E37 -> 173.58958
A46: 3. Máy
A48: 4. Chi phí chung
A49: Chi phí khấu hao hệ thống pin năng lượng mặt trời | C49: 21449563 | D49: =B49-(B49/12)*3 -> 0 | E49: =B49+C49-D49 -> 21449563 | F49: =E49/E37 -> 1329.7931
A50: Chi phí khấu hao thay tấm pin sửa chửa hệ thống | C50: 2872328 | E50: =B50+C50-D50 -> 2872328 | F50: =E50/E37 -> 178.07365
A51: Chi phí khấu hao sửa chửa hệ thống ĐMT | C51: =825978+(B51/12) -> 825978 | E51: =B51+C51-D51 -> 825978 | F51: =E51/E37 -> 51.207564
...

Sheet T8
A1: ='THONG TIN'!C3 -> Công ty TNHH Thuận An | E1: Mẫu số : S 25 - SKT/DNN
A2: ='THONG TIN'!C4 -> Ấp Chồng Nô 3, Xã Hòa Tân, Huyện Cầu Kè, Tỉnh Trà Vinh | E2: Ban hành theo quyết định số
E3: 133/2016/TT-BTC ngày 14/06/2016
E4: của bộ tài chính
A5: THẺ TÍNH GIÁ THÀNH SẢN PHẨM
A6: Tháng 8/2023
B7: ĐỊA ĐIỂM : | C7: HÒA TÂN
B8: Tên sản phẩm , dịch vụ : Điện năng lượng mặt trời
B9: Số lượng sản phẩm , dịch vụ hoàn thành trong kỳ : | E9: 6405
B10: Phương pháp tính giá thành : Giá thành thực tế
A12: Khoản mục chi phí sản xuất kinh doanh | B12: Chi phí SXKD dở dang đầu kỳ | C12: Chi phí SXKD phát sinh trong kỳ | D12: Chi phí SXKD dở dang cuối kỳ | E12: Giá thành sản phẩm dịch vụ trong kỳ
E13: Giá thành | F13: Giá thành đơn vị
A14: 1. Vật liệu
A16: 2. Nhân công | C16: =1400000 -> 1400000 | E16: =C16 -> 1400000 | F16: =E16/E9 -> 218.57923
A18: 3. Máy
A20: 4. Chi phí chung
A21: Chi phí khấu hao hệ thống pin năng lượng mặt trời | C21: =12823592+(B21/12) -> 12823592 | D21: =B21-(B21/12)*3 -> 0 | E21: =B21+C21-D21 -> 12823592 | F21: =E21/E9 -> 2002.1221
A22: Chi phí khấu hao thay tấm pin sửa chửa hệ thống | C22: 897603 | D22: =B22-(B22/12)*3 -> 0 | E22: =B22+C22-D22 -> 897603 | F22: =E22/E9 -> 140.14098
A24: Cộng | B24: =B21+B23 -> 0 | C24: =C16+C21+C22 -> 15121195 | D24: =D16+D21+D22 -> 0 | E24: =E16+E21+E22 -> 15121195 | F24: =F16+F21+F22 -> 2360.8423
A26: Người ghi sổ | C26: Kế toán trưởng | E26: Giám đốc
A27: (Ký , họ tên) | C27: (Ký , họ tên) | E27: (Ký , họ tên,đóng dấu)
A29: =A1 -> Công ty TNHH Thuận An | E29: Mẫu số : S 25 - SKT/DNN
A30: =A2 -> Ấp Chồng Nô 3, Xã Hòa Tân, Huyện Cầu Kè, Tỉnh Trà Vinh | E30: Ban hành theo quyết định số
E31: 133/2016/TT-BTC ngày 14/06/2016
E32: của bộ tài chính
A33: THẺ TÍNH GIÁ THÀNH SẢN PHẨM
A34: Tháng 8 /2023
B35: ĐỊA ĐIỂM : | C35: HÒA ÂN
B36: Tên sản phẩm , dịch vụ : Điện năng lượng mặt trời
B37: Số lượng sản phẩm , dịch vụ hoàn thành trong kỳ : | E37: 19540
B38: Phương pháp tính giá thành : Giá thành thực tế
A40: Khoản mục chi phí sản xuất kinh doanh | B40: Chi phí SXKD dở dang đầu kỳ | C40: Chi phí SXKD phát sinh trong kỳ | D40: Chi phí SXKD dở dang cuối kỳ | E40: Giá thành sản phẩm dịch vụ trong kỳ
E41: Giá thành | F41: Giá thành đơn vị
A42: 1. Vật liệu
A44: 2. Nhân công | C44: 2800000 | E44: =C44 -> 2800000 | F44: =E44/E37 -> 143.2958
A46: 3. Máy
A48: 4. Chi phí chung
A49: Chi phí khấu hao hệ thống pin năng lượng mặt trời | C49: 21449563 | D49: =B49-(B49/12)*3 -> 0 | E49: =B49+C49-D49 -> 21449563 | F49: =E49/E37 -> 1097.7258
A50: Chi phí khấu hao thay tấm pin sửa chửa hệ thống | C50: 2872328 | E50: =B50+C50-D50 -> 2872328 | F50: =E50/E37 -> 146.99734
A51: Chi phí khấu hao sửa chửa hệ thống ĐMT | C51: =825978+(B51/12) -> 825978 | E51: =B51+C51-D51 -> 825978 | F51: =E51/E37 -> 42.271136
...

Sheet T9
A1: ='THONG TIN'!C3 -> Công ty TNHH Thuận An | E1: Mẫu số : S 25 - SKT/DNN
A2: ='THONG TIN'!C4 -> Ấp Chồng Nô 3, Xã Hòa Tân, Huyện Cầu Kè, Tỉnh Trà Vinh | E2: Ban hành theo quyết định số
E3: 133/2016/TT-BTC ngày 14/06/2016
E4: của bộ tài chính
A5: THẺ TÍNH GIÁ THÀNH SẢN PHẨM
A6: Tháng 9/2023
B7: ĐỊA ĐIỂM : | C7: HÒA TÂN
B8: Tên sản phẩm , dịch vụ : Điện năng lượng mặt trời
B9: Số lượng sản phẩm , dịch vụ hoàn thành trong kỳ : | E9: 6440
B10: Phương pháp tính giá thành : Giá thành thực tế
A12: Khoản mục chi phí sản xuất kinh doanh | B12: Chi phí SXKD dở dang đầu kỳ | C12: Chi phí SXKD phát sinh trong kỳ | D12: Chi phí SXKD dở dang cuối kỳ | E12: Giá thành sản phẩm dịch vụ trong kỳ
E13: Giá thành | F13: Giá thành đơn vị
A14: 1. Vật liệu
A16: 2. Nhân công | C16: =1400000 -> 1400000 | E16: =C16 -> 1400000 | F16: =E16/E9 -> 217.3913
A18: 3. Máy
A20: 4. Chi phí chung
A21: Chi phí khấu hao hệ thống pin năng lượng mặt trời | C21: =12823592+(B21/12) -> 12823592 | D21: =B21-(B21/12)*3 -> 0 | E21: =B21+C21-D21 -> 12823592 | F21: =E21/E9 -> 1991.241
A22: Chi phí khấu hao thay tấm pin sửa chửa hệ thống | C22: 897603 | D22: =B22-(B22/12)*3 -> 0 | E22: =B22+C22-D22 -> 897603 | F22: =E22/E9 -> 139.37935
A24: Cộng | B24: =B21+B23 -> 0 | C24: =C16+C21+C22 -> 15121195 | D24: =D16+D21+D22 -> 0 | E24: =E16+E21+E22 -> 15121195 | F24: =F16+F21+F22 -> 2348.0116
A26: Người ghi sổ | C26: Kế toán trưởng | E26: Giám đốc
A27: (Ký , họ tên) | C27: (Ký , họ tên) | E27: (Ký , họ tên,đóng dấu)
A29: =A1 -> Công ty TNHH Thuận An | E29: Mẫu số : S 25 - SKT/DNN
A30: =A2 -> Ấp Chồng Nô 3, Xã Hòa Tân, Huyện Cầu Kè, Tỉnh Trà Vinh | E30: Ban hành theo quyết định số
E31: 133/2016/TT-BTC ngày 14/06/2016
E32: của bộ tài chính
A33: THẺ TÍNH GIÁ THÀNH SẢN PHẨM
A34: Tháng 9 /2023
B35: ĐỊA ĐIỂM : | C35: HÒA ÂN
B36: Tên sản phẩm , dịch vụ : Điện năng lượng mặt trời
B37: Số lượng sản phẩm , dịch vụ hoàn thành trong kỳ : | E37: 16268
B38: Phương pháp tính giá thành : Giá thành thực tế
A40: Khoản mục chi phí sản xuất kinh doanh | B40: Chi phí SXKD dở dang đầu kỳ | C40: Chi phí SXKD phát sinh trong kỳ | D40: Chi phí SXKD dở dang cuối kỳ | E40: Giá thành sản phẩm dịch vụ trong kỳ
E41: Giá thành | F41: Giá thành đơn vị
A42: 1. Vật liệu
A44: 2. Nhân công | C44: 2800000 | E44: =C44 -> 2800000 | F44: =E44/E37 -> 172.11704
A46: 3. Máy
A48: 4. Chi phí chung
A49: Chi phí khấu hao hệ thống pin năng lượng mặt trời | C49: 21449563 | D49: =B49-(B49/12)*3 -> 0 | E49: =B49+C49-D49 -> 21449563 | F49: =E49/E37 -> 1318.5126
A50: Chi phí khấu hao thay tấm pin sửa chửa hệ thống | C50: 2872328 | E50: =B50+C50-D50 -> 2872328 | F50: =E50/E37 -> 176.56307
A51: Chi phí khấu hao sửa chửa hệ thống ĐMT | C51: =825978+(B51/12) -> 825978 | E51: =B51+C51-D51 -> 825978 | F51: =E51/E37 -> 50.773174
...

Sheet T10
A1: ='THONG TIN'!C3 -> Công ty TNHH Thuận An | E1: Mẫu số : S 25 - SKT/DNN
A2: ='THONG TIN'!C4 -> Ấp Chồng Nô 3, Xã Hòa Tân, Huyện Cầu Kè, Tỉnh Trà Vinh | E2: Ban hành theo quyết định số
E3: 133/2016/TT-BTC ngày 14/06/2016
E4: của bộ tài chính
A5: THẺ TÍNH GIÁ THÀNH SẢN PHẨM
A6: Tháng 10/2023
B7: ĐỊA ĐIỂM : | C7: HÒA TÂN
B8: Tên sản phẩm , dịch vụ : Điện năng lượng mặt trời
B9: Số lượng sản phẩm , dịch vụ hoàn thành trong kỳ : | E9: 7785
B10: Phương pháp tính giá thành : Giá thành thực tế
A12: Khoản mục chi phí sản xuất kinh doanh | B12: Chi phí SXKD dở dang đầu kỳ | C12: Chi phí SXKD phát sinh trong kỳ | D12: Chi phí SXKD dở dang cuối kỳ | E12: Giá thành sản phẩm dịch vụ trong kỳ
E13: Giá thành | F13: Giá thành đơn vị
A14: 1. Vật liệu
A16: 2. Nhân công | C16: =1400000 -> 1400000 | E16: =C16 -> 1400000 | F16: =E16/E9 -> 179.83301
A18: 3. Máy
A20: 4. Chi phí chung
A21: Chi phí khấu hao hệ thống pin năng lượng mặt trời | C21: =12823592+(B21/12) -> 12823592 | D21: =B21-(B21/12)*3 -> 0 | E21: =B21+C21-D21 -> 12823592 | F21: =E21/E9 -> 1647.218
A22: Chi phí khấu hao thay tấm pin sửa chửa hệ thống | C22: 897603 | D22: =B22-(B22/12)*3 -> 0 | E22: =B22+C22-D22 -> 897603 | F22: =E22/E9 -> 115.29904
A24: Cộng | B24: =B21+B23 -> 0 | C24: =C16+C21+C22 -> 15121195 | D24: =D16+D21+D22 -> 0 | E24: =E16+E21+E22 -> 15121195 | F24: =F16+F21+F22 -> 1942.35
A26: Người ghi sổ | C26: Kế toán trưởng | E26: Giám đốc
A27: (Ký , họ tên) | C27: (Ký , họ tên) | E27: (Ký , họ tên,đóng dấu)
A29: =A1 -> Công ty TNHH Thuận An | E29: Mẫu số : S 25 - SKT/DNN
A30: =A2 -> Ấp Chồng Nô 3, Xã Hòa Tân, Huyện Cầu Kè, Tỉnh Trà Vinh | E30: Ban hành theo quyết định số
E31: 133/2016/TT-BTC ngày 14/06/2016
E32: của bộ tài chính
A33: THẺ TÍNH GIÁ THÀNH SẢN PHẨM
A34: Tháng 10 /2023
B35: ĐỊA ĐIỂM : | C35: HÒA ÂN
B36: Tên sản phẩm , dịch vụ : Điện năng lượng mặt trời
B37: Số lượng sản phẩm , dịch vụ hoàn thành trong kỳ : | E37: 17856
B38: Phương pháp tính giá thành : Giá thành thực tế
A40: Khoản mục chi phí sản xuất kinh doanh | B40: Chi phí SXKD dở dang đầu kỳ | C40: Chi phí SXKD phát sinh trong kỳ | D40: Chi phí SXKD dở dang cuối kỳ | E40: Giá thành sản phẩm dịch vụ trong kỳ
E41: Giá thành | F41: Giá thành đơn vị
A42: 1. Vật liệu
A44: 2. Nhân công | C44: 2800000 | E44: =C44 -> 2800000 | F44: =E44/E37 -> 156.81004
A46: 3. Máy
A48: 4. Chi phí chung
A49: Chi phí khấu hao hệ thống pin năng lượng mặt trời | C49: 21449563 | D49: =B49-(B49/12)*3 -> 0 | E49: =B49+C49-D49 -> 21449563 | F49: =E49/E37 -> 1201.2524
A50: Chi phí khấu hao thay tấm pin sửa chửa hệ thống | C50: 2872328 | E50: =B50+C50-D50 -> 2872328 | F50: =E50/E37 -> 160.86066
A51: Chi phí khấu hao sửa chửa hệ thống ĐMT | C51: =825978+(B51/12) -> 825978 | E51: =B51+C51-D51 -> 825978 | F51: =E51/E37 -> 46.257728
...

Sheet T11
A1: ='THONG TIN'!C3 -> Công ty TNHH Thuận An | E1: Mẫu số : S 25 - SKT/DNN
A2: ='THONG TIN'!C4 -> Ấp Chồng Nô 3, Xã Hòa Tân, Huyện Cầu Kè, Tỉnh Trà Vinh | E2: Ban hành theo quyết định số
E3: 133/2016/TT-BTC ngày 14/06/2016
E4: của bộ tài chính
A5: THẺ TÍNH GIÁ THÀNH SẢN PHẨM
A6: Tháng 11/2023
B7: ĐỊA ĐIỂM : | C7: HÒA TÂN
B8: Tên sản phẩm , dịch vụ : Điện năng lượng mặt trời
B9: Số lượng sản phẩm , dịch vụ hoàn thành trong kỳ : | E9: 7303
B10: Phương pháp tính giá thành : Giá thành thực tế
A12: Khoản mục chi phí sản xuất kinh doanh | B12: Chi phí SXKD dở dang đầu kỳ | C12: Chi phí SXKD phát sinh trong kỳ | D12: Chi phí SXKD dở dang cuối kỳ | E12: Giá thành sản phẩm dịch vụ trong kỳ
E13: Giá thành | F13: Giá thành đơn vị
A14: 1. Vật liệu
A16: 2. Nhân công | C16: =1400000 -> 1400000 | E16: =C16 -> 1400000 | F16: =E16/E9 -> 191.70204
A18: 3. Máy
A20: 4. Chi phí chung
A21: Chi phí khấu hao hệ thống pin năng lượng mặt trời | C21: =12823592+(B21/12) -> 12823592 | D21: =B21-(B21/12)*3 -> 0 | E21: =B21+C21-D21 -> 12823592 | F21: =E21/E9 -> 1755.9348
A22: Chi phí khấu hao thay tấm pin sửa chửa hệ thống | C22: 897603 | D22: =B22-(B22/12)*3 -> 0 | E22: =B22+C22-D22 -> 897603 | F22: =E22/E9 -> 122.9088
A24: Cộng | B24: =B21+B23 -> 0 | C24: =C16+C21+C22 -> 15121195 | D24: =D16+D21+D22 -> 0 | E24: =E16+E21+E22 -> 15121195 | F24: =F16+F21+F22 -> 2070.5457
A26: Người ghi sổ | C26: Kế toán trưởng | E26: Giám đốc
A27: (Ký , họ tên) | C27: (Ký , họ tên) | E27: (Ký , họ tên,đóng dấu)
A29: =A1 -> Công ty TNHH Thuận An | E29: Mẫu số : S 25 - SKT/DNN
A30: =A2 -> Ấp Chồng Nô 3, Xã Hòa Tân, Huyện Cầu Kè, Tỉnh Trà Vinh | E30: Ban hành theo quyết định số
E31: 133/2016/TT-BTC ngày 14/06/2016
E32: của bộ tài chính
A33: THẺ TÍNH GIÁ THÀNH SẢN PHẨM
A34: Tháng 11 /2023
B35: ĐỊA ĐIỂM : | C35: HÒA ÂN
B36: Tên sản phẩm , dịch vụ : Điện năng lượng mặt trời
B37: Số lượng sản phẩm , dịch vụ hoàn thành trong kỳ : | E37: 17976
B38: Phương pháp tính giá thành : Giá thành thực tế
A40: Khoản mục chi phí sản xuất kinh doanh | B40: Chi phí SXKD dở dang đầu kỳ | C40: Chi phí SXKD phát sinh trong kỳ | D40: Chi phí SXKD dở dang cuối kỳ | E40: Giá thành sản phẩm dịch vụ trong kỳ
E41: Giá thành | F41: Giá thành đơn vị
A42: 1. Vật liệu
A44: 2. Nhân công | C44: 2800000 | E44: =C44 -> 2800000 | F44: =E44/E37 -> 155.76324
A46: 3. Máy
A48: 4. Chi phí chung
A49: Chi phí khấu hao hệ thống pin năng lượng mặt trời | C49: 21449563 | D49: =B49-(B49/12)*3 -> 0 | E49: =B49+C49-D49 -> 21449563 | F49: =E49/E37 -> 1193.2334
A50: Chi phí khấu hao thay tấm pin sửa chửa hệ thống | C50: 2872328 | E50: =B50+C50-D50 -> 2872328 | F50: =E50/E37 -> 159.78683
A51: Chi phí khấu hao sửa chửa hệ thống ĐMT | C51: =825978+(B51/12) -> 825978 | E51: =B51+C51-D51 -> 825978 | F51: =E51/E37 -> 45.948932
...

Sheet T12
A1: ='THONG TIN'!C3 -> Công ty TNHH Thuận An | E1: Mẫu số : S 25 - SKT/DNN
A2: ='THONG TIN'!C4 -> Ấp Chồng Nô 3, Xã Hòa Tân, Huyện Cầu Kè, Tỉnh Trà Vinh | E2: Ban hành theo quyết định số
E3: 133/2016/TT-BTC ngày 14/06/2016
E4: của bộ tài chính
A5: THẺ TÍNH GIÁ THÀNH SẢN PHẨM
A6: Tháng 12/2023
B7: ĐỊA ĐIỂM : | C7: HÒA TÂN
B8: Tên sản phẩm , dịch vụ : Điện năng lượng mặt trời
B9: Số lượng sản phẩm , dịch vụ hoàn thành trong kỳ : | E9: 7872
B10: Phương pháp tính giá thành : Giá thành thực tế
A12: Khoản mục chi phí sản xuất kinh doanh | B12: Chi phí SXKD dở dang đầu kỳ | C12: Chi phí SXKD phát sinh trong kỳ | D12: Chi phí SXKD dở dang cuối kỳ | E12: Giá thành sản phẩm dịch vụ trong kỳ
E13: Giá thành | F13: Giá thành đơn vị
A14: 1. Vật liệu
A16: 2. Nhân công | C16: =1400000 -> 1400000 | E16: =C16 -> 1400000 | F16: =E16/E9 -> 177.84553
A18: 3. Máy
A20: 4. Chi phí chung
A21: Chi phí khấu hao hệ thống pin năng lượng mặt trời | C21: =12823592+(B21/12) -> 12823592 | D21: =B21-(B21/12)*3 -> 0 | E21: =B21+C21-D21 -> 12823592 | F21: =E21/E9 -> 1629.0132
A22: Chi phí khấu hao thay tấm pin sửa chửa hệ thống | C22: 897603 | D22: =B22-(B22/12)*3 -> 0 | E22: =B22+C22-D22 -> 897603 | F22: =E22/E9 -> 114.02477
A24: Cộng | B24: =B21+B23 -> 0 | C24: =C16+C21+C22 -> 15121195 | D24: =D16+D21+D22 -> 0 | E24: =E16+E21+E22 -> 15121195 | F24: =F16+F21+F22 -> 1920.8835
A26: Người ghi sổ | C26: Kế toán trưởng | E26: Giám đốc
A27: (Ký , họ tên) | C27: (Ký , họ tên) | E27: (Ký , họ tên,đóng dấu)
A29: =A1 -> Công ty TNHH Thuận An | E29: Mẫu số : S 25 - SKT/DNN
A30: =A2 -> Ấp Chồng Nô 3, Xã Hòa Tân, Huyện Cầu Kè, Tỉnh Trà Vinh | E30: Ban hành theo quyết định số
E31: 133/2016/TT-BTC ngày 14/06/2016
E32: của bộ tài chính
A33: THẺ TÍNH GIÁ THÀNH SẢN PHẨM
A34: Tháng 12 /2023
B35: ĐỊA ĐIỂM : | C35: HÒA ÂN
B36: Tên sản phẩm , dịch vụ : Điện năng lượng mặt trời
B37: Số lượng sản phẩm , dịch vụ hoàn thành trong kỳ : | E37: 17750
B38: Phương pháp tính giá thành : Giá thành thực tế
A40: Khoản mục chi phí sản xuất kinh doanh | B40: Chi phí SXKD dở dang đầu kỳ | C40: Chi phí SXKD phát sinh trong kỳ | D40: Chi phí SXKD dở dang cuối kỳ | E40: Giá thành sản phẩm dịch vụ trong kỳ
E41: Giá thành | F41: Giá thành đơn vị
A42: 1. Vật liệu
A44: 2. Nhân công | C44: 2800000 | E44: =C44 -> 2800000 | F44: =E44/E37 -> 157.74648
A46: 3. Máy
A48: 4. Chi phí chung
A49: Chi phí khấu hao hệ thống pin năng lượng mặt trời | C49: 21449563 | D49: =B49-(B49/12)*3 -> 0 | E49: =B49+C49-D49 -> 21449563 | F49: =E49/E37 -> 1208.4261
A50: Chi phí khấu hao thay tấm pin sửa chửa hệ thống | C50: 2872328 | E50: =B50+C50-D50 -> 2872328 | F50: =E50/E37 -> 161.8213
A51: Chi phí khấu hao sửa chửa hệ thống ĐMT | C51: =825978+(B51/12) -> 825978 | E51: =B51+C51-D51 -> 825978 | F51: =E51/E37 -> 46.533972
...
