Workbook

Sheet THONG TIN
A3: Tên doanh nghiệp: | C3: Công ty TNHH Thuận An
A4: Trụ sở chính : | C4: Ấp Chồng Nô 3, Xã Hòa Tân, Huyện Cầu Kè, Tỉnh Trà Vinh
A5: Mã số thuế : | C5: 2 1 0 0 4 0 6 8 1 8

Sheet SL 2025
A1: Tên doanh nghiệp: | C1: ='THONG TIN'!C3 -> Công ty TNHH Thuận An
A2: Trụ sở chính: | C2: ='THONG TIN'!C4 -> Ấp Chồng Nô 3, Xã Hòa Tân, Huyện Cầu Kè, Tỉnh Trà Vinh
A3: BẢNG BÁO CÁO SẢN LƯỢNG SẢN XUẤT VÀ TIÊU THỤ ĐIỆN SOLAR
A4: HÒA TÂN
B5: Công suất dự án : | D5: 62,3 Kw | E5: Năm | F5: 2025
A7: Thời gian | C7: Sản lượng phát | D7: Sản lượng bán | E7: Sản lượng phát bỏ | F7: Sản lượng tiêu dùng | I7: Giá thành
A8: Sản lượng còn lại 12/2024 | C8: 0 | D8: 6430 | G8: Hóa đơn 3
A9: Tháng 1 | C9: =D9+E9+F9 -> 7429 | D9: 7067 | F9: 362 | G9: Hóa đơn số 5 | I9: ='T1'!F25 -> 1846.9774
A10: Tháng 2 | C10: =D10+E10+F10 -> 8242 | D10: 8032 | F10: 210 | G10: Hóa đơn số 7 | I10: ='T2'!F25 -> 1664.7895
A11: Tháng 3 | C11: =D11+E11+F11 -> 9208 | D11: 9190 | F11: 18 | G11: Hóa đơn số 11 | I11: ='T3'!F25 -> 1490.1385
A12: Quý I | C12: =SUM(C8:C11) -> 24879 | D12: =SUM(D9:D11) -> 24289 | E12: =SUM(E9:E11) -> 0 | F12: =SUM(F9:F11) -> 590
A13: Tháng 4 | C13: =D13+E13+F13 -> 8814 | D13: 8442 | F13: 372 | G13: Hóa đơn Số 13 | I13: ='T4'!F25 -> 1556.7501
A14: Tháng 5 | C14: =D14+E14+F14 -> 7451 | D14: 7450 | F14: 1 | G14: Hóa đơn Số 16 | I14: ='T5'!F25 -> 1841.524
A15: Tháng 6 | C15: =D15+E15+F15 -> 6557 | D15: 6373 | F15: 184 | G15: Hóa đơn Số 19 | I15: ='T6'!F25 -> 2092.6026
A16: Quý II | C16: =SUM(C13:C15) -> 22822 | D16: =SUM(D13:D15) -> 22265 | E16: =SUM(E13:E15) -> 0 | F16: =SUM(F13:F15) -> 557
A17: Tháng 7 | C17: =D17+E17+F17 -> 7222 | D17: 7207 | F17: 15 | G17: Hóa đơn Số 22 | I17: ='T7'!F25 -> 1899.9162
A18: Tháng 8 | C18: =D18+E18+F18 -> 7839 | D18: 7678 | F18: 161 | G18: Hóa đơn Số 24 | I18: ='T8'!F25 -> 1750.3757
A19: Tháng 9 | C19: =D19+E19+F19 -> 6549 | D19: 6450 | F19: 99 | G19: Hóa đơn Số 27 | I19: ='T9'!F25 -> 2095.1588
A20: Quý III | C20: =SUM(C17:C19) -> 21610 | D20: =SUM(D17:D19) -> 21335 | E20: =SUM(E17:E19) -> 0 | F20: =SUM(F17:F19) -> 275
A21: Tháng 10 | C21: =D21+E21+F21 -> 6914 | D21: 6732 | F21: 182 | G21: Hóa đơn Số 29 | I21: ='T10'!F25 -> 1984.5524
A22: Tháng 11 | C22: =D22+E22+F22 -> 6702 | D22: 6630 | F22: 72 | G22: Hóa đơn Số 31 | I22: ='T11'!F25 -> 2047.3284
A23: Tháng 12 | C23: =D23+E23+F23 -> 7222 | D23: 7188 | F23: 34 | G23: Hóa đơn Số 01/2026 | I23: ='T12'!F25 -> 1936.0482
I24: =SUM(I9:I23) -> 22206.162
A25: Quý IV | C25: =SUM(C21:C24) -> 20838 | D25: =SUM(D21:D24) -> 20550 | E25: =SUM(E21:E24) -> 0 | F25: =SUM(F21:F24) -> 288 | I25: =I24/12 -> 1850.5135
C26: =C12+C16+C20+C25 -> 90149 | D26: =D12+D16+D20+D25 -> 88439 | E26: =SUM(E12+E16+E20+E25) -> 0 | F26: =SUM(F12+F16+F20+F25) -> 1710 | G26: =E26+F26 -> 1710
H27: =D23+E26+F26 -> 8898
A28: Hướng dẫn | C28: Sản lượng phát ghi số liệu từ phần mềm quản lý Solar
C29: Sản lượng bán ghi số liệu từ cơ quan điện lực chốt sổ + SL nội suy đến cuối cuối tháng
C30: Sản lượng phát bỏ ghi nhận điện lực không mua và những ngày cúp điện
C31: Sản lượng tiêu dùng là chênh lệch còn lại
A35: Tên doanh nghiệp: | C35: ='THONG TIN'!C3 -> Công ty TNHH Thuận An
A36: Trụ sở chính: | C36: ='THONG TIN'!C4 -> Ấp Chồng Nô 3, Xã Hòa Tân, Huyện Cầu Kè, Tỉnh Trà Vinh
A37: BẢNG BÁO CÁO SẢN LƯỢNG SẢN XUẤT VÀ TIÊU THỤ ĐIỆN SOLAR
A38: HÒA ÂN
B39: Công suất dự án : | D39: 142,4 Kw | E39: Năm | F39: 2025
A41: Thời gian | C41: Sản lượng phát | D41: Sản lượng bán | E41: Sản lượng phát bỏ | F41: Sản lượng tiêu dùng | I41: Giá thành
A42: Sản lượng còn lại 12/2024 | C42: 0 | D42: 12107 | G42: Hóa đơn Số 02
A43: Tháng 1 | C43: =D43+E43+F43 -> 15752 | D43: 13737 | E43: 1200 | F43: 815 | G43: Hóa đơn Số 06 | I43: ='T1'!F55 -> 1544.051
A44: Tháng 2 | C44: =D44+E44+F44 -> 18008 | D44: 15400 | E44: 1100 | F44: 1508 | G44: Hóa đơn Số 8 | I44: ='T2'!F55 -> 1381.7642
A45: Tháng 3 | C45: =D45+E45+F45 -> 19059 | D45: 18886 | E45: 0 | F45: 173 | G45: Hóa đơn Số 10 | I45: ='T3'!F54 -> 1305.5674
...

Sheet T1
A1: ='THONG TIN'!C3 -> Công ty TNHH Thuận An | E1: Mẫu số : S 25 - SKT/DNN
A2: ='THONG TIN'!C4 -> Ấp Chồng Nô 3, Xã Hòa Tân, Huyện Cầu Kè, Tỉnh Trà Vinh | E2: Ban hành theo quyết định số
E3: 133/2016/TT-BTC ngày 14/06/2016
E4: của bộ tài chính
A5: THẺ TÍNH GIÁ THÀNH SẢN PHẨM
A6: Tháng 1/2025
B7: ĐỊA ĐIỂM : | C7: HÒA TÂN
B8: Tên sản phẩm , dịch vụ : Điện năng lượng mặt trời
B9: Số lượng sản phẩm , dịch vụ hoàn thành trong kỳ : | E9: ='SL 2025'!C9 -> 7429
B10: Phương pháp tính giá thành : Giá thành thực tế
A12: Khoản mục chi phí sản xuất kinh doanh | B12: Chi phí SXKD dở dang đầu kỳ | C12: Chi phí SXKD phát sinh trong kỳ | D12: Chi phí SXKD dở dang cuối kỳ | E12: Giá thành sản phẩm dịch vụ trong kỳ
E13: Giá thành | F13: Giá thành đơn vị
A14: 1. Vật liệu
A16: 2. Nhân công | C16: 0 | E16: =C16 -> 0 | F16: =E16/E9 -> 0
A18: 3. Máy
A20: 4. Chi phí chung
A21: Chi phí khấu hao hệ thống pin năng lượng mặt trời | C21: =12823592+(B21/12) -> 12823592 | D21: =B21-(B21/12) -> 0 | E21: =B21+C21-D21 -> 12823592 | F21: =E21/E9 -> 1726.1532
A22: Chi phí khấu hao thay tấm pin sửa chửa hệ thống (2023) | C22: 897603 | D22: =B22-(B22/12) -> 0 | E22: =B22+C22-D22 -> 897603 | F22: =E22/E9 -> 120.8242
A23: Chi phí khấu hao thay tấm pin sửa chửa hệ thống (2024) | C23: 0 | E23: =B23+C23-D23 -> 0 | F23: =E23/E9 -> 0
A25: Cộng | B25: =B21+B24 -> 0 | C25: =C16+C21+C22+C23 -> 13721195 | D25: =D16+D21+D22+D23 -> 0 | E25: =E16+E21+E22+E23 -> 13721195 | F25: =F16+F21+F22+F23 -> 1846.9774
A27: Người ghi sổ | C27: Kế toán trưởng | E27: Giám đốc
A28: (Ký , họ tên) | C28: (Ký , họ tên) | E28: (Ký , họ tên,đóng dấu)
A30: =A1 -> Công ty TNHH Thuận An | E30: Mẫu số : S 25 - SKT/DNN
A31: =A2 -> Ấp Chồng Nô 3, Xã Hòa Tân, Huyện Cầu Kè, Tỉnh Trà Vinh | E31: Ban hành theo quyết định số
E32: 133/2016/TT-BTC ngày 14/06/2016
E33: của bộ tài chính
A34: THẺ TÍNH GIÁ THÀNH SẢN PHẨM
A35: Tháng 1/2025
B36: ĐỊA ĐIỂM : | C36: HÒA ÂN
B37: Tên sản phẩm , dịch vụ : Điện năng lượng mặt trời
B38: Số lượng sản phẩm , dịch vụ hoàn thành trong kỳ : | E38: ='SL 2025'!C43 -> 15752
B39: Phương pháp tính giá thành : Giá thành thực tế
A41: Khoản mục chi phí sản xuất kinh doanh | B41: Chi phí SXKD dở dang đầu kỳ | C41: Chi phí SXKD phát sinh trong kỳ | D41: Chi phí SXKD dở dang cuối kỳ | E41: Giá thành sản phẩm dịch vụ trong kỳ
E42: Giá thành | F42: Giá thành đơn vị
A43: 1. Vật liệu
A45: 2. Nhân công | C45: 0 | E45: =C45 -> 0 | F45: =E45/E38 -> 0
A47: 3. Máy
A49: 4. Chi phí chung
A50: Chi phí khấu hao hệ thống pin năng lượng mặt trời | C50: 21449563 | D50: =B50-(B50/12)*3 -> 0 | E50: =B50+C50-D50 -> 21449563 | F50: =E50/E38 -> 1361.7041
A51: Chi phí khấu hao thay tấm pin sửa chửa hệ thống (2023) | C51: 2872328 | E51: =B51+C51-D51 -> 2872328 | F51: =E51/E38 -> 182.34688
...

Sheet T2
A1: ='THONG TIN'!C3 -> Công ty TNHH Thuận An | E1: Mẫu số : S 25 - SKT/DNN
A2: ='THONG TIN'!C4 -> Ấp Chồng Nô 3, Xã Hòa Tân, Huyện Cầu Kè, Tỉnh Trà Vinh | E2: Ban hành theo quyết định số
E3: 133/2016/TT-BTC ngày 14/06/2016
E4: của bộ tài chính
A5: THẺ TÍNH GIÁ THÀNH SẢN PHẨM
A6: Tháng 2/2025
B7: ĐỊA ĐIỂM : | C7: HÒA TÂN
B8: Tên sản phẩm , dịch vụ : Điện năng lượng mặt trời
B9: Số lượng sản phẩm , dịch vụ hoàn thành trong kỳ : | E9: ='SL 2025'!C10 -> 8242
B10: Phương pháp tính giá thành : Giá thành thực tế
A12: Khoản mục chi phí sản xuất kinh doanh | B12: Chi phí SXKD dở dang đầu kỳ | C12: Chi phí SXKD phát sinh trong kỳ | D12: Chi phí SXKD dở dang cuối kỳ | E12: Giá thành sản phẩm dịch vụ trong kỳ
E13: Giá thành | F13: Giá thành đơn vị
A14: 1. Vật liệu
A16: 2. Nhân công | C16: 0 | E16: =C16 -> 0 | F16: =E16/E9 -> 0
A18: 3. Máy
A20: 4. Chi phí chung
A21: Chi phí khấu hao hệ thống pin năng lượng mặt trời | C21: =12823592+(B21/12) -> 12823592 | D21: =B21-(B21/12)*3 -> 0 | E21: =B21+C21-D21 -> 12823592 | F21: =E21/E9 -> 1555.8835
A22: Chi phí khấu hao thay tấm pin sửa chửa hệ thống (2023) | C22: 897603 | D22: =B22-(B22/12)*3 -> 0 | E22: =B22+C22-D22 -> 897603 | F22: =E22/E9 -> 108.90597
A23: Chi phí khấu hao thay tấm pin sửa chửa hệ thống (2024) | C23: 0 | E23: =B23+C23-D23 -> 0 | F23: =E23/E9 -> 0
A25: Cộng | B25: =B21+B24 -> 0 | C25: =C16+C21+C22+C23 -> 13721195 | D25: =D16+D21+D22+D23 -> 0 | E25: =E16+E21+E22+E23 -> 13721195 | F25: =F16+F21+F22+F23 -> 1664.7895
A27: Người ghi sổ | C27: Kế toán trưởng | E27: Giám đốc
A28: (Ký , họ tên) | C28: (Ký , họ tên) | E28: (Ký , họ tên,đóng dấu)
A30: =A1 -> Công ty TNHH Thuận An | E30: Mẫu số : S 25 - SKT/DNN
A31: =A2 -> Ấp Chồng Nô 3, Xã Hòa Tân, Huyện Cầu Kè, Tỉnh Trà Vinh | E31: Ban hành theo quyết định số
E32: 133/2016/TT-BTC ngày 14/06/2016
E33: của bộ tài chính
A34: THẺ TÍNH GIÁ THÀNH SẢN PHẨM
A35: Tháng 2/2025
B36: ĐỊA ĐIỂM : | C36: HÒA ÂN
B37: Tên sản phẩm , dịch vụ : Điện năng lượng mặt trời
B38: Số lượng sản phẩm , dịch vụ hoàn thành trong kỳ : | E38: ='SL 2025'!C44 -> 18008
B39: Phương pháp tính giá thành : Giá thành thực tế
A41: Khoản mục chi phí sản xuất kinh doanh | B41: Chi phí SXKD dở dang đầu kỳ | C41: Chi phí SXKD phát sinh trong kỳ | D41: Chi phí SXKD dở dang cuối kỳ | E41: Giá thành sản phẩm dịch vụ trong kỳ
E42: Giá thành | F42: Giá thành đơn vị
A43: 1. Vật liệu
A45: 2. Nhân công | C45: 0 | E45: =C45 -> 0 | F45: =E45/E38 -> 0
A47: 3. Máy
A49: 4. Chi phí chung
A50: Chi phí khấu hao hệ thống pin năng lượng mặt trời | C50: 21449563 | D50: =B50-(B50/12)*3 -> 0 | E50: =B50+C50-D50 -> 21449563 | F50: =E50/E38 -> 1191.113
A51: Chi phí khấu hao thay tấm pin sửa chửa hệ thống (2023) | C51: 2872328 | E51: =B51+C51-D51 -> 2872328 | F51: =E51/E38 -> 159.50289
...

Sheet T3
A1: ='THONG TIN'!C3 -> Công ty TNHH Thuận An | E1: Mẫu số : S 25 - SKT/DNN
A2: ='THONG TIN'!C4 -> Ấp Chồng Nô 3, Xã Hòa Tân, Huyện Cầu Kè, Tỉnh Trà Vinh | E2: Ban hành theo quyết định số
E3: 133/2016/TT-BTC ngày 14/06/2016
E4: của bộ tài chính
A5: THẺ TÍNH GIÁ THÀNH SẢN PHẨM
A6: Tháng 3/2025
B7: ĐỊA ĐIỂM : | C7: HÒA TÂN
B8: Tên sản phẩm , dịch vụ : Điện năng lượng mặt trời
B9: Số lượng sản phẩm , dịch vụ hoàn thành trong kỳ : | E9: ='SL 2025'!C11 -> 9208
B10: Phương pháp tính giá thành : Giá thành thực tế
A12: Khoản mục chi phí sản xuất kinh doanh | B12: Chi phí SXKD dở dang đầu kỳ | C12: Chi phí SXKD phát sinh trong kỳ | D12: Chi phí SXKD dở dang cuối kỳ | E12: Giá thành sản phẩm dịch vụ trong kỳ
E13: Giá thành | F13: Giá thành đơn vị
A14: 1. Vật liệu
A16: 2. Nhân công | C16: 0 | E16: =C16 -> 0 | F16: =E16/E9 -> 0
A18: 3. Máy
A20: 4. Chi phí chung
A21: Chi phí khấu hao hệ thống pin năng lượng mặt trời | C21: =12823592+(B21/12) -> 12823592 | D21: =B21-(B21/12)*3 -> 0 | E21: =B21+C21-D21 -> 12823592 | F21: =E21/E9 -> 1392.6577
A22: Chi phí khấu hao thay tấm pin sửa chửa hệ thống (2023) | C22: 897603 | D22: =B22-(B22/12)*3 -> 0 | E22: =B22+C22-D22 -> 897603 | F22: =E22/E9 -> 97.480778
A23: Chi phí khấu hao thay tấm pin sửa chửa hệ thống (2024) | C23: 0 | E23: =B23+C23-D23 -> 0 | F23: =E23/E9 -> 0
A25: Cộng | B25: =B21+B24 -> 0 | C25: =C16+C21+C22+C23 -> 13721195 | D25: =D16+D21+D22+D23 -> 0 | E25: =E16+E21+E22+E23 -> 13721195 | F25: =F16+F21+F22+F23 -> 1490.1385
A27: Người ghi sổ | C27: Kế toán trưởng | E27: Giám đốc
A28: (Ký , họ tên) | C28: (Ký , họ tên) | E28: (Ký , họ tên,đóng dấu)
A30: =A1 -> Công ty TNHH Thuận An | E30: Mẫu số : S 25 - SKT/DNN
A31: =A2 -> Ấp Chồng Nô 3, Xã Hòa Tân, Huyện Cầu Kè, Tỉnh Trà Vinh | E31: Ban hành theo quyết định số
E32: 133/2016/TT-BTC ngày 14/06/2016
E33: của bộ tài chính
A34: THẺ TÍNH GIÁ THÀNH SẢN PHẨM
A35: Tháng 3/2025
B36: ĐỊA ĐIỂM : | C36: HÒA ÂN
B37: Tên sản phẩm , dịch vụ : Điện năng lượng mặt trời
B38: Số lượng sản phẩm , dịch vụ hoàn thành trong kỳ : | E38: ='SL 2025'!C45 -> 19059
B39: Phương pháp tính giá thành : Giá thành thực tế
A41: Khoản mục chi phí sản xuất kinh doanh | B41: Chi phí SXKD dở dang đầu kỳ | C41: Chi phí SXKD phát sinh trong kỳ | D41: Chi phí SXKD dở dang cuối kỳ | E41: Giá thành sản phẩm dịch vụ trong kỳ
E42: Giá thành | F42: Giá thành đơn vị
A43: 1. Vật liệu
A45: 2. Nhân công | C45: 0 | E45: =C45 -> 0 | F45: =E45/E38 -> 0
A47: 3. Máy
A49: 4. Chi phí chung
A50: Chi phí khấu hao hệ thống pin năng lượng mặt trời | C50: 21449563 | D50: =B50-(B50/12)*3 -> 0 | E50: =B50+C50-D50 -> 21449563 | F50: =E50/E38 -> 1125.4296
A51: Chi phí khấu hao thay tấm pin sửa chửa hệ thống (2023) | C51: 2872328 | E51: =B51+C51-D51 -> 2872328 | F51: =E51/E38 -> 150.70717
...

Sheet T4
A1: ='THONG TIN'!C3 -> Công ty TNHH Thuận An | E1: Mẫu số : S 25 - SKT/DNN
A2: ='THONG TIN'!C4 -> Ấp Chồng Nô 3, Xã Hòa Tân, Huyện Cầu Kè, Tỉnh Trà Vinh | E2: Ban hành theo quyết định số
E3: 133/2016/TT-BTC ngày 14/06/2016
E4: của bộ tài chính
A5: THẺ TÍNH GIÁ THÀNH SẢN PHẨM
A6: Tháng 4/2025
B7: ĐỊA ĐIỂM : | C7: HÒA TÂN
B8: Tên sản phẩm , dịch vụ : Điện năng lượng mặt trời
B9: Số lượng sản phẩm , dịch vụ hoàn thành trong kỳ : | E9: ='SL 2025'!C13 -> 8814
B10: Phương pháp tính giá thành : Giá thành thực tế
A12: Khoản mục chi phí sản xuất kinh doanh | B12: Chi phí SXKD dở dang đầu kỳ | C12: Chi phí SXKD phát sinh trong kỳ | D12: Chi phí SXKD dở dang cuối kỳ | E12: Giá thành sản phẩm dịch vụ trong kỳ
E13: Giá thành | F13: Giá thành đơn vị
A14: 1. Vật liệu
A16: 2. Nhân công | C16: 0 | E16: =C16 -> 0 | F16: =E16/E9 -> 0
A18: 3. Máy
A20: 4. Chi phí chung
A21: Chi phí khấu hao hệ thống pin năng lượng mặt trời | C21: =12823592+(B21/12) -> 12823592 | D21: =B21-(B21/12)*3 -> 0 | E21: =B21+C21-D21 -> 12823592 | F21: =E21/E9 -> 1454.9117
A22: Chi phí khấu hao thay tấm pin sửa chửa hệ thống (2023) | C22: 897603 | D22: =B22-(B22/12)*3 -> 0 | E22: =B22+C22-D22 -> 897603 | F22: =E22/E9 -> 101.83833
A23: Chi phí khấu hao thay tấm pin sửa chửa hệ thống (2024) | C23: 0 | E23: =B23+C23-D23 -> 0 | F23: =E23/E9 -> 0
A25: Cộng | B25: =B21+B24 -> 0 | C25: =C16+C21+C22+C23 -> 13721195 | D25: =D16+D21+D22+D23 -> 0 | E25: =E16+E21+E22+E23 -> 13721195 | F25: =F16+F21+F22+F23 -> 1556.7501
A27: Người ghi sổ | C27: Kế toán trưởng | E27: Giám đốc
A28: (Ký , họ tên) | C28: (Ký , họ tên) | E28: (Ký , họ tên,đóng dấu)
A30: =A1 -> Công ty TNHH Thuận An | E30: Mẫu số : S 25 - SKT/DNN
A31: =A2 -> Ấp Chồng Nô 3, Xã Hòa Tân, Huyện Cầu Kè, Tỉnh Trà Vinh | E31: Ban hành theo quyết định số
E32: 133/2016/TT-BTC ngày 14/06/2016
E33: của bộ tài chính
A34: THẺ TÍNH GIÁ THÀNH SẢN PHẨM
A35: Tháng 4/2025
B36: ĐỊA ĐIỂM : | C36: HÒA ÂN
B37: Tên sản phẩm , dịch vụ : Điện năng lượng mặt trời
B38: Số lượng sản phẩm , dịch vụ hoàn thành trong kỳ : | E38: ='SL 2025'!C47 -> 18181
B39: Phương pháp tính giá thành : Giá thành thực tế
A41: Khoản mục chi phí sản xuất kinh doanh | B41: Chi phí SXKD dở dang đầu kỳ | C41: Chi phí SXKD phát sinh trong kỳ | D41: Chi phí SXKD dở dang cuối kỳ | E41: Giá thành sản phẩm dịch vụ trong kỳ
E42: Giá thành | F42: Giá thành đơn vị
A43: 1. Vật liệu
A45: 2. Nhân công | C45: 0 | E45: =C45 -> 0 | F45: =E45/E38 -> 0
A47: 3. Máy
A49: 4. Chi phí chung
A50: Chi phí khấu hao hệ thống pin năng lượng mặt trời | C50: 21449563 | D50: =B50-(B50/12)*3 -> 0 | E50: =B50+C50-D50 -> 21449563 | F50: =E50/E38 -> 1179.7791
A51: Chi phí khấu hao thay tấm pin sửa chửa hệ thống | C51: 2872328 | E51: =B51+C51-D51 -> 2872328 | F51: =E51/E38 -> 157.98515
...

Sheet T5
A1: ='THONG TIN'!C3 -> Công ty TNHH Thuận An | E1: Mẫu số : S 25 - SKT/DNN
A2: ='THONG TIN'!C4 -> Ấp Chồng Nô 3, Xã Hòa Tân, Huyện Cầu Kè, Tỉnh Trà Vinh | E2: Ban hành theo quyết định số
E3: 133/2016/TT-BTC ngày 14/06/2016
E4: của bộ tài chính
A5: THẺ TÍNH GIÁ THÀNH SẢN PHẨM
A6: Tháng 5/2025
B7: ĐỊA ĐIỂM : | C7: HÒA TÂN
B8: Tên sản phẩm , dịch vụ : Điện năng lượng mặt trời
B9: Số lượng sản phẩm , dịch vụ hoàn thành trong kỳ : | E9: ='SL 2025'!C14 -> 7451
B10: Phương pháp tính giá thành : Giá thành thực tế
A12: Khoản mục chi phí sản xuất kinh doanh | B12: Chi phí SXKD dở dang đầu kỳ | C12: Chi phí SXKD phát sinh trong kỳ | D12: Chi phí SXKD dở dang cuối kỳ | E12: Giá thành sản phẩm dịch vụ trong kỳ
E13: Giá thành | F13: Giá thành đơn vị
A14: 1. Vật liệu
A16: 2. Nhân công | C16: 0 | E16: =C16 -> 0 | F16: =E16/E9 -> 0
A18: 3. Máy
A20: 4. Chi phí chung
A21: Chi phí khấu hao hệ thống pin năng lượng mặt trời | C21: =12823592+(B21/12) -> 12823592 | D21: =B21-(B21/12)*3 -> 0 | E21: =B21+C21-D21 -> 12823592 | F21: =E21/E9 -> 1721.0565
A22: Chi phí khấu hao thay tấm pin sửa chửa hệ thống (2023) | C22: 897603 | D22: =B22-(B22/12)*3 -> 0 | E22: =B22+C22-D22 -> 897603 | F22: =E22/E9 -> 120.46745
A23: Chi phí khấu hao thay tấm pin sửa chửa hệ thống (2024) | C23: 0 | E23: =B23+C23-D23 -> 0 | F23: =E23/E9 -> 0
A25: Cộng | B25: =B21+B24 -> 0 | C25: =C16+C21+C22+C23 -> 13721195 | D25: =D16+D21+D22+D23 -> 0 | E25: =E16+E21+E22+E23 -> 13721195 | F25: =F16+F21+F22+F23 -> 1841.524
A27: Người ghi sổ | C27: Kế toán trưởng | E27: Giám đốc
A28: (Ký , họ tên) | C28: (Ký , họ tên) | E28: (Ký , họ tên,đóng dấu)
A30: =A1 -> Công ty TNHH Thuận An | E30: Mẫu số : S 25 - SKT/DNN
A31: =A2 -> Ấp Chồng Nô 3, Xã Hòa Tân, Huyện Cầu Kè, Tỉnh Trà Vinh | E31: Ban hành theo quyết định số
E32: 133/2016/TT-BTC ngày 14/06/2016
E33: của bộ tài chính
A34: THẺ TÍNH GIÁ THÀNH SẢN PHẨM
A35: Tháng 5 /2025
B36: ĐỊA ĐIỂM : | C36: HÒA ÂN
B37: Tên sản phẩm , dịch vụ : Điện năng lượng mặt trời
B38: Số lượng sản phẩm , dịch vụ hoàn thành trong kỳ : | E38: ='SL 2025'!C48 -> 14776
B39: Phương pháp tính giá thành : Giá thành thực tế
A41: Khoản mục chi phí sản xuất kinh doanh | B41: Chi phí SXKD dở dang đầu kỳ | C41: Chi phí SXKD phát sinh trong kỳ | D41: Chi phí SXKD dở dang cuối kỳ | E41: Giá thành sản phẩm dịch vụ trong kỳ
E42: Giá thành | F42: Giá thành đơn vị
A43: 1. Vật liệu
A45: 2. Nhân công | C45: 0 | E45: =C45 -> 0 | F45: =E45/E38 -> 0
A47: 3. Máy
A49: 4. Chi phí chung
A50: Chi phí khấu hao hệ thống pin năng lượng mặt trời | C50: 21449563 | D50: =B50-(B50/12)*3 -> 0 | E50: =B50+C50-D50 -> 21449563 | F50: =E50/E38 -> 1451.6488
A51: Chi phí khấu hao thay tấm pin sửa chửa hệ thống | C51: 2872328 | E51: =B51+C51-D51 -> 2872328 | F51: =E51/E38 -> 194.39145
...

Sheet T6
A1: ='THONG TIN'!C3 -> Công ty TNHH Thuận An | E1: Mẫu số : S 25 - SKT/DNN
A2: ='THONG TIN'!C4 -> Ấp Chồng Nô 3, Xã Hòa Tân, Huyện Cầu Kè, Tỉnh Trà Vinh | E2: Ban hành theo quyết định số
E3: 133/2016/TT-BTC ngày 14/06/2016
E4: của bộ tài chính
A5: THẺ TÍNH GIÁ THÀNH SẢN PHẨM
A6: Tháng 6/2025
B7: ĐỊA ĐIỂM : | C7: HÒA TÂN
B8: Tên sản phẩm , dịch vụ : Điện năng lượng mặt trời
B9: Số lượng sản phẩm , dịch vụ hoàn thành trong kỳ : | E9: ='SL 2025'!C15 -> 6557
B10: Phương pháp tính giá thành : Giá thành thực tế
A12: Khoản mục chi phí sản xuất kinh doanh | B12: Chi phí SXKD dở dang đầu kỳ | C12: Chi phí SXKD phát sinh trong kỳ | D12: Chi phí SXKD dở dang cuối kỳ | E12: Giá thành sản phẩm dịch vụ trong kỳ
E13: Giá thành | F13: Giá thành đơn vị
A14: 1. Vật liệu
A16: 2. Nhân công | C16: 0 | E16: =C16 -> 0 | F16: =E16/E9 -> 0
A18: 3. Máy
A20: 4. Chi phí chung
A21: Chi phí khấu hao hệ thống pin năng lượng mặt trời | C21: =12823592+(B21/12) -> 12823592 | D21: =B21-(B21/12)*3 -> 0 | E21: =B21+C21-D21 -> 12823592 | F21: =E21/E9 -> 1955.7102
A22: Chi phí khấu hao thay tấm pin sửa chửa hệ thống (2023) | C22: 897603 | D22: =B22-(B22/12)*3 -> 0 | E22: =B22+C22-D22 -> 897603 | F22: =E22/E9 -> 136.89233
A23: Chi phí khấu hao thay tấm pin sửa chửa hệ thống (2024) | C23: 0 | E23: =B23+C23-D23 -> 0 | F23: =E23/E9 -> 0
A25: Cộng | B25: =B21+B24 -> 0 | C25: =C16+C21+C22+C23 -> 13721195 | D25: =D16+D21+D22+D23 -> 0 | E25: =E16+E21+E22+E23 -> 13721195 | F25: =F16+F21+F22+F23 -> 2092.6026
A27: Người ghi sổ | C27: Kế toán trưởng | E27: Giám đốc
A28: (Ký , họ tên) | C28: (Ký , họ tên) | E28: (Ký , họ tên,đóng dấu)
A30: =A1 -> Công ty TNHH Thuận An | E30: Mẫu số : S 25 - SKT/DNN
A31: =A2 -> Ấp Chồng Nô 3, Xã Hòa Tân, Huyện Cầu Kè, Tỉnh Trà Vinh | E31: Ban hành theo quyết định số
E32: 133/2016/TT-BTC ngày 14/06/2016
E33: của bộ tài chính
A34: THẺ TÍNH GIÁ THÀNH SẢN PHẨM
A35: Tháng 6 /2025
B36: ĐỊA ĐIỂM : | C36: HÒA ÂN
B37: Tên sản phẩm , dịch vụ : Điện năng lượng mặt trời
B38: Số lượng sản phẩm , dịch vụ hoàn thành trong kỳ : | E38: ='SL 2025'!C49 -> 12977
B39: Phương pháp tính giá thành : Giá thành thực tế
A41: Khoản mục chi phí sản xuất kinh doanh | B41: Chi phí SXKD dở dang đầu kỳ | C41: Chi phí SXKD phát sinh trong kỳ | D41: Chi phí SXKD dở dang cuối kỳ | E41: Giá thành sản phẩm dịch vụ trong kỳ
E42: Giá thành | F42: Giá thành đơn vị
A43: 1. Vật liệu
A45: 2. Nhân công | C45: 0 | E45: =C45 -> 0 | F45: =E45/E38 -> 0
A47: 3. Máy
A49: 4. Chi phí chung
A50: Chi phí khấu hao hệ thống pin năng lượng mặt trời | C50: 21449563 | D50: =B50-(B50/12)*3 -> 0 | E50: =B50+C50-D50 -> 21449563 | F50: =E50/E38 -> 1652.8907
A51: Chi phí khấu hao thay tấm pin sửa chửa hệ thống | C51: 2872328 | E51: =B51+C51-D51 -> 2872328 | F51: =E51/E38 -> 221.33991
...

Sheet T7
A1: ='THONG TIN'!C3 -> Công ty TNHH Thuận An | E1: Mẫu số : S 25 - SKT/DNN
A2: ='THONG TIN'!C4 -> Ấp Chồng Nô 3, Xã Hòa Tân, Huyện Cầu Kè, Tỉnh Trà Vinh | E2: Ban hành theo quyết định số
E3: 133/2016/TT-BTC ngày 14/06/2016
E4: của bộ tài chính
A5: THẺ TÍNH GIÁ THÀNH SẢN PHẨM
A6: Tháng 7/2025
B7: ĐỊA ĐIỂM : | C7: HÒA TÂN
B8: Tên sản phẩm , dịch vụ : Điện năng lượng mặt trời
B9: Số lượng sản phẩm , dịch vụ hoàn thành trong kỳ : | E9: ='SL 2025'!C17 -> 7222
B10: Phương pháp tính giá thành : Giá thành thực tế
A12: Khoản mục chi phí sản xuất kinh doanh | B12: Chi phí SXKD dở dang đầu kỳ | C12: Chi phí SXKD phát sinh trong kỳ | D12: Chi phí SXKD dở dang cuối kỳ | E12: Giá thành sản phẩm dịch vụ trong kỳ
E13: Giá thành | F13: Giá thành đơn vị
A14: 1. Vật liệu
A16: 2. Nhân công | C16: 0 | E16: =C16 -> 0 | F16: =E16/E9 -> 0
A18: 3. Máy
A20: 4. Chi phí chung
A21: Chi phí khấu hao hệ thống pin năng lượng mặt trời | C21: =12823592+(B21/12) -> 12823592 | D21: =B21-(B21/12)*3 -> 0 | E21: =B21+C21-D21 -> 12823592 | F21: =E21/E9 -> 1775.6289
A22: Chi phí khấu hao thay tấm pin sửa chửa hệ thống (2023) | C22: 897603 | D22: =B22-(B22/12)*3 -> 0 | E22: =B22+C22-D22 -> 897603 | F22: =E22/E9 -> 124.28732
A23: Chi phí khấu hao thay tấm pin sửa chửa hệ thống (2024) | C23: 0 | E23: =B23+C23-D23 -> 0 | F23: =E23/E9 -> 0
A25: Cộng | B25: =B21+B24 -> 0 | C25: =C16+C21+C22+C23 -> 13721195 | D25: =D16+D21+D22+D23 -> 0 | E25: =E16+E21+E22+E23 -> 13721195 | F25: =F16+F21+F22+F23 -> 1899.9162
A27: Người ghi sổ | C27: Kế toán trưởng | E27: Giám đốc
A28: (Ký , họ tên) | C28: (Ký , họ tên) | E28: (Ký , họ tên,đóng dấu)
A30: =A1 -> Công ty TNHH Thuận An | E30: Mẫu số : S 25 - SKT/DNN
A31: =A2 -> Ấp Chồng Nô 3, Xã Hòa Tân, Huyện Cầu Kè, Tỉnh Trà Vinh | E31: Ban hành theo quyết định số
E32: 133/2016/TT-BTC ngày 14/06/2016
E33: của bộ tài chính
A34: THẺ TÍNH GIÁ THÀNH SẢN PHẨM
A35: Tháng 7 /2025
B36: ĐỊA ĐIỂM : | C36: HÒA ÂN
B37: Tên sản phẩm , dịch vụ : Điện năng lượng mặt trời
B38: Số lượng sản phẩm , dịch vụ hoàn thành trong kỳ : | E38: ='SL 2025'!C51 -> 14653
B39: Phương pháp tính giá thành : Giá thành thực tế
A41: Khoản mục chi phí sản xuất kinh doanh | B41: Chi phí SXKD dở dang đầu kỳ | C41: Chi phí SXKD phát sinh trong kỳ | D41: Chi phí SXKD dở dang cuối kỳ | E41: Giá thành sản phẩm dịch vụ trong kỳ
E42: Giá thành | F42: Giá thành đơn vị
A43: 1. Vật liệu
A45: 2. Nhân công | C45: 0 | E45: =C45 -> 0 | F45: =E45/E38 -> 0
A47: 3. Máy
A49: 4. Chi phí chung
A50: Chi phí khấu hao hệ thống pin năng lượng mặt trời | C50: 21449563 | D50: =B50-(B50/12)*3 -> 0 | E50: =B50+C50-D50 -> 21449563 | F50: =E50/E38 -> 1463.8342
A51: Chi phí khấu hao thay tấm pin sửa chửa hệ thống | C51: 2872328 | E51: =B51+C51-D51 -> 2872328 | F51: =E51/E38 -> 196.0232
...

Sheet T8
A1: ='THONG TIN'!C3 -> Công ty TNHH Thuận An | E1: Mẫu số : S 25 - SKT/DNN
A2: ='THONG TIN'!C4 -> Ấp Chồng Nô 3, Xã Hòa Tân, Huyện Cầu Kè, Tỉnh Trà Vinh | E2: Ban hành theo quyết định số
E3: 133/2016/TT-BTC ngày 14/06/2016
E4: của bộ tài chính
A5: THẺ TÍNH GIÁ THÀNH SẢN PHẨM
A6: Tháng 8/2025
B7: ĐỊA ĐIỂM : | C7: HÒA TÂN
B8: Tên sản phẩm , dịch vụ : Điện năng lượng mặt trời
B9: Số lượng sản phẩm , dịch vụ hoàn thành trong kỳ : | E9: ='SL 2025'!C18 -> 7839
B10: Phương pháp tính giá thành : Giá thành thực tế
A12: Khoản mục chi phí sản xuất kinh doanh | B12: Chi phí SXKD dở dang đầu kỳ | C12: Chi phí SXKD phát sinh trong kỳ | D12: Chi phí SXKD dở dang cuối kỳ | E12: Giá thành sản phẩm dịch vụ trong kỳ
E13: Giá thành | F13: Giá thành đơn vị
A14: 1. Vật liệu
A16: 2. Nhân công | C16: 0 | E16: =C16 -> 0 | F16: =E16/E9 -> 0
A18: 3. Máy
A20: 4. Chi phí chung
A21: Chi phí khấu hao hệ thống pin năng lượng mặt trời | C21: =12823592+(B21/12) -> 12823592 | D21: =B21-(B21/12)*3 -> 0 | E21: =B21+C21-D21 -> 12823592 | F21: =E21/E9 -> 1635.8709
A22: Chi phí khấu hao thay tấm pin sửa chửa hệ thống (2023) | C22: 897603 | D22: =B22-(B22/12)*3 -> 0 | E22: =B22+C22-D22 -> 897603 | F22: =E22/E9 -> 114.50478
A23: Chi phí khấu hao thay tấm pin sửa chửa hệ thống (2024) | C23: 0 | E23: =B23+C23-D23 -> 0 | F23: =E23/E9 -> 0
A25: Cộng | B25: =B21+B24 -> 0 | C25: =C16+C21+C22+C23 -> 13721195 | D25: =D16+D21+D22+D23 -> 0 | E25: =E16+E21+E22+E23 -> 13721195 | F25: =F16+F21+F22+F23 -> 1750.3757
A27: Người ghi sổ | C27: Kế toán trưởng | E27: Giám đốc
A28: (Ký , họ tên) | C28: (Ký , họ tên) | E28: (Ký , họ tên,đóng dấu)
A30: =A1 -> Công ty TNHH Thuận An | E30: Mẫu số : S 25 - SKT/DNN
A31: =A2 -> Ấp Chồng Nô 3, Xã Hòa Tân, Huyện Cầu Kè, Tỉnh Trà Vinh | E31: Ban hành theo quyết định số
E32: 133/2016/TT-BTC ngày 14/06/2016
E33: của bộ tài chính
A34: THẺ TÍNH GIÁ THÀNH SẢN PHẨM
A35: Tháng 8 /2025
B36: ĐỊA ĐIỂM : | C36: HÒA ÂN
B37: Tên sản phẩm , dịch vụ : Điện năng lượng mặt trời
B38: Số lượng sản phẩm , dịch vụ hoàn thành trong kỳ : | E38: ='SL 2025'!C52 -> 16187
B39: Phương pháp tính giá thành : Giá thành thực tế
A41: Khoản mục chi phí sản xuất kinh doanh | B41: Chi phí SXKD dở dang đầu kỳ | C41: Chi phí SXKD phát sinh trong kỳ | D41: Chi phí SXKD dở dang cuối kỳ | E41: Giá thành sản phẩm dịch vụ trong kỳ
E42: Giá thành | F42: Giá thành đơn vị
A43: 1. Vật liệu
A45: 2. Nhân công | C45: 0 | E45: =C45 -> 0 | F45: =E45/E38 -> 0
A47: 3. Máy
A49: 4. Chi phí chung
A50: Chi phí khấu hao hệ thống pin năng lượng mặt trời | C50: 21449563 | D50: =B50-(B50/12)*3 -> 0 | E50: =B50+C50-D50 -> 21449563 | F50: =E50/E38 -> 1325.1105
A51: Chi phí khấu hao thay tấm pin sửa chửa hệ thống | C51: 2872328 | E51: =B51+C51-D51 -> 2872328 | F51: =E51/E38 -> 177.44659
...

Sheet T9
A1: ='THONG TIN'!C3 -> Công ty TNHH Thuận An | E1: Mẫu số : S 25 - SKT/DNN
A2: ='THONG TIN'!C4 -> Ấp Chồng Nô 3, Xã Hòa Tân, Huyện Cầu Kè, Tỉnh Trà Vinh | E2: Ban hành theo quyết định số
E3: 133/2016/TT-BTC ngày 14/06/2016
E4: của bộ tài chính
A5: THẺ TÍNH GIÁ THÀNH SẢN PHẨM
A6: Tháng 9/2025
B7: ĐỊA ĐIỂM : | C7: HÒA TÂN
B8: Tên sản phẩm , dịch vụ : Điện năng lượng mặt trời
B9: Số lượng sản phẩm , dịch vụ hoàn thành trong kỳ : | E9: ='SL 2025'!C19 -> 6549
B10: Phương pháp tính giá thành : Giá thành thực tế
A12: Khoản mục chi phí sản xuất kinh doanh | B12: Chi phí SXKD dở dang đầu kỳ | C12: Chi phí SXKD phát sinh trong kỳ | D12: Chi phí SXKD dở dang cuối kỳ | E12: Giá thành sản phẩm dịch vụ trong kỳ
E13: Giá thành | F13: Giá thành đơn vị
A14: 1. Vật liệu
A16: 2. Nhân công | C16: 0 | E16: =C16 -> 0 | F16: =E16/E9 -> 0
A18: 3. Máy
A20: 4. Chi phí chung
A21: Chi phí khấu hao hệ thống pin năng lượng mặt trời | C21: =12823592+(B21/12) -> 12823592 | D21: =B21-(B21/12)*3 -> 0 | E21: =B21+C21-D21 -> 12823592 | F21: =E21/E9 -> 1958.0993
A22: Chi phí khấu hao thay tấm pin sửa chửa hệ thống (2023) | C22: 897603 | D22: =B22-(B22/12)*3 -> 0 | E22: =B22+C22-D22 -> 897603 | F22: =E22/E9 -> 137.05955
A23: Chi phí khấu hao thay tấm pin sửa chửa hệ thống (2024) | C23: 0 | E23: =B23+C23-D23 -> 0 | F23: =E23/E9 -> 0
A25: Cộng | B25: =B21+B24 -> 0 | C25: =C16+C21+C22+C23 -> 13721195 | D25: =D16+D21+D22+D23 -> 0 | E25: =E16+E21+E22+E23 -> 13721195 | F25: =F16+F21+F22+F23 -> 2095.1588
A27: Người ghi sổ | C27: Kế toán trưởng | E27: Giám đốc
A28: (Ký , họ tên) | C28: (Ký , họ tên) | E28: (Ký , họ tên,đóng dấu)
A30: =A1 -> Công ty TNHH Thuận An | E30: Mẫu số : S 25 - SKT/DNN
A31: =A2 -> Ấp Chồng Nô 3, Xã Hòa Tân, Huyện Cầu Kè, Tỉnh Trà Vinh | E31: Ban hành theo quyết định số
E32: 133/2016/TT-BTC ngày 14/06/2016
E33: của bộ tài chính
A34: THẺ TÍNH GIÁ THÀNH SẢN PHẨM
A35: Tháng 9 /2025
B36: ĐỊA ĐIỂM : | C36: HÒA ÂN
B37: Tên sản phẩm , dịch vụ : Điện năng lượng mặt trời
B38: Số lượng sản phẩm , dịch vụ hoàn thành trong kỳ : | E38: ='SL 2025'!C53 -> 14020
B39: Phương pháp tính giá thành : Giá thành thực tế
A41: Khoản mục chi phí sản xuất kinh doanh | B41: Chi phí SXKD dở dang đầu kỳ | C41: Chi phí SXKD phát sinh trong kỳ | D41: Chi phí SXKD dở dang cuối kỳ | E41: Giá thành sản phẩm dịch vụ trong kỳ
E42: Giá thành | F42: Giá thành đơn vị
A43: 1. Vật liệu
A45: 2. Nhân công | C45: 0 | E45: =C45 -> 0 | F45: =E45/E38 -> 0
A47: 3. Máy
A49: 4. Chi phí chung
A50: Chi phí khấu hao hệ thống pin năng lượng mặt trời | C50: 21449563 | D50: =B50-(B50/12)*3 -> 0 | E50: =B50+C50-D50 -> 21449563 | F50: =E50/E38 -> 1529.926
A51: Chi phí khấu hao thay tấm pin sửa chửa hệ thống | C51: 2872328 | E51: =B51+C51-D51 -> 2872328 | F51: =E51/E38 -> 204.87361
...

Sheet T10
A1: ='THONG TIN'!C3 -> Công ty TNHH Thuận An | E1: Mẫu số : S 25 - SKT/DNN
A2: ='THONG TIN'!C4 -> Ấp Chồng Nô 3, Xã Hòa Tân, Huyện Cầu Kè, Tỉnh Trà Vinh | E2: Ban hành theo quyết định số
E3: 133/2016/TT-BTC ngày 14/06/2016
E4: của bộ tài chính
A5: THẺ TÍNH GIÁ THÀNH SẢN PHẨM
A6: Tháng 10/2025
B7: ĐỊA ĐIỂM : | C7: HÒA TÂN
B8: Tên sản phẩm , dịch vụ : Điện năng lượng mặt trời
B9: Số lượng sản phẩm , dịch vụ hoàn thành trong kỳ : | E9: ='SL 2025'!C21 -> 6914
B10: Phương pháp tính giá thành : Giá thành thực tế
A12: Khoản mục chi phí sản xuất kinh doanh | B12: Chi phí SXKD dở dang đầu kỳ | C12: Chi phí SXKD phát sinh trong kỳ | D12: Chi phí SXKD dở dang cuối kỳ | E12: Giá thành sản phẩm dịch vụ trong kỳ
E13: Giá thành | F13: Giá thành đơn vị
A14: 1. Vật liệu
A16: 2. Nhân công | C16: 0 | E16: =C16 -> 0 | F16: =E16/E9 -> 0
A18: 3. Máy
A20: 4. Chi phí chung
A21: Chi phí khấu hao hệ thống pin năng lượng mặt trời | C21: =12823592+(B21/12) -> 12823592 | D21: =B21-(B21/12)*3 -> 0 | E21: =B21+C21-D21 -> 12823592 | F21: =E21/E9 -> 1854.7284
A22: Chi phí khấu hao thay tấm pin sửa chửa hệ thống (2023) | C22: 897603 | D22: =B22-(B22/12)*3 -> 0 | E22: =B22+C22-D22 -> 897603 | F22: =E22/E9 -> 129.82398
A23: Chi phí khấu hao thay tấm pin sửa chửa hệ thống (2024) | C23: 0 | E23: =B23+C23-D23 -> 0 | F23: =E23/E9 -> 0
A25: Cộng | B25: =B21+B24 -> 0 | C25: =C16+C21+C22+C23 -> 13721195 | D25: =D16+D21+D22+D23 -> 0 | E25: =E16+E21+E22+E23 -> 13721195 | F25: =F16+F21+F22+F23 -> 1984.5524
A27: Người ghi sổ | C27: Kế toán trưởng | E27: Giám đốc
A28: (Ký , họ tên) | C28: (Ký , họ tên) | E28: (Ký , họ tên,đóng dấu)
A30: =A1 -> Công ty TNHH Thuận An | E30: Mẫu số : S 25 - SKT/DNN
A31: =A2 -> Ấp Chồng Nô 3, Xã Hòa Tân, Huyện Cầu Kè, Tỉnh Trà Vinh | E31: Ban hành theo quyết định số
E32: 133/2016/TT-BTC ngày 14/06/2016
E33: của bộ tài chính
A34: THẺ TÍNH GIÁ THÀNH SẢN PHẨM
A35: Tháng 10 /2025
B36: ĐỊA ĐIỂM : | C36: HÒA ÂN
B37: Tên sản phẩm , dịch vụ : Điện năng lượng mặt trời
B38: Số lượng sản phẩm , dịch vụ hoàn thành trong kỳ : | E38: ='SL 2025'!C55 -> 14287
B39: Phương pháp tính giá thành : Giá thành thực tế
A41: Khoản mục chi phí sản xuất kinh doanh | B41: Chi phí SXKD dở dang đầu kỳ | C41: Chi phí SXKD phát sinh trong kỳ | D41: Chi phí SXKD dở dang cuối kỳ | E41: Giá thành sản phẩm dịch vụ trong kỳ
E42: Giá thành | F42: Giá thành đơn vị
A43: 1. Vật liệu
A45: 2. Nhân công | C45: 0 | E45: =C45 -> 0 | F45: =E45/E38 -> 0
A47: 3. Máy
A49: 4. Chi phí chung
A50: Chi phí khấu hao hệ thống pin năng lượng mặt trời | C50: 21449563 | D50: =B50-(B50/12)*3 -> 0 | E50: =B50+C50-D50 -> 21449563 | F50: =E50/E38 -> 1501.3343
A51: Chi phí khấu hao thay tấm pin sửa chửa hệ thống | C51: 2872328 | E51: =B51+C51-D51 -> 2872328 | F51: =E51/E38 -> 201.04487
...

Sheet T11
A1: ='THONG TIN'!C3 -> Công ty TNHH Thuận An | E1: Mẫu số : S 25 - SKT/DNN
A2: ='THONG TIN'!C4 -> Ấp Chồng Nô 3, Xã Hòa Tân, Huyện Cầu Kè, Tỉnh Trà Vinh | E2: Ban hành theo quyết định số
E3: 133/2016/TT-BTC ngày 14/06/2016
E4: của bộ tài chính
A5: THẺ TÍNH GIÁ THÀNH SẢN PHẨM
A6: Tháng 11/2025
B7: ĐỊA ĐIỂM : | C7: HÒA TÂN
B8: Tên sản phẩm , dịch vụ : Điện năng lượng mặt trời
B9: Số lượng sản phẩm , dịch vụ hoàn thành trong kỳ : | E9: ='SL 2025'!C22 -> 6702
B10: Phương pháp tính giá thành : Giá thành thực tế
A12: Khoản mục chi phí sản xuất kinh doanh | B12: Chi phí SXKD dở dang đầu kỳ | C12: Chi phí SXKD phát sinh trong kỳ | D12: Chi phí SXKD dở dang cuối kỳ | E12: Giá thành sản phẩm dịch vụ trong kỳ
E13: Giá thành | F13: Giá thành đơn vị
A14: 1. Vật liệu
A16: 2. Nhân công | C16: 0 | E16: =C16 -> 0 | F16: =E16/E9 -> 0
A18: 3. Máy
A20: 4. Chi phí chung
A21: Chi phí khấu hao hệ thống pin năng lượng mặt trời | C21: =12823592+(B21/12) -> 12823592 | D21: =B21-(B21/12)*3 -> 0 | E21: =B21+C21-D21 -> 12823592 | F21: =E21/E9 -> 1913.3978
A22: Chi phí khấu hao thay tấm pin sửa chửa hệ thống (2023) | C22: 897603 | D22: =B22-(B22/12)*3 -> 0 | E22: =B22+C22-D22 -> 897603 | F22: =E22/E9 -> 133.93062
A23: Chi phí khấu hao thay tấm pin sửa chửa hệ thống (2024) | C23: 0 | E23: =B23+C23-D23 -> 0 | F23: =E23/E9 -> 0
A25: Cộng | B25: =B21+B24 -> 0 | C25: =C16+C21+C22+C23 -> 13721195 | D25: =D16+D21+D22+D23 -> 0 | E25: =E16+E21+E22+E23 -> 13721195 | F25: =F16+F21+F22+F23 -> 2047.3284
A27: Người ghi sổ | C27: Kế toán trưởng | E27: Giám đốc
A28: (Ký , họ tên) | C28: (Ký , họ tên) | E28: (Ký , họ tên,đóng dấu)
A30: =A1 -> Công ty TNHH Thuận An | E30: Mẫu số : S 25 - SKT/DNN
A31: =A2 -> Ấp Chồng Nô 3, Xã Hòa Tân, Huyện Cầu Kè, Tỉnh Trà Vinh | E31: Ban hành theo quyết định số
E32: 133/2016/TT-BTC ngày 14/06/2016
E33: của bộ tài chính
A34: THẺ TÍNH GIÁ THÀNH SẢN PHẨM
A35: Tháng 11 /2025
B36: ĐỊA ĐIỂM : | C36: HÒA ÂN
B37: Tên sản phẩm , dịch vụ : Điện năng lượng mặt trời
B38: Số lượng sản phẩm , dịch vụ hoàn thành trong kỳ : | E38: ='SL 2025'!C56 -> 12938
B39: Phương pháp tính giá thành : Giá thành thực tế
A41: Khoản mục chi phí sản xuất kinh doanh | B41: Chi phí SXKD dở dang đầu kỳ | C41: Chi phí SXKD phát sinh trong kỳ | D41: Chi phí SXKD dở dang cuối kỳ | E41: Giá thành sản phẩm dịch vụ trong kỳ
E42: Giá thành | F42: Giá thành đơn vị
A43: 1. Vật liệu
A45: 2. Nhân công | C45: 0 | E45: =C45 -> 0 | F45: =E45/E38 -> 0
A47: 3. Máy
A49: 4. Chi phí chung
A50: Chi phí khấu hao hệ thống pin năng lượng mặt trời | C50: 21449563 | D50: =B50-(B50/12)*3 -> 0 | E50: =B50+C50-D50 -> 21449563 | F50: =E50/E38 -> 1657.8732
A51: Chi phí khấu hao thay tấm pin sửa chửa hệ thống | C51: 2872328 | E51: =B51+C51-D51 -> 2872328 | F51: =E51/E38 -> 222.00711
...

Sheet T12
A1: ='THONG TIN'!C3 -> Công ty TNHH Thuận An | E1: Mẫu số : S 25 - SKT/DNN
A2: ='THONG TIN'!C4 -> Ấp Chồng Nô 3, Xã Hòa Tân, Huyện Cầu Kè, Tỉnh Trà Vinh | E2: Ban hành theo quyết định số
E3: 133/2016/TT-BTC ngày 14/06/2016
E4: của bộ tài chính
A5: THẺ TÍNH GIÁ THÀNH SẢN PHẨM
A6: Tháng 12/2025
B7: ĐỊA ĐIỂM : | C7: HÒA TÂN
B8: Tên sản phẩm , dịch vụ : Điện năng lượng mặt trời
B9: Số lượng sản phẩm , dịch vụ hoàn thành trong kỳ : | E9: ='SL 2025'!C23 -> 7222
B10: Phương pháp tính giá thành : Giá thành thực tế
A12: Khoản mục chi phí sản xuất kinh doanh | B12: Chi phí SXKD dở dang đầu kỳ | C12: Chi phí SXKD phát sinh trong kỳ | D12: Chi phí SXKD dở dang cuối kỳ | E12: Giá thành sản phẩm dịch vụ trong kỳ
E13: Giá thành | F13: Giá thành đơn vị
A14: 1. Vật liệu
A16: 2. Nhân công | C16: 0 | E16: =C16 -> 0 | F16: =E16/E9 -> 0
A18: 3. Máy
A20: 4. Chi phí chung
A21: Chi phí khấu hao hệ thống pin năng lượng mặt trời | C21: =12823592+(B21/12) -> 12823592 | D21: =B21-(B21/12)*3 -> 0 | E21: =B21+C21-D21 -> 12823592 | F21: =E21/E9 -> 1775.6289
A22: Chi phí khấu hao thay tấm pin sửa chửa hệ thống (2023) | C22: 897588 | D22: =B22-(B22/12)*3 -> 0 | E22: =B22+C22-D22 -> 897588 | F22: =E22/E9 -> 124.28524
A23: Chi phí khấu hao sửa chửa hệ thống ĐMT(2025) | C23: 260960 | E23: =B23+C23-D23 -> 260960 | F23: =E23/E9 -> 36.134035
A25: Cộng | B25: =B21+B24 -> 0 | C25: =C16+C21+C22+C23 -> 13982140 | D25: =D16+D21+D22+D23 -> 0 | E25: =E16+E21+E22+E23 -> 13982140 | F25: =F16+F21+F22+F23 -> 1936.0482
A27: Người ghi sổ | C27: Kế toán trưởng | E27: Giám đốc
A28: (Ký , họ tên) | C28: (Ký , họ tên) | E28: (Ký , họ tên,đóng dấu)
A30: =A1 -> Công ty TNHH Thuận An | E30: Mẫu số : S 25 - SKT/DNN
A31: =A2 -> Ấp Chồng Nô 3, Xã Hòa Tân, Huyện Cầu Kè, Tỉnh Trà Vinh | E31: Ban hành theo quyết định số
E32: 133/2016/TT-BTC ngày 14/06/2016
E33: của bộ tài chính
A34: THẺ TÍNH GIÁ THÀNH SẢN PHẨM
A35: Tháng 12 /2025
B36: ĐỊA ĐIỂM : | C36: HÒA ÂN
B37: Tên sản phẩm , dịch vụ : Điện năng lượng mặt trời
B38: Số lượng sản phẩm , dịch vụ hoàn thành trong kỳ : | E38: ='SL 2025'!C57 -> 13924
B39: Phương pháp tính giá thành : Giá thành thực tế
A41: Khoản mục chi phí sản xuất kinh doanh | B41: Chi phí SXKD dở dang đầu kỳ | C41: Chi phí SXKD phát sinh trong kỳ | D41: Chi phí SXKD dở dang cuối kỳ | E41: Giá thành sản phẩm dịch vụ trong kỳ
E42: Giá thành | F42: Giá thành đơn vị
A43: 1. Vật liệu
A45: 2. Nhân công | C45: 0 | E45: =C45 -> 0 | F45: =E45/E38 -> 0
A47: 3. Máy
A49: 4. Chi phí chung
A50: Chi phí khấu hao hệ thống pin năng lượng mặt trời | C50: 21449563 | D50: =B50-(B50/12)*3 -> 0 | E50: =B50+C50-D50 -> 21449563 | F50: =E50/E38 -> 1540.4742
A51: Chi phí khấu hao thay tấm pin sửa chửa hệ thống | C51: 2872328 | E51: =B51+C51-D51 -> 2872328 | F51: =E51/E38 -> 206.28612
...
