Workbook

Sheet THONG TIN
A3: Tên doanh nghiệp: | C3: Công ty TNHH Thuận An
A4: Trụ sở chính : | C4: Ấp Chồng Nô 3, Xã Hòa Tân, Huyện Cầu Kè, Tỉnh Trà Vinh
A5: Mã số thuế : | C5: 2 1 0 0 4 0 6 8 1 8

Sheet SL 2022
A1: Tên doanh nghiệp: | C1: ='THONG TIN'!C3 -> Công ty TNHH Thuận An
A2: Trụ sở chính: | C2: ='THONG TIN'!C4 -> Ấp Chồng Nô 3, Xã Hòa Tân, Huyện Cầu Kè, Tỉnh Trà Vinh
A3: BẢNG BÁO CÁO SẢN LƯỢNG SẢN XUẤT VÀ TIÊU THỤ ĐIỆN SOLAR
A4: HÒA TÂN
B5: Công suất dự án : | D5: 62,3 Kw | E5: Năm | F5: 2022
A7: Thời gian | C7: Sản lượng phát | D7: Sản lượng bán | E7: Sản lượng phát bỏ | F7: Sản lượng tiêu dùng | I7: Giá thành
A8: Sản lượng còn lại 12/2021 | C8: 0
A9: Tháng 1 | C9: =D9+E9+F9 -> 11790 | D9: =2650+9110 -> 11760 | E9: 10 | F9: 20 | G9: Hóa đơn cũ Số 50 + 52 | I9: ='T1'!F23 -> 1201.6617
A10: Tháng 2 | C10: =D10+E10+F10 -> 8501 | D10: 8360 | E10: 100 | F10: 41 | G10: Hóa đơn cũ Số 57 | I10: ='T2'!F23 -> 1666.5795
A11: Tháng 3 | C11: =D11+E11+F11 -> 8654 | D11: 8610 | E11: 10 | F11: 34 | G11: Hóa đơn cũ Số 62 | I11: ='T3'!F23 -> 1637.1149
A12: Quý I | C12: =SUM(C8:C11) -> 28945 | D12: =SUM(D9:D11) -> 28730 | E12: =SUM(E9:E11) -> 120 | F12: =SUM(F9:F11) -> 95
A13: Tháng 4 | C13: =D13+E13+F13 -> 8032 | D13: 7960 | E13: 10 | F13: 62 | G13: Hóa đơn Số 02 | I13: ='T4'!F23 -> 1763.8934
A14: Tháng 5 | C14: =D14+E14+F14 -> 7450 | D14: 7280 | E14: 50 | F14: 120 | G14: Hóa đơn Số 4 | I14: ='T5'!F23 -> 1901.6902
A15: Tháng 6 | C15: =D15+E15+F15 -> 8003 | D15: 7890 | E15: 50 | F15: 63 | G15: Hóa đơn Số 11 | I15: ='T6'!F23 -> 1770.2851
A16: Quý II | C16: =SUM(C13:C15) -> 23485 | D16: =SUM(D13:D15) -> 23130 | E16: =SUM(E13:E15) -> 110 | F16: =SUM(F13:F15) -> 245
A17: Tháng 7 | C17: =D17+E17+F17 -> 7259 | D17: 7100 | E17: 100 | F17: 59 | G17: Hóa đơn Số 16 | I17: ='T7'!F23 -> 1951.7278
A18: Tháng 8 | C18: =D18+E18+F18 -> 7779 | D18: 7690 | E18: 10 | F18: 79 | G18: Hóa đơn Số 20 | I18: ='T8'!F23 -> 1821.2613
A19: Tháng 9 | C19: =D19+E19+F19 -> 7055 | D19: 6890 | E19: 50 | F19: 115 | G19: Hóa đơn Số 23 | I19: ='T9'!F23 -> 2008.1633
A20: Quý III | C20: =SUM(C17:C19) -> 22093 | D20: =SUM(D17:D19) -> 21680 | E20: =SUM(E17:E19) -> 160 | F20: =SUM(F17:F19) -> 253
A21: Tháng 10 | C21: =D21+E21+F21 -> 6865 | D21: 6710 | E21: 100 | F21: 55 | G21: Hóa đơn Số 26 | I21: ='T10'!F23 -> 2063.7425
A22: Tháng 11 | C22: =D22+E22+F22 -> 6752 | D22: 6600 | E22: 55 | F22: 97 | G22: Hóa đơn Số 29 | I22: ='T11'!F23 -> 2098.2808
A23: Tháng 12 | C23: =D23+E23+F23 -> 5832 | D23: 5720 | E23: 10 | F23: 102 | G23: Hóa đơn Số 01/2023 | I23: ='T12'!F23 -> 2429.2853
A24: Quý IV | C24: =SUM(C21:C23) -> 19449 | D24: =SUM(D21:D23) -> 19030 | E24: =SUM(E21:E23) -> 165 | F24: =SUM(F21:F23) -> 254
C25: =C12+C16+C20+C24 -> 93972 | D25: =D12+D16+D20+D24 -> 92570 | E25: =SUM(E12+E16+E20+E24) -> 555 | F25: =SUM(F12+F16+F20+F24) -> 847 | G25: =E25+F25 -> 1402
A27: Hướng dẫn | C27: Sản lượng phát ghi số liệu từ phần mềm quản lý Solar
C28: Sản lượng bán ghi số liệu từ cơ quan điện lực chốt sổ + SL nội suy đến cuối cuối tháng
C29: Sản lượng phát bỏ ghi nhận điện lực không mua và những ngày cúp điện
C30: Sản lượng tiêu dùng là chênh lệch còn lại
A34: Tên doanh nghiệp: | C34: ='THONG TIN'!C3 -> Công ty TNHH Thuận An
A35: Trụ sở chính: | C35: ='THONG TIN'!C4 -> Ấp Chồng Nô 3, Xã Hòa Tân, Huyện Cầu Kè, Tỉnh Trà Vinh
A36: BẢNG BÁO CÁO SẢN LƯỢNG SẢN XUẤT VÀ TIÊU THỤ ĐIỆN SOLAR
A37: HÒA ÂN
B38: Công suất dự án : | D38: 142,4 Kw | E38: Năm | F38: 2022
A40: Thời gian | C40: Sản lượng phát | D40: Sản lượng bán | E40: Sản lượng phát bỏ | F40: Sản lượng tiêu dùng | I40: Giá thành
A41: Sản lượng còn lại 12/2021 | C41: 0
A42: Tháng 1 | C42: =D42+E42+F42 -> 20176 | D42: 19376 | E42: 500 | F42: 300 | G42: Hóa đơn cũ Số 53 | I42: ='T1'!F51 -> 1227.7727
A43: Tháng 2 | C43: =D43+E43+F43 -> 19213 | D43: 16513 | E43: 1700 | F43: 1000 | G43: Hóa đơn cũ Số 56 | I43: ='T2'!F51 -> 1289.3115
A44: Tháng 3 | C44: =D44+E44+F44 -> 19976 | D44: 19026 | E44: 700 | F44: 250 | G44: Hóa đơn cũ Số 59 | I44: ='T3'!F51 -> 1240.0651
A45: Quý I | C45: =SUM(C41:C44) -> 59365 | D45: =SUM(D41:D44) -> 54915 | E45: =SUM(E42:E44) -> 2900 | F45: =SUM(F42:F44) -> 1550
A46: Tháng 4 | C46: =D46+E46+F46 -> 19432 | D46: 17732 | E46: 1400 | F46: 300 | G46: Hóa đơn Số 01 | I46: ='T4'!F51 -> 1274.7808
...

Sheet T1
A1: ='THONG TIN'!C3 -> Công ty TNHH Thuận An | E1: Mẫu số : S 25 - SKT/DNN
A2: ='THONG TIN'!C4 -> Ấp Chồng Nô 3, Xã Hòa Tân, Huyện Cầu Kè, Tỉnh Trà Vinh | E2: Ban hành theo quyết định số
E3: 133/2016/TT-BTC ngày 14/06/2016
E4: của bộ tài chính
A5: THẺ TÍNH GIÁ THÀNH SẢN PHẨM
A6: Tháng 1/2022
B7: ĐỊA ĐIỂM : | C7: HÒA TÂN
B8: Tên sản phẩm , dịch vụ : Điện năng lượng mặt trời
B9: Số lượng sản phẩm , dịch vụ hoàn thành trong kỳ : | E9: 11790
B10: Phương pháp tính giá thành : Giá thành thực tế
A12: Khoản mục chi phí sản xuất kinh doanh | B12: Chi phí SXKD dở dang đầu kỳ | C12: Chi phí SXKD phát sinh trong kỳ | D12: Chi phí SXKD dở dang cuối kỳ | E12: Giá thành sản phẩm dịch vụ trong kỳ
E13: Giá thành | F13: Giá thành đơn vị
A14: 1. Vật liệu
A16: 2. Nhân công | C16: =16128000/12 -> 1344000 | E16: =C16 -> 1344000 | F16: =E16/E9 -> 113.99491
A18: 3. Máy
A20: 4. Chi phí chung
A21: Chi phí khấu hao hệ thống pin năng lượng mặt trời | C21: =12823592+(B21/12) -> 12823592 | D21: =B21-(B21/12) -> 0 | E21: =B21+C21-D21 -> 12823592 | F21: =E21/E9 -> 1087.6668
A23: Cộng | B23: =B21+B22 -> 0 | C23: =C21+C22 -> 12823592 | D23: =D21+D22 -> 0 | E23: =E21+E22 -> 12823592 | F23: =F16+F21 -> 1201.6617
A25: Người ghi sổ | C25: Kế toán trưởng | E25: Giám đốc
A26: (Ký , họ tên) | C26: (Ký , họ tên) | E26: (Ký , họ tên,đóng dấu)
A28: =A1 -> Công ty TNHH Thuận An | E28: Mẫu số : S 25 - SKT/DNN
A29: =A2 -> Ấp Chồng Nô 3, Xã Hòa Tân, Huyện Cầu Kè, Tỉnh Trà Vinh | E29: Ban hành theo quyết định số
E30: 133/2016/TT-BTC ngày 14/06/2016
E31: của bộ tài chính
A32: THẺ TÍNH GIÁ THÀNH SẢN PHẨM
A33: Tháng 1/2022
B34: ĐỊA ĐIỂM : | C34: HÒA ÂN
B35: Tên sản phẩm , dịch vụ : Điện năng lượng mặt trời
B36: Số lượng sản phẩm , dịch vụ hoàn thành trong kỳ : | E36: 20176
B37: Phương pháp tính giá thành : Giá thành thực tế
A39: Khoản mục chi phí sản xuất kinh doanh | B39: Chi phí SXKD dở dang đầu kỳ | C39: Chi phí SXKD phát sinh trong kỳ | D39: Chi phí SXKD dở dang cuối kỳ | E39: Giá thành sản phẩm dịch vụ trong kỳ
E40: Giá thành | F40: Giá thành đơn vị
A41: 1. Vật liệu
A43: 2. Nhân công | C43: =29952000/12 -> 2496000 | E43: =C43 -> 2496000 | F43: =E43/E36 -> 123.71134
A45: 3. Máy
A47: 4. Chi phí chung
A48: Chi phí khấu hao hệ thống pin năng lượng mặt trời | C48: 21449563 | D48: =B48-(B48/12)*3 -> 0 | E48: =B48+C48-D48 -> 21449563 | F48: =E48/E36 -> 1063.1227
A49: Chi phí khấu hao sửa chửa hệ thống ĐMT | C49: 825978 | E49: =B49+C49-D49 -> 825978 | F49: =E49/E36 -> 40.93864
A51: Cộng | B51: =B48+B49 -> 0 | C51: =C48+C49 -> 22275541 | D51: =D48+D49 -> 0 | E51: =E48+E49 -> 22275541 | F51: =F43+F48+F49 -> 1227.7727
A53: Người ghi sổ | C53: Kế toán trưởng | E53: Giám đốc
...

Sheet T2
A1: ='THONG TIN'!C3 -> Công ty TNHH Thuận An | E1: Mẫu số : S 25 - SKT/DNN
A2: ='THONG TIN'!C4 -> Ấp Chồng Nô 3, Xã Hòa Tân, Huyện Cầu Kè, Tỉnh Trà Vinh | E2: Ban hành theo quyết định số
E3: 133/2016/TT-BTC ngày 14/06/2016
E4: của bộ tài chính
A5: THẺ TÍNH GIÁ THÀNH SẢN PHẨM
A6: Tháng 2/2022
B7: ĐỊA ĐIỂM : | C7: HÒA TÂN
B8: Tên sản phẩm , dịch vụ : Điện năng lượng mặt trời
B9: Số lượng sản phẩm , dịch vụ hoàn thành trong kỳ : | E9: 8501
B10: Phương pháp tính giá thành : Giá thành thực tế
A12: Khoản mục chi phí sản xuất kinh doanh | B12: Chi phí SXKD dở dang đầu kỳ | C12: Chi phí SXKD phát sinh trong kỳ | D12: Chi phí SXKD dở dang cuối kỳ | E12: Giá thành sản phẩm dịch vụ trong kỳ
E13: Giá thành | F13: Giá thành đơn vị
A14: 1. Vật liệu
A16: 2. Nhân công | C16: =16128000/12 -> 1344000 | E16: =C16 -> 1344000 | F16: =E16/E9 -> 158.09905
A18: 3. Máy
A20: 4. Chi phí chung
A21: Chi phí khấu hao hệ thống pin năng lượng mặt trời | C21: =12823592+(B21/12) -> 12823592 | D21: =B21-(B21/12)*3 -> 0 | E21: =B21+C21-D21 -> 12823592 | F21: =E21/E9 -> 1508.4804
A23: Cộng | B23: =B21+B22 -> 0 | C23: =C21+C22 -> 12823592 | D23: =D21+D22 -> 0 | E23: =E21+E22 -> 12823592 | F23: =F16+F21 -> 1666.5795
A25: Người ghi sổ | C25: Kế toán trưởng | E25: Giám đốc
A26: (Ký , họ tên) | C26: (Ký , họ tên) | E26: (Ký , họ tên,đóng dấu)
A28: =A1 -> Công ty TNHH Thuận An | E28: Mẫu số : S 25 - SKT/DNN
A29: =A2 -> Ấp Chồng Nô 3, Xã Hòa Tân, Huyện Cầu Kè, Tỉnh Trà Vinh | E29: Ban hành theo quyết định số
E30: 133/2016/TT-BTC ngày 14/06/2016
E31: của bộ tài chính
A32: THẺ TÍNH GIÁ THÀNH SẢN PHẨM
A33: Tháng 2/2022
B34: ĐỊA ĐIỂM : | C34: HÒA ÂN
B35: Tên sản phẩm , dịch vụ : Điện năng lượng mặt trời
B36: Số lượng sản phẩm , dịch vụ hoàn thành trong kỳ : | E36: 19213
B37: Phương pháp tính giá thành : Giá thành thực tế
A39: Khoản mục chi phí sản xuất kinh doanh | B39: Chi phí SXKD dở dang đầu kỳ | C39: Chi phí SXKD phát sinh trong kỳ | D39: Chi phí SXKD dở dang cuối kỳ | E39: Giá thành sản phẩm dịch vụ trong kỳ
E40: Giá thành | F40: Giá thành đơn vị
A41: 1. Vật liệu
A43: 2. Nhân công | C43: =29952000/12 -> 2496000 | E43: =C43 -> 2496000 | F43: =E43/E36 -> 129.91204
A45: 3. Máy
A47: 4. Chi phí chung
A48: Chi phí khấu hao hệ thống pin năng lượng mặt trời | C48: 21449563 | D48: =B48-(B48/12)*3 -> 0 | E48: =B48+C48-D48 -> 21449563 | F48: =E48/E36 -> 1116.4088
A49: Chi phí khấu hao sửa chửa hệ thống ĐMT | C49: 825978 | E49: =B49+C49-D49 -> 825978 | F49: =E49/E36 -> 42.990579
A51: Cộng | B51: =B48+B49 -> 0 | C51: =C48+C49 -> 22275541 | D51: =D48+D49 -> 0 | E51: =E48+E49 -> 22275541 | F51: =F43+F48+F49 -> 1289.3115
A53: Người ghi sổ | C53: Kế toán trưởng | E53: Giám đốc
...

Sheet T3
A1: ='THONG TIN'!C3 -> Công ty TNHH Thuận An | E1: Mẫu số : S 25 - SKT/DNN
A2: ='THONG TIN'!C4 -> Ấp Chồng Nô 3, Xã Hòa Tân, Huyện Cầu Kè, Tỉnh Trà Vinh | E2: Ban hành theo quyết định số
E3: 133/2016/TT-BTC ngày 14/06/2016
E4: của bộ tài chính
A5: THẺ TÍNH GIÁ THÀNH SẢN PHẨM
A6: Tháng 3/2022
B7: ĐỊA ĐIỂM : | C7: HÒA TÂN
B8: Tên sản phẩm , dịch vụ : Điện năng lượng mặt trời
B9: Số lượng sản phẩm , dịch vụ hoàn thành trong kỳ : | E9: 8654
B10: Phương pháp tính giá thành : Giá thành thực tế
A12: Khoản mục chi phí sản xuất kinh doanh | B12: Chi phí SXKD dở dang đầu kỳ | C12: Chi phí SXKD phát sinh trong kỳ | D12: Chi phí SXKD dở dang cuối kỳ | E12: Giá thành sản phẩm dịch vụ trong kỳ
E13: Giá thành | F13: Giá thành đơn vị
A14: 1. Vật liệu
A16: 2. Nhân công | C16: =16128000/12 -> 1344000 | E16: =C16 -> 1344000 | F16: =E16/E9 -> 155.30391
A18: 3. Máy
A20: 4. Chi phí chung
A21: Chi phí khấu hao hệ thống pin năng lượng mặt trời | C21: =12823592+(B21/12) -> 12823592 | D21: =B21-(B21/12)*3 -> 0 | E21: =B21+C21-D21 -> 12823592 | F21: =E21/E9 -> 1481.811
A23: Cộng | B23: =B21+B22 -> 0 | C23: =C21+C22 -> 12823592 | D23: =D21+D22 -> 0 | E23: =E21+E22 -> 12823592 | F23: =SUM(F16+F21) -> 1637.1149
A25: Người ghi sổ | C25: Kế toán trưởng | E25: Giám đốc
A26: (Ký , họ tên) | C26: (Ký , họ tên) | E26: (Ký , họ tên,đóng dấu)
A28: =A1 -> Công ty TNHH Thuận An | E28: Mẫu số : S 25 - SKT/DNN
A29: =A2 -> Ấp Chồng Nô 3, Xã Hòa Tân, Huyện Cầu Kè, Tỉnh Trà Vinh | E29: Ban hành theo quyết định số
E30: 133/2016/TT-BTC ngày 14/06/2016
E31: của bộ tài chính
A32: THẺ TÍNH GIÁ THÀNH SẢN PHẨM
A33: Tháng 3/2022
B34: ĐỊA ĐIỂM : | C34: HÒA ÂN
B35: Tên sản phẩm , dịch vụ : Điện năng lượng mặt trời
B36: Số lượng sản phẩm , dịch vụ hoàn thành trong kỳ : | E36: 19976
B37: Phương pháp tính giá thành : Giá thành thực tế
A39: Khoản mục chi phí sản xuất kinh doanh | B39: Chi phí SXKD dở dang đầu kỳ | C39: Chi phí SXKD phát sinh trong kỳ | D39: Chi phí SXKD dở dang cuối kỳ | E39: Giá thành sản phẩm dịch vụ trong kỳ
E40: Giá thành | F40: Giá thành đơn vị
A41: 1. Vật liệu
A43: 2. Nhân công | C43: =29952000/12 -> 2496000 | E43: =C43 -> 2496000 | F43: =E43/E36 -> 124.94994
A45: 3. Máy
A47: 4. Chi phí chung
A48: Chi phí khấu hao hệ thống pin năng lượng mặt trời | C48: 21449563 | D48: =B48-(B48/12)*3 -> 0 | E48: =B48+C48-D48 -> 21449563 | F48: =E48/E36 -> 1073.7667
A49: Chi phí khấu hao sửa chửa hệ thống ĐMT | C49: =825978+(B49/12) -> 825978 | E49: =B49+C49-D49 -> 825978 | F49: =E49/E36 -> 41.348518
A51: Cộng | B51: =B48+B49 -> 0 | C51: =C48+C49 -> 22275541 | D51: =D48+D49 -> 0 | E51: =E48+E49 -> 22275541 | F51: =F43+F48+F49 -> 1240.0651
A53: Người ghi sổ | C53: Kế toán trưởng | E53: Giám đốc
...

Sheet T4
A1: ='THONG TIN'!C3 -> Công ty TNHH Thuận An | E1: Mẫu số : S 25 - SKT/DNN
A2: ='THONG TIN'!C4 -> Ấp Chồng Nô 3, Xã Hòa Tân, Huyện Cầu Kè, Tỉnh Trà Vinh | E2: Ban hành theo quyết định số
E3: 133/2016/TT-BTC ngày 14/06/2016
E4: của bộ tài chính
A5: THẺ TÍNH GIÁ THÀNH SẢN PHẨM
A6: Tháng 4/2022
B7: ĐỊA ĐIỂM : | C7: HÒA TÂN
B8: Tên sản phẩm , dịch vụ : Điện năng lượng mặt trời
B9: Số lượng sản phẩm , dịch vụ hoàn thành trong kỳ : | E9: 8032
B10: Phương pháp tính giá thành : Giá thành thực tế
A12: Khoản mục chi phí sản xuất kinh doanh | B12: Chi phí SXKD dở dang đầu kỳ | C12: Chi phí SXKD phát sinh trong kỳ | D12: Chi phí SXKD dở dang cuối kỳ | E12: Giá thành sản phẩm dịch vụ trong kỳ
E13: Giá thành | F13: Giá thành đơn vị
A14: 1. Vật liệu
A16: 2. Nhân công | C16: =16128000/12 -> 1344000 | E16: =C16 -> 1344000 | F16: =E16/E9 -> 167.33068
A18: 3. Máy
A20: 4. Chi phí chung
A21: Chi phí khấu hao hệ thống pin năng lượng mặt trời | C21: =12823592+(B21/12) -> 12823592 | D21: =B21-(B21/12)*3 -> 0 | E21: =B21+C21-D21 -> 12823592 | F21: =E21/E9 -> 1596.5627
A23: Cộng | B23: =B21+B22 -> 0 | C23: =C21+C22 -> 12823592 | D23: =D21+D22 -> 0 | E23: =E21+E22 -> 12823592 | F23: =F16+F21 -> 1763.8934
A25: Người ghi sổ | C25: Kế toán trưởng | E25: Giám đốc
A26: (Ký , họ tên) | C26: (Ký , họ tên) | E26: (Ký , họ tên,đóng dấu)
A28: =A1 -> Công ty TNHH Thuận An | E28: Mẫu số : S 25 - SKT/DNN
A29: =A2 -> Ấp Chồng Nô 3, Xã Hòa Tân, Huyện Cầu Kè, Tỉnh Trà Vinh | E29: Ban hành theo quyết định số
E30: 133/2016/TT-BTC ngày 14/06/2016
E31: của bộ tài chính
A32: THẺ TÍNH GIÁ THÀNH SẢN PHẨM
A33: Tháng 4/2022
B34: ĐỊA ĐIỂM : | C34: HÒA ÂN
B35: Tên sản phẩm , dịch vụ : Điện năng lượng mặt trời
B36: Số lượng sản phẩm , dịch vụ hoàn thành trong kỳ : | E36: 19432
B37: Phương pháp tính giá thành : Giá thành thực tế
A39: Khoản mục chi phí sản xuất kinh doanh | B39: Chi phí SXKD dở dang đầu kỳ | C39: Chi phí SXKD phát sinh trong kỳ | D39: Chi phí SXKD dở dang cuối kỳ | E39: Giá thành sản phẩm dịch vụ trong kỳ
E40: Giá thành | F40: Giá thành đơn vị
A41: 1. Vật liệu
A43: 2. Nhân công | C43: =29952000/12 -> 2496000 | E43: =C43 -> 2496000 | F43: =E43/E36 -> 128.44792
A45: 3. Máy
A47: 4. Chi phí chung
A48: Chi phí khấu hao hệ thống pin năng lượng mặt trời | C48: 21449563 | D48: =B48-(B48/12)*3 -> 0 | E48: =B48+C48-D48 -> 21449563 | F48: =E48/E36 -> 1103.8268
A49: Chi phí khấu hao sửa chửa hệ thống ĐMT | C49: =825978+(B49/12) -> 825978 | E49: =B49+C49-D49 -> 825978 | F49: =E49/E36 -> 42.506072
A51: Cộng | B51: =B48+B49 -> 0 | C51: =C48+C49+C50 -> 22275541 | D51: =D48+D49 -> 0 | E51: =E48+E49+E50 -> 22275541 | F51: =F43+F48+F49+F50 -> 1274.7808
A53: Người ghi sổ | C53: Kế toán trưởng | E53: Giám đốc
...

Sheet T5
A1: ='THONG TIN'!C3 -> Công ty TNHH Thuận An | E1: Mẫu số : S 25 - SKT/DNN
A2: ='THONG TIN'!C4 -> Ấp Chồng Nô 3, Xã Hòa Tân, Huyện Cầu Kè, Tỉnh Trà Vinh | E2: Ban hành theo quyết định số
E3: 133/2016/TT-BTC ngày 14/06/2016
E4: của bộ tài chính
A5: THẺ TÍNH GIÁ THÀNH SẢN PHẨM
A6: Tháng 5/2022
B7: ĐỊA ĐIỂM : | C7: HÒA TÂN
B8: Tên sản phẩm , dịch vụ : Điện năng lượng mặt trời
B9: Số lượng sản phẩm , dịch vụ hoàn thành trong kỳ : | E9: 7450
B10: Phương pháp tính giá thành : Giá thành thực tế
A12: Khoản mục chi phí sản xuất kinh doanh | B12: Chi phí SXKD dở dang đầu kỳ | C12: Chi phí SXKD phát sinh trong kỳ | D12: Chi phí SXKD dở dang cuối kỳ | E12: Giá thành sản phẩm dịch vụ trong kỳ
E13: Giá thành | F13: Giá thành đơn vị
A14: 1. Vật liệu
A16: 2. Nhân công | C16: =16128000/12 -> 1344000 | E16: =C16 -> 1344000 | F16: =E16/E9 -> 180.40268
A18: 3. Máy
A20: 4. Chi phí chung
A21: Chi phí khấu hao hệ thống pin năng lượng mặt trời | C21: =12823592+(B21/12) -> 12823592 | D21: =B21-(B21/12)*3 -> 0 | E21: =B21+C21-D21 -> 12823592 | F21: =E21/E9 -> 1721.2875
A23: Cộng | B23: =B21+B22 -> 0 | C23: =C21+C22 -> 12823592 | D23: =D21+D22 -> 0 | E23: =E21+E22 -> 12823592 | F23: =F16+F21 -> 1901.6902
A25: Người ghi sổ | C25: Kế toán trưởng | E25: Giám đốc
A26: (Ký , họ tên) | C26: (Ký , họ tên) | E26: (Ký , họ tên,đóng dấu)
A28: =A1 -> Công ty TNHH Thuận An | E28: Mẫu số : S 25 - SKT/DNN
A29: =A2 -> Ấp Chồng Nô 3, Xã Hòa Tân, Huyện Cầu Kè, Tỉnh Trà Vinh | E29: Ban hành theo quyết định số
E30: 133/2016/TT-BTC ngày 14/06/2016
E31: của bộ tài chính
A32: THẺ TÍNH GIÁ THÀNH SẢN PHẨM
A33: Tháng 5 /2022
B34: ĐỊA ĐIỂM : | C34: HÒA ÂN
B35: Tên sản phẩm , dịch vụ : Điện năng lượng mặt trời
B36: Số lượng sản phẩm , dịch vụ hoàn thành trong kỳ : | E36: 16587
B37: Phương pháp tính giá thành : Giá thành thực tế
A39: Khoản mục chi phí sản xuất kinh doanh | B39: Chi phí SXKD dở dang đầu kỳ | C39: Chi phí SXKD phát sinh trong kỳ | D39: Chi phí SXKD dở dang cuối kỳ | E39: Giá thành sản phẩm dịch vụ trong kỳ
E40: Giá thành | F40: Giá thành đơn vị
A41: 1. Vật liệu
A43: 2. Nhân công | C43: =29952000/12 -> 2496000 | E43: =C43 -> 2496000 | F43: =E43/E36 -> 150.47929
A45: 3. Máy
A47: 4. Chi phí chung
A48: Chi phí khấu hao hệ thống pin năng lượng mặt trời | C48: 21449563 | D48: =B48-(B48/12)*3 -> 0 | E48: =B48+C48-D48 -> 21449563 | F48: =E48/E36 -> 1293.1551
A49: Chi phí khấu hao sửa chửa hệ thống ĐMT | C49: =825978+(B49/12) -> 825978 | E49: =B49+C49-D49 -> 825978 | F49: =E49/E36 -> 49.796708
A51: Cộng | B51: =B48+B49 -> 0 | C51: =C48+C49+C50 -> 22275541 | D51: =D48+D49 -> 0 | E51: =E48+E49+E50 -> 22275541 | F51: =F43+F48+F49 -> 1493.4311
A53: Người ghi sổ | C53: Kế toán trưởng | E53: Giám đốc
...

Sheet T6
A1: ='THONG TIN'!C3 -> Công ty TNHH Thuận An | E1: Mẫu số : S 25 - SKT/DNN
A2: ='THONG TIN'!C4 -> Ấp Chồng Nô 3, Xã Hòa Tân, Huyện Cầu Kè, Tỉnh Trà Vinh | E2: Ban hành theo quyết định số
E3: 133/2016/TT-BTC ngày 14/06/2016
E4: của bộ tài chính
A5: THẺ TÍNH GIÁ THÀNH SẢN PHẨM
A6: Tháng 6/2022
B7: ĐỊA ĐIỂM : | C7: HÒA TÂN
B8: Tên sản phẩm , dịch vụ : Điện năng lượng mặt trời
B9: Số lượng sản phẩm , dịch vụ hoàn thành trong kỳ : | E9: 8003
B10: Phương pháp tính giá thành : Giá thành thực tế
A12: Khoản mục chi phí sản xuất kinh doanh | B12: Chi phí SXKD dở dang đầu kỳ | C12: Chi phí SXKD phát sinh trong kỳ | D12: Chi phí SXKD dở dang cuối kỳ | E12: Giá thành sản phẩm dịch vụ trong kỳ
E13: Giá thành | F13: Giá thành đơn vị
A14: 1. Vật liệu
A16: 2. Nhân công | C16: =16128000/12 -> 1344000 | E16: =C16 -> 1344000 | F16: =E16/E9 -> 167.93702
A18: 3. Máy
A20: 4. Chi phí chung
A21: Chi phí khấu hao hệ thống pin năng lượng mặt trời | C21: =12823592+(B21/12) -> 12823592 | D21: =B21-(B21/12)*3 -> 0 | E21: =B21+C21-D21 -> 12823592 | F21: =E21/E9 -> 1602.3481
A23: Cộng | B23: =B21+B22 -> 0 | C23: =C21+C22 -> 12823592 | D23: =D21+D22 -> 0 | E23: =E21+E22 -> 12823592 | F23: =F16+F21 -> 1770.2851
A25: Người ghi sổ | C25: Kế toán trưởng | E25: Giám đốc
A26: (Ký , họ tên) | C26: (Ký , họ tên) | E26: (Ký , họ tên,đóng dấu)
A28: =A1 -> Công ty TNHH Thuận An | E28: Mẫu số : S 25 - SKT/DNN
A29: =A2 -> Ấp Chồng Nô 3, Xã Hòa Tân, Huyện Cầu Kè, Tỉnh Trà Vinh | E29: Ban hành theo quyết định số
E30: 133/2016/TT-BTC ngày 14/06/2016
E31: của bộ tài chính
A32: THẺ TÍNH GIÁ THÀNH SẢN PHẨM
A33: Tháng 6 /2022
B34: ĐỊA ĐIỂM : | C34: HÒA ÂN
B35: Tên sản phẩm , dịch vụ : Điện năng lượng mặt trời
B36: Số lượng sản phẩm , dịch vụ hoàn thành trong kỳ : | E36: 18136
B37: Phương pháp tính giá thành : Giá thành thực tế
A39: Khoản mục chi phí sản xuất kinh doanh | B39: Chi phí SXKD dở dang đầu kỳ | C39: Chi phí SXKD phát sinh trong kỳ | D39: Chi phí SXKD dở dang cuối kỳ | E39: Giá thành sản phẩm dịch vụ trong kỳ
E40: Giá thành | F40: Giá thành đơn vị
A41: 1. Vật liệu
A43: 2. Nhân công | C43: =29952000/12 -> 2496000 | E43: =C43 -> 2496000 | F43: =E43/E36 -> 137.62682
A45: 3. Máy
A47: 4. Chi phí chung
A48: Chi phí khấu hao hệ thống pin năng lượng mặt trời | C48: 21449563 | D48: =B48-(B48/12)*3 -> 0 | E48: =B48+C48-D48 -> 21449563 | F48: =E48/E36 -> 1182.7064
A49: Chi phí khấu hao sửa chửa hệ thống ĐMT | C49: =825978+(B49/12) -> 825978 | E49: =B49+C49-D49 -> 825978 | F49: =E49/E36 -> 45.54356
A51: Cộng | B51: =B48+B49 -> 0 | C51: =C48+C49+C50 -> 22275541 | D51: =D48+D49 -> 0 | E51: =E48+E49+E50 -> 22275541 | F51: =F43+F48+F49 -> 1365.8768
A53: Người ghi sổ | C53: Kế toán trưởng | E53: Giám đốc
...

Sheet T7
A1: ='THONG TIN'!C3 -> Công ty TNHH Thuận An | E1: Mẫu số : S 25 - SKT/DNN
A2: ='THONG TIN'!C4 -> Ấp Chồng Nô 3, Xã Hòa Tân, Huyện Cầu Kè, Tỉnh Trà Vinh | E2: Ban hành theo quyết định số
E3: 133/2016/TT-BTC ngày 14/06/2016
E4: của bộ tài chính
A5: THẺ TÍNH GIÁ THÀNH SẢN PHẨM
A6: Tháng 7/2022
B7: ĐỊA ĐIỂM : | C7: HÒA TÂN
B8: Tên sản phẩm , dịch vụ : Điện năng lượng mặt trời
B9: Số lượng sản phẩm , dịch vụ hoàn thành trong kỳ : | E9: 7259
B10: Phương pháp tính giá thành : Giá thành thực tế
A12: Khoản mục chi phí sản xuất kinh doanh | B12: Chi phí SXKD dở dang đầu kỳ | C12: Chi phí SXKD phát sinh trong kỳ | D12: Chi phí SXKD dở dang cuối kỳ | E12: Giá thành sản phẩm dịch vụ trong kỳ
E13: Giá thành | F13: Giá thành đơn vị
A14: 1. Vật liệu
A16: 2. Nhân công | C16: =16128000/12 -> 1344000 | E16: =C16 -> 1344000 | F16: =E16/E9 -> 185.14947
A18: 3. Máy
A20: 4. Chi phí chung
A21: Chi phí khấu hao hệ thống pin năng lượng mặt trời | C21: =12823592+(B21/12) -> 12823592 | D21: =B21-(B21/12)*3 -> 0 | E21: =B21+C21-D21 -> 12823592 | F21: =E21/E9 -> 1766.5783
A23: Cộng | B23: =B21+B22 -> 0 | C23: =C21+C22 -> 12823592 | D23: =D21+D22 -> 0 | E23: =E21+E22 -> 12823592 | F23: =F16+F21 -> 1951.7278
A25: Người ghi sổ | C25: Kế toán trưởng | E25: Giám đốc
A26: (Ký , họ tên) | C26: (Ký , họ tên) | E26: (Ký , họ tên,đóng dấu)
A28: =A1 -> Công ty TNHH Thuận An | E28: Mẫu số : S 25 - SKT/DNN
A29: =A2 -> Ấp Chồng Nô 3, Xã Hòa Tân, Huyện Cầu Kè, Tỉnh Trà Vinh | E29: Ban hành theo quyết định số
E30: 133/2016/TT-BTC ngày 14/06/2016
E31: của bộ tài chính
A32: THẺ TÍNH GIÁ THÀNH SẢN PHẨM
A33: Tháng 7 /2022
B34: ĐỊA ĐIỂM : | C34: HÒA ÂN
B35: Tên sản phẩm , dịch vụ : Điện năng lượng mặt trời
B36: Số lượng sản phẩm , dịch vụ hoàn thành trong kỳ : | E36: 16476
B37: Phương pháp tính giá thành : Giá thành thực tế
A39: Khoản mục chi phí sản xuất kinh doanh | B39: Chi phí SXKD dở dang đầu kỳ | C39: Chi phí SXKD phát sinh trong kỳ | D39: Chi phí SXKD dở dang cuối kỳ | E39: Giá thành sản phẩm dịch vụ trong kỳ
E40: Giá thành | F40: Giá thành đơn vị
A41: 1. Vật liệu
A43: 2. Nhân công | C43: =29952000/12 -> 2496000 | E43: =C43 -> 2496000 | F43: =E43/E36 -> 151.49308
A45: 3. Máy
A47: 4. Chi phí chung
A48: Chi phí khấu hao hệ thống pin năng lượng mặt trời | C48: 21449563 | D48: =B48-(B48/12)*3 -> 0 | E48: =B48+C48-D48 -> 21449563 | F48: =E48/E36 -> 1301.8671
A49: Chi phí khấu hao sửa chửa hệ thống ĐMT | C49: =825978+(B49/12) -> 825978 | E49: =B49+C49-D49 -> 825978 | F49: =E49/E36 -> 50.132192
A51: Cộng | B51: =B48+B49 -> 0 | C51: =C48+C49+C50 -> 22275541 | D51: =D48+D49 -> 0 | E51: =E48+E49+E50 -> 22275541 | F51: =F43+F48+F49 -> 1503.4924
A53: Người ghi sổ | C53: Kế toán trưởng | E53: Giám đốc
...

Sheet T8
A1: ='THONG TIN'!C3 -> Công ty TNHH Thuận An | E1: Mẫu số : S 25 - SKT/DNN
A2: ='THONG TIN'!C4 -> Ấp Chồng Nô 3, Xã Hòa Tân, Huyện Cầu Kè, Tỉnh Trà Vinh | E2: Ban hành theo quyết định số
E3: 133/2016/TT-BTC ngày 14/06/2016
E4: của bộ tài chính
A5: THẺ TÍNH GIÁ THÀNH SẢN PHẨM
A6: Tháng 8/2022
B7: ĐỊA ĐIỂM : | C7: HÒA TÂN
B8: Tên sản phẩm , dịch vụ : Điện năng lượng mặt trời
B9: Số lượng sản phẩm , dịch vụ hoàn thành trong kỳ : | E9: 7779
B10: Phương pháp tính giá thành : Giá thành thực tế
A12: Khoản mục chi phí sản xuất kinh doanh | B12: Chi phí SXKD dở dang đầu kỳ | C12: Chi phí SXKD phát sinh trong kỳ | D12: Chi phí SXKD dở dang cuối kỳ | E12: Giá thành sản phẩm dịch vụ trong kỳ
E13: Giá thành | F13: Giá thành đơn vị
A14: 1. Vật liệu
A16: 2. Nhân công | C16: =16128000/12 -> 1344000 | E16: =C16 -> 1344000 | F16: =E16/E9 -> 172.77285
A18: 3. Máy
A20: 4. Chi phí chung
A21: Chi phí khấu hao hệ thống pin năng lượng mặt trời | C21: =12823592+(B21/12) -> 12823592 | D21: =B21-(B21/12)*3 -> 0 | E21: =B21+C21-D21 -> 12823592 | F21: =E21/E9 -> 1648.4885
A23: Cộng | B23: =B21+B22 -> 0 | C23: =C21+C22 -> 12823592 | D23: =D21+D22 -> 0 | E23: =E21+E22 -> 12823592 | F23: =F16+F21 -> 1821.2613
A25: Người ghi sổ | C25: Kế toán trưởng | E25: Giám đốc
A26: (Ký , họ tên) | C26: (Ký , họ tên) | E26: (Ký , họ tên,đóng dấu)
A28: =A1 -> Công ty TNHH Thuận An | E28: Mẫu số : S 25 - SKT/DNN
A29: =A2 -> Ấp Chồng Nô 3, Xã Hòa Tân, Huyện Cầu Kè, Tỉnh Trà Vinh | E29: Ban hành theo quyết định số
E30: 133/2016/TT-BTC ngày 14/06/2016
E31: của bộ tài chính
A32: THẺ TÍNH GIÁ THÀNH SẢN PHẨM
A33: Tháng 8 /2022
B34: ĐỊA ĐIỂM : | C34: HÒA ÂN
B35: Tên sản phẩm , dịch vụ : Điện năng lượng mặt trời
B36: Số lượng sản phẩm , dịch vụ hoàn thành trong kỳ : | E36: 18697
B37: Phương pháp tính giá thành : Giá thành thực tế
A39: Khoản mục chi phí sản xuất kinh doanh | B39: Chi phí SXKD dở dang đầu kỳ | C39: Chi phí SXKD phát sinh trong kỳ | D39: Chi phí SXKD dở dang cuối kỳ | E39: Giá thành sản phẩm dịch vụ trong kỳ
E40: Giá thành | F40: Giá thành đơn vị
A41: 1. Vật liệu
A43: 2. Nhân công | C43: =29952000/12 -> 2496000 | E43: =C43 -> 2496000 | F43: =E43/E36 -> 133.49735
A45: 3. Máy
A47: 4. Chi phí chung
A48: Chi phí khấu hao hệ thống pin năng lượng mặt trời | C48: 21449563 | D48: =B48-(B48/12)*3 -> 0 | E48: =B48+C48-D48 -> 21449563 | F48: =E48/E36 -> 1147.2195
A49: Chi phí khấu hao sửa chửa hệ thống ĐMT | C49: =825978+(B49/12) -> 825978 | E49: =B49+C49-D49 -> 825978 | F49: =E49/E36 -> 44.177034
A51: Cộng | B51: =B48+B49 -> 0 | C51: =C48+C49+C50 -> 22275541 | D51: =D48+D49 -> 0 | E51: =E48+E49+E50 -> 22275541 | F51: =F43+F48+F49 -> 1324.8939
A53: Người ghi sổ | C53: Kế toán trưởng | E53: Giám đốc
...

Sheet T9
A1: ='THONG TIN'!C3 -> Công ty TNHH Thuận An | E1: Mẫu số : S 25 - SKT/DNN
A2: ='THONG TIN'!C4 -> Ấp Chồng Nô 3, Xã Hòa Tân, Huyện Cầu Kè, Tỉnh Trà Vinh | E2: Ban hành theo quyết định số
E3: 133/2016/TT-BTC ngày 14/06/2016
E4: của bộ tài chính
A5: THẺ TÍNH GIÁ THÀNH SẢN PHẨM
A6: Tháng 9/2022
B7: ĐỊA ĐIỂM : | C7: HÒA TÂN
B8: Tên sản phẩm , dịch vụ : Điện năng lượng mặt trời
B9: Số lượng sản phẩm , dịch vụ hoàn thành trong kỳ : | E9: 7055
B10: Phương pháp tính giá thành : Giá thành thực tế
A12: Khoản mục chi phí sản xuất kinh doanh | B12: Chi phí SXKD dở dang đầu kỳ | C12: Chi phí SXKD phát sinh trong kỳ | D12: Chi phí SXKD dở dang cuối kỳ | E12: Giá thành sản phẩm dịch vụ trong kỳ
E13: Giá thành | F13: Giá thành đơn vị
A14: 1. Vật liệu
A16: 2. Nhân công | C16: =16128000/12 -> 1344000 | E16: =C16 -> 1344000 | F16: =E16/E9 -> 190.50319
A18: 3. Máy
A20: 4. Chi phí chung
A21: Chi phí khấu hao hệ thống pin năng lượng mặt trời | C21: =12823592+(B21/12) -> 12823592 | D21: =B21-(B21/12)*3 -> 0 | E21: =B21+C21-D21 -> 12823592 | F21: =E21/E9 -> 1817.6601
A23: Cộng | B23: =B21+B22 -> 0 | C23: =C21+C22 -> 12823592 | D23: =D21+D22 -> 0 | E23: =E21+E22 -> 12823592 | F23: =F16+F21 -> 2008.1633
A25: Người ghi sổ | C25: Kế toán trưởng | E25: Giám đốc
A26: (Ký , họ tên) | C26: (Ký , họ tên) | E26: (Ký , họ tên,đóng dấu)
A28: =A1 -> Công ty TNHH Thuận An | E28: Mẫu số : S 25 - SKT/DNN
A29: =A2 -> Ấp Chồng Nô 3, Xã Hòa Tân, Huyện Cầu Kè, Tỉnh Trà Vinh | E29: Ban hành theo quyết định số
E30: 133/2016/TT-BTC ngày 14/06/2016
E31: của bộ tài chính
A32: THẺ TÍNH GIÁ THÀNH SẢN PHẨM
A33: Tháng 9 /2022
B34: ĐỊA ĐIỂM : | C34: HÒA ÂN
B35: Tên sản phẩm , dịch vụ : Điện năng lượng mặt trời
B36: Số lượng sản phẩm , dịch vụ hoàn thành trong kỳ : | E36: 15251
B37: Phương pháp tính giá thành : Giá thành thực tế
A39: Khoản mục chi phí sản xuất kinh doanh | B39: Chi phí SXKD dở dang đầu kỳ | C39: Chi phí SXKD phát sinh trong kỳ | D39: Chi phí SXKD dở dang cuối kỳ | E39: Giá thành sản phẩm dịch vụ trong kỳ
E40: Giá thành | F40: Giá thành đơn vị
A41: 1. Vật liệu
A43: 2. Nhân công | C43: =29952000/12 -> 2496000 | E43: =C43 -> 2496000 | F43: =E43/E36 -> 163.6614
A45: 3. Máy
A47: 4. Chi phí chung
A48: Chi phí khấu hao hệ thống pin năng lượng mặt trời | C48: 21449563 | D48: =B48-(B48/12)*3 -> 0 | E48: =B48+C48-D48 -> 21449563 | F48: =E48/E36 -> 1406.4365
A49: Chi phí khấu hao sửa chửa hệ thống ĐMT | C49: =825978+(B49/12) -> 825978 | E49: =B49+C49-D49 -> 825978 | F49: =E49/E36 -> 54.15894
A51: Cộng | B51: =B48+B49 -> 0 | C51: =C48+C49+C50 -> 22275541 | D51: =D48+D49 -> 0 | E51: =E48+E49+E50 -> 22275541 | F51: =F43+F48+F49 -> 1624.2568
A53: Người ghi sổ | C53: Kế toán trưởng | E53: Giám đốc
...

Sheet T10
A1: ='THONG TIN'!C3 -> Công ty TNHH Thuận An | E1: Mẫu số : S 25 - SKT/DNN
A2: ='THONG TIN'!C4 -> Ấp Chồng Nô 3, Xã Hòa Tân, Huyện Cầu Kè, Tỉnh Trà Vinh | E2: Ban hành theo quyết định số
E3: 133/2016/TT-BTC ngày 14/06/2016
E4: của bộ tài chính
A5: THẺ TÍNH GIÁ THÀNH SẢN PHẨM
A6: Tháng 10/2022
B7: ĐỊA ĐIỂM : | C7: HÒA TÂN
B8: Tên sản phẩm , dịch vụ : Điện năng lượng mặt trời
B9: Số lượng sản phẩm , dịch vụ hoàn thành trong kỳ : | E9: 6865
B10: Phương pháp tính giá thành : Giá thành thực tế
A12: Khoản mục chi phí sản xuất kinh doanh | B12: Chi phí SXKD dở dang đầu kỳ | C12: Chi phí SXKD phát sinh trong kỳ | D12: Chi phí SXKD dở dang cuối kỳ | E12: Giá thành sản phẩm dịch vụ trong kỳ
E13: Giá thành | F13: Giá thành đơn vị
A14: 1. Vật liệu
A16: 2. Nhân công | C16: =16128000/12 -> 1344000 | E16: =C16 -> 1344000 | F16: =E16/E9 -> 195.77567
A18: 3. Máy
A20: 4. Chi phí chung
A21: Chi phí khấu hao hệ thống pin năng lượng mặt trời | C21: =12823592+(B21/12) -> 12823592 | D21: =B21-(B21/12)*3 -> 0 | E21: =B21+C21-D21 -> 12823592 | F21: =E21/E9 -> 1867.9668
A23: Cộng | B23: =B21+B22 -> 0 | C23: =C21+C22 -> 12823592 | D23: =D21+D22 -> 0 | E23: =E21+E22 -> 12823592 | F23: =F16+F21 -> 2063.7425
A25: Người ghi sổ | C25: Kế toán trưởng | E25: Giám đốc
A26: (Ký , họ tên) | C26: (Ký , họ tên) | E26: (Ký , họ tên,đóng dấu)
A28: =A1 -> Công ty TNHH Thuận An | E28: Mẫu số : S 25 - SKT/DNN
A29: =A2 -> Ấp Chồng Nô 3, Xã Hòa Tân, Huyện Cầu Kè, Tỉnh Trà Vinh | E29: Ban hành theo quyết định số
E30: 133/2016/TT-BTC ngày 14/06/2016
E31: của bộ tài chính
A32: THẺ TÍNH GIÁ THÀNH SẢN PHẨM
A33: Tháng 10 /2022
B34: ĐỊA ĐIỂM : | C34: HÒA ÂN
B35: Tên sản phẩm , dịch vụ : Điện năng lượng mặt trời
B36: Số lượng sản phẩm , dịch vụ hoàn thành trong kỳ : | E36: 16172
B37: Phương pháp tính giá thành : Giá thành thực tế
A39: Khoản mục chi phí sản xuất kinh doanh | B39: Chi phí SXKD dở dang đầu kỳ | C39: Chi phí SXKD phát sinh trong kỳ | D39: Chi phí SXKD dở dang cuối kỳ | E39: Giá thành sản phẩm dịch vụ trong kỳ
E40: Giá thành | F40: Giá thành đơn vị
A41: 1. Vật liệu
A43: 2. Nhân công | C43: =29952000/12 -> 2496000 | E43: =C43 -> 2496000 | F43: =E43/E36 -> 154.34084
A45: 3. Máy
A47: 4. Chi phí chung
A48: Chi phí khấu hao hệ thống pin năng lượng mặt trời | C48: 21449563 | D48: =B48-(B48/12)*3 -> 0 | E48: =B48+C48-D48 -> 21449563 | F48: =E48/E36 -> 1326.3395
A49: Chi phí khấu hao sửa chửa hệ thống ĐMT | C49: =825978+(B49/12) -> 825978 | E49: =B49+C49-D49 -> 825978 | F49: =E49/E36 -> 51.074573
A51: Cộng | B51: =B48+B49 -> 0 | C51: =C48+C49+C50 -> 22275541 | D51: =D48+D49 -> 0 | E51: =E48+E49+E50 -> 22275541 | F51: =F43+F48+F49 -> 1531.7549
A53: Người ghi sổ | C53: Kế toán trưởng | E53: Giám đốc
...

Sheet T11
A1: ='THONG TIN'!C3 -> Công ty TNHH Thuận An | E1: Mẫu số : S 25 - SKT/DNN
A2: ='THONG TIN'!C4 -> Ấp Chồng Nô 3, Xã Hòa Tân, Huyện Cầu Kè, Tỉnh Trà Vinh | E2: Ban hành theo quyết định số
E3: 133/2016/TT-BTC ngày 14/06/2016
E4: của bộ tài chính
A5: THẺ TÍNH GIÁ THÀNH SẢN PHẨM
A6: Tháng 11/2022
B7: ĐỊA ĐIỂM : | C7: HÒA TÂN
B8: Tên sản phẩm , dịch vụ : Điện năng lượng mặt trời
B9: Số lượng sản phẩm , dịch vụ hoàn thành trong kỳ : | E9: 6752
B10: Phương pháp tính giá thành : Giá thành thực tế
A12: Khoản mục chi phí sản xuất kinh doanh | B12: Chi phí SXKD dở dang đầu kỳ | C12: Chi phí SXKD phát sinh trong kỳ | D12: Chi phí SXKD dở dang cuối kỳ | E12: Giá thành sản phẩm dịch vụ trong kỳ
E13: Giá thành | F13: Giá thành đơn vị
A14: 1. Vật liệu
A16: 2. Nhân công | C16: =16128000/12 -> 1344000 | E16: =C16 -> 1344000 | F16: =E16/E9 -> 199.05213
A18: 3. Máy
A20: 4. Chi phí chung
A21: Chi phí khấu hao hệ thống pin năng lượng mặt trời | C21: =12823592+(B21/12) -> 12823592 | D21: =B21-(B21/12)*3 -> 0 | E21: =B21+C21-D21 -> 12823592 | F21: =E21/E9 -> 1899.2287
A23: Cộng | B23: =B21+B22 -> 0 | C23: =C21+C22 -> 12823592 | D23: =D21+D22 -> 0 | E23: =E21+E22 -> 12823592 | F23: =F16+F21 -> 2098.2808
A25: Người ghi sổ | C25: Kế toán trưởng | E25: Giám đốc
A26: (Ký , họ tên) | C26: (Ký , họ tên) | E26: (Ký , họ tên,đóng dấu)
A28: =A1 -> Công ty TNHH Thuận An | E28: Mẫu số : S 25 - SKT/DNN
A29: =A2 -> Ấp Chồng Nô 3, Xã Hòa Tân, Huyện Cầu Kè, Tỉnh Trà Vinh | E29: Ban hành theo quyết định số
E30: 133/2016/TT-BTC ngày 14/06/2016
E31: của bộ tài chính
A32: THẺ TÍNH GIÁ THÀNH SẢN PHẨM
A33: Tháng 11 /2022
B34: ĐỊA ĐIỂM : | C34: HÒA ÂN
B35: Tên sản phẩm , dịch vụ : Điện năng lượng mặt trời
B36: Số lượng sản phẩm , dịch vụ hoàn thành trong kỳ : | E36: 15508
B37: Phương pháp tính giá thành : Giá thành thực tế
A39: Khoản mục chi phí sản xuất kinh doanh | B39: Chi phí SXKD dở dang đầu kỳ | C39: Chi phí SXKD phát sinh trong kỳ | D39: Chi phí SXKD dở dang cuối kỳ | E39: Giá thành sản phẩm dịch vụ trong kỳ
E40: Giá thành | F40: Giá thành đơn vị
A41: 1. Vật liệu
A43: 2. Nhân công | C43: =29952000/12 -> 2496000 | E43: =C43 -> 2496000 | F43: =E43/E36 -> 160.94919
A45: 3. Máy
A47: 4. Chi phí chung
A48: Chi phí khấu hao hệ thống pin năng lượng mặt trời | C48: 21449563 | D48: =B48-(B48/12)*3 -> 0 | E48: =B48+C48-D48 -> 21449563 | F48: =E48/E36 -> 1383.1289
A49: Chi phí khấu hao sửa chửa hệ thống ĐMT | C49: =825978+(B49/12) -> 825978 | E49: =B49+C49-D49 -> 825978 | F49: =E49/E36 -> 53.261413
A51: Cộng | B51: =B48+B49 -> 0 | C51: =C48+C49+C50 -> 22275541 | D51: =D48+D49 -> 0 | E51: =E48+E49+E50 -> 22275541 | F51: =F43+F48+F49 -> 1597.3395
A53: Người ghi sổ | C53: Kế toán trưởng | E53: Giám đốc
...

Sheet T12
A1: ='THONG TIN'!C3 -> Công ty TNHH Thuận An | E1: Mẫu số : S 25 - SKT/DNN
A2: ='THONG TIN'!C4 -> Ấp Chồng Nô 3, Xã Hòa Tân, Huyện Cầu Kè, Tỉnh Trà Vinh | E2: Ban hành theo quyết định số
E3: 133/2016/TT-BTC ngày 14/06/2016
E4: của bộ tài chính
A5: THẺ TÍNH GIÁ THÀNH SẢN PHẨM
A6: Tháng 12/2022
B7: ĐỊA ĐIỂM : | C7: HÒA TÂN
B8: Tên sản phẩm , dịch vụ : Điện năng lượng mặt trời
B9: Số lượng sản phẩm , dịch vụ hoàn thành trong kỳ : | E9: 5832
B10: Phương pháp tính giá thành : Giá thành thực tế
A12: Khoản mục chi phí sản xuất kinh doanh | B12: Chi phí SXKD dở dang đầu kỳ | C12: Chi phí SXKD phát sinh trong kỳ | D12: Chi phí SXKD dở dang cuối kỳ | E12: Giá thành sản phẩm dịch vụ trong kỳ
E13: Giá thành | F13: Giá thành đơn vị
A14: 1. Vật liệu
A16: 2. Nhân công | C16: =16128000/12 -> 1344000 | E16: =C16 -> 1344000 | F16: =E16/E9 -> 230.45267
A18: 3. Máy
A20: 4. Chi phí chung
A21: Chi phí khấu hao hệ thống pin năng lượng mặt trời | C21: =12823592+(B21/12) -> 12823592 | D21: =B21-(B21/12)*3 -> 0 | E21: =B21+C21-D21 -> 12823592 | F21: =E21/E9 -> 2198.8326
A23: Cộng | B23: =B21+B22 -> 0 | C23: =C21+C22 -> 12823592 | D23: =D21+D22 -> 0 | E23: =E21+E22 -> 12823592 | F23: =F16+F21 -> 2429.2853
A25: Người ghi sổ | C25: Kế toán trưởng | E25: Giám đốc
A26: (Ký , họ tên) | C26: (Ký , họ tên) | E26: (Ký , họ tên,đóng dấu)
A28: =A1 -> Công ty TNHH Thuận An | E28: Mẫu số : S 25 - SKT/DNN
A29: =A2 -> Ấp Chồng Nô 3, Xã Hòa Tân, Huyện Cầu Kè, Tỉnh Trà Vinh | E29: Ban hành theo quyết định số
E30: 133/2016/TT-BTC ngày 14/06/2016
E31: của bộ tài chính
A32: THẺ TÍNH GIÁ THÀNH SẢN PHẨM
A33: Tháng 12 /2022
B34: ĐỊA ĐIỂM : | C34: HÒA ÂN
B35: Tên sản phẩm , dịch vụ : Điện năng lượng mặt trời
B36: Số lượng sản phẩm , dịch vụ hoàn thành trong kỳ : | E36: 17868
B37: Phương pháp tính giá thành : Giá thành thực tế
A39: Khoản mục chi phí sản xuất kinh doanh | B39: Chi phí SXKD dở dang đầu kỳ | C39: Chi phí SXKD phát sinh trong kỳ | D39: Chi phí SXKD dở dang cuối kỳ | E39: Giá thành sản phẩm dịch vụ trong kỳ
E40: Giá thành | F40: Giá thành đơn vị
A41: 1. Vật liệu
A43: 2. Nhân công | C43: =29952000/12 -> 2496000 | E43: =C43 -> 2496000 | F43: =E43/E36 -> 139.69107
A45: 3. Máy
A47: 4. Chi phí chung
A48: Chi phí khấu hao hệ thống pin năng lượng mặt trời | C48: 21449563 | D48: =B48-(B48/12)*3 -> 0 | E48: =B48+C48-D48 -> 21449563 | F48: =E48/E36 -> 1200.4457
A49: Chi phí khấu hao sửa chửa hệ thống ĐMT | C49: =825978+(B49/12) -> 825978 | E49: =B49+C49-D49 -> 825978 | F49: =E49/E36 -> 46.226662
A51: Cộng | B51: =B48+B49 -> 0 | C51: =C48+C49+C50 -> 22275541 | D51: =D48+D49 -> 0 | E51: =E48+E49+E50 -> 22275541 | F51: =F43+F48+F49 -> 1386.3634
A53: Người ghi sổ | C53: Kế toán trưởng | E53: Giám đốc
...
