Workbook

Sheet THONG TIN
A3: Tên doanh nghiệp: | C3: Công ty TNHH Thuận An
A4: Trụ sở chính : | C4: Ấp Chồng Nô 3, Xã Hòa Tân, Huyện Cầu Kè, Tỉnh Trà Vinh
A5: Mã số thuế : | C5: 2 1 0 0 4 0 6 8 1 8

Sheet SL 2024
A1: Tên doanh nghiệp: | C1: ='THONG TIN'!C3 -> Công ty TNHH Thuận An
A2: Trụ sở chính: | C2: ='THONG TIN'!C4 -> Ấp Chồng Nô 3, Xã Hòa Tân, Huyện Cầu Kè, Tỉnh Trà Vinh
A3: BẢNG BÁO CÁO SẢN LƯỢNG SẢN XUẤT VÀ TIÊU THỤ ĐIỆN SOLAR
A4: HÒA TÂN
B5: Công suất dự án : | D5: 62,3 Kw | E5: Năm | F5: 2024
A7: Thời gian | C7: Sản lượng phát | D7: Sản lượng bán | E7: Sản lượng phát bỏ | F7: Sản lượng tiêu dùng | I7: Giá thành
A8: Sản lượng còn lại 12/2023 | C8: 0 | D8: 7770 | G8: Hóa đơn 1
A9: Tháng 1 | C9: =D9+E9+F9 -> 8830 | D9: 8690 | E9: 40 | F9: 100 | G9: Hóa đơn số 5 | I9: ='T1'!F25 -> 1712.4796
A10: Tháng 2 | C10: =D10+E10+F10 -> 8610 | D10: 8470 | E10: 100 | F10: 40 | G10: Hóa đơn số 11 | I10: ='T2'!F25 -> 1756.2364
A11: Tháng 3 | C11: =D11+E11+F11 -> 9630 | D11: 9620 | E11: 10 | F11: 0 | G11: Hóa đơn số 13 | I11: ='T3'!F25 -> 1571.8498
A12: Quý I | C12: =SUM(C8:C11) -> 27070 | D12: =SUM(D9:D11) -> 26780 | E12: =SUM(E9:E11) -> 150 | F12: =SUM(F9:F11) -> 140
A13: Tháng 4 | C13: =D13+E13+F13 -> 9310 | D13: 9300 | E13: 10 | F13: 0 | G13: Hóa đơn Số 14 | I13: ='T4'!F25 -> 1624.1885
A14: Tháng 5 | C14: =D14+E14+F14 -> 7940 | D14: 7770 | E14: 50 | F14: 120 | G14: Hóa đơn Số 19 | I14: ='T5'!F25 -> 1904.4326
A15: Tháng 6 | C15: =D15+E15+F15 -> 7331 | D15: 7230 | E15: 50 | F15: 51 | G15: Hóa đơn Số 22 | I15: ='T6'!F25 -> 2062.6374
A16: Quý II | C16: =SUM(C13:C15) -> 24581 | D16: =SUM(D13:D15) -> 24300 | E16: =SUM(E13:E15) -> 110 | F16: =SUM(F13:F15) -> 171
A17: Tháng 7 | C17: =D17+E17+F17 -> 6700 | D17: 6540 | E17: 100 | F17: 60 | G17: Hóa đơn Số 27 | I17: ='T7'!F25 -> 2256.8948
A18: Tháng 8 | C18: =D18+E18+F18 -> 8569 | D18: 8490 | E18: 0 | F18: 79 | G18: Hóa đơn Số 29 | I18: ='T8'!F25 -> 1764.6394
A19: Tháng 9 | C19: =D19+E19+F19 -> 6429 | D19: 6340 | E19: 10 | F19: 79 | G19: Hóa đơn Số 34 | I19: ='T9'!F25 -> 2352.0291
A20: Quý III | C20: =SUM(C17:C19) -> 21698 | D20: =SUM(D17:D19) -> 21370 | E20: =SUM(E17:E19) -> 110 | F20: =SUM(F17:F19) -> 218
A21: Tháng 10 | C21: =D21+E21+F21 -> 6850 | D21: 6740 | E21: 50 | F21: 60 | G21: Hóa đơn Số 36 | I21: ='T10'!F25 -> 2207.4737
A22: Tháng 11 | C22: =D22+E22+F22 -> 7575 | D22: 7520 | E22: 0 | F22: 55 | G22: Hóa đơn Số 39 | I22: ='T11'!F25 -> 1996.1974
A23: Tháng 12 | C23: =D23+E23+F23 -> 6573 | D23: 6430 | E23: 55 | F23: 88 | G23: Hóa đơn Số 03/2025 | I23: ='T12'!F25 -> 2300.5013
I24: =SUM(I9:I23) -> 23509.56
A25: Quý IV | C25: =SUM(C21:C24) -> 20998 | D25: =SUM(D21:D24) -> 20690 | E25: =SUM(E21:E24) -> 105 | F25: =SUM(F21:F24) -> 203 | I25: =I24/12 -> 1959.13
C26: =C12+C16+C20+C25 -> 94347 | D26: =D12+D16+D20+D25 -> 93140 | E26: =SUM(E12+E16+E20+E25) -> 475 | F26: =SUM(F12+F16+F20+F25) -> 732 | G26: =E26+F26 -> 1207
H27: =D23+E26+F26 -> 7637
A28: Hướng dẫn | C28: Sản lượng phát ghi số liệu từ phần mềm quản lý Solar
C29: Sản lượng bán ghi số liệu từ cơ quan điện lực chốt sổ + SL nội suy đến cuối cuối tháng
C30: Sản lượng phát bỏ ghi nhận điện lực không mua và những ngày cúp điện
C31: Sản lượng tiêu dùng là chênh lệch còn lại
A35: Tên doanh nghiệp: | C35: ='THONG TIN'!C3 -> Công ty TNHH Thuận An
A36: Trụ sở chính: | C36: ='THONG TIN'!C4 -> Ấp Chồng Nô 3, Xã Hòa Tân, Huyện Cầu Kè, Tỉnh Trà Vinh
A37: BẢNG BÁO CÁO SẢN LƯỢNG SẢN XUẤT VÀ TIÊU THỤ ĐIỆN SOLAR
A38: HÒA ÂN
B39: Công suất dự án : | D39: 142,4 Kw | E39: Năm | F39: 2024
A41: Thời gian | C41: Sản lượng phát | D41: Sản lượng bán | E41: Sản lượng phát bỏ | F41: Sản lượng tiêu dùng | I41: Giá thành
A42: Sản lượng còn lại 12/2023 | C42: 0 | D42: 16110 | G42: Hóa đơn Số 02
A43: Tháng 1 | C43: =D43+E43+F43 -> 19444 | D43: 18844 | E43: 100 | F43: 500 | G43: Hóa đơn Số 06 | I43: ='T1'!F55 -> 1437.3518
A44: Tháng 2 | C44: =D44+E44+F44 -> 19838 | D44: 18638 | E44: 700 | F44: 500 | G44: Hóa đơn Số 10 | I44: ='T2'!F55 -> 1408.804
A45: Tháng 3 | C45: =D45+E45+F45 -> 21374 | D45: 20674 | E45: 300 | F45: 400 | G45: Hóa đơn Số 12 | I45: ='T3'!F54 -> 1268.9198
...

Sheet T1
A1: ='THONG TIN'!C3 -> Công ty TNHH Thuận An | E1: Mẫu số : S 25 - SKT/DNN
A2: ='THONG TIN'!C4 -> Ấp Chồng Nô 3, Xã Hòa Tân, Huyện Cầu Kè, Tỉnh Trà Vinh | E2: Ban hành theo quyết định số
E3: 133/2016/TT-BTC ngày 14/06/2016
E4: của bộ tài chính
A5: THẺ TÍNH GIÁ THÀNH SẢN PHẨM
A6: Tháng 1/2024
B7: ĐỊA ĐIỂM : | C7: HÒA TÂN
B8: Tên sản phẩm , dịch vụ : Điện năng lượng mặt trời
B9: Số lượng sản phẩm , dịch vụ hoàn thành trong kỳ : | E9: 8830
B10: Phương pháp tính giá thành : Giá thành thực tế
A12: Khoản mục chi phí sản xuất kinh doanh | B12: Chi phí SXKD dở dang đầu kỳ | C12: Chi phí SXKD phát sinh trong kỳ | D12: Chi phí SXKD dở dang cuối kỳ | E12: Giá thành sản phẩm dịch vụ trong kỳ
E13: Giá thành | F13: Giá thành đơn vị
A14: 1. Vật liệu
A16: 2. Nhân công | C16: 1400000 | E16: =C16 -> 1400000 | F16: =E16/E9 -> 158.5504
A18: 3. Máy
A20: 4. Chi phí chung
A21: Chi phí khấu hao hệ thống pin năng lượng mặt trời | C21: =12823592+(B21/12) -> 12823592 | D21: =B21-(B21/12) -> 0 | E21: =B21+C21-D21 -> 12823592 | F21: =E21/E9 -> 1452.2754
A22: Chi phí khấu hao thay tấm pin sửa chửa hệ thống (2023) | C22: 897603 | D22: =B22-(B22/12) -> 0 | E22: =B22+C22-D22 -> 897603 | F22: =E22/E9 -> 101.65379
A23: Chi phí khấu hao thay tấm pin sửa chửa hệ thống (2024) | C23: 0 | E23: =B23+C23-D23 -> 0 | F23: =E23/E9 -> 0
A25: Cộng | B25: =B21+B24 -> 0 | C25: =C16+C21+C22+C23 -> 15121195 | D25: =D16+D21+D22+D23 -> 0 | E25: =E16+E21+E22+E23 -> 15121195 | F25: =F16+F21+F22+F23 -> 1712.4796
A27: Người ghi sổ | C27: Kế toán trưởng | E27: Giám đốc
A28: (Ký , họ tên) | C28: (Ký , họ tên) | E28: (Ký , họ tên,đóng dấu)
A30: =A1 -> Công ty TNHH Thuận An | E30: Mẫu số : S 25 - SKT/DNN
A31: =A2 -> Ấp Chồng Nô 3, Xã Hòa Tân, Huyện Cầu Kè, Tỉnh Trà Vinh | E31: Ban hành theo quyết định số
E32: 133/2016/TT-BTC ngày 14/06/2016
E33: của bộ tài chính
A34: THẺ TÍNH GIÁ THÀNH SẢN PHẨM
A35: Tháng 1/2024
B36: ĐỊA ĐIỂM : | C36: HÒA ÂN
B37: Tên sản phẩm , dịch vụ : Điện năng lượng mặt trời
B38: Số lượng sản phẩm , dịch vụ hoàn thành trong kỳ : | E38: 19444
B39: Phương pháp tính giá thành : Giá thành thực tế
A41: Khoản mục chi phí sản xuất kinh doanh | B41: Chi phí SXKD dở dang đầu kỳ | C41: Chi phí SXKD phát sinh trong kỳ | D41: Chi phí SXKD dở dang cuối kỳ | E41: Giá thành sản phẩm dịch vụ trong kỳ
E42: Giá thành | F42: Giá thành đơn vị
A43: 1. Vật liệu
A45: 2. Nhân công | C45: 2800000 | E45: =C45 -> 2800000 | F45: =E45/E38 -> 144.00329
A47: 3. Máy
A49: 4. Chi phí chung
A50: Chi phí khấu hao hệ thống pin năng lượng mặt trời | C50: 21449563 | D50: =B50-(B50/12)*3 -> 0 | E50: =B50+C50-D50 -> 21449563 | F50: =E50/E38 -> 1103.1456
A51: Chi phí khấu hao thay tấm pin sửa chửa hệ thống (2023) | C51: 2872328 | E51: =B51+C51-D51 -> 2872328 | F51: =E51/E38 -> 147.7231
...

Sheet T2
A1: ='THONG TIN'!C3 -> Công ty TNHH Thuận An | E1: Mẫu số : S 25 - SKT/DNN
A2: ='THONG TIN'!C4 -> Ấp Chồng Nô 3, Xã Hòa Tân, Huyện Cầu Kè, Tỉnh Trà Vinh | E2: Ban hành theo quyết định số
E3: 133/2016/TT-BTC ngày 14/06/2016
E4: của bộ tài chính
A5: THẺ TÍNH GIÁ THÀNH SẢN PHẨM
A6: Tháng 2/2024
B7: ĐỊA ĐIỂM : | C7: HÒA TÂN
B8: Tên sản phẩm , dịch vụ : Điện năng lượng mặt trời
B9: Số lượng sản phẩm , dịch vụ hoàn thành trong kỳ : | E9: 8610
B10: Phương pháp tính giá thành : Giá thành thực tế
A12: Khoản mục chi phí sản xuất kinh doanh | B12: Chi phí SXKD dở dang đầu kỳ | C12: Chi phí SXKD phát sinh trong kỳ | D12: Chi phí SXKD dở dang cuối kỳ | E12: Giá thành sản phẩm dịch vụ trong kỳ
E13: Giá thành | F13: Giá thành đơn vị
A14: 1. Vật liệu
A16: 2. Nhân công | C16: =1400000 -> 1400000 | E16: =C16 -> 1400000 | F16: =E16/E9 -> 162.60163
A18: 3. Máy
A20: 4. Chi phí chung
A21: Chi phí khấu hao hệ thống pin năng lượng mặt trời | C21: =12823592+(B21/12) -> 12823592 | D21: =B21-(B21/12)*3 -> 0 | E21: =B21+C21-D21 -> 12823592 | F21: =E21/E9 -> 1489.3835
A22: Chi phí khấu hao thay tấm pin sửa chửa hệ thống (2023) | C22: 897603 | D22: =B22-(B22/12)*3 -> 0 | E22: =B22+C22-D22 -> 897603 | F22: =E22/E9 -> 104.25122
A23: Chi phí khấu hao thay tấm pin sửa chửa hệ thống (2024) | C23: 0 | E23: =B23+C23-D23 -> 0 | F23: =E23/E9 -> 0
A25: Cộng | B25: =B21+B24 -> 0 | C25: =C16+C21+C22+C23 -> 15121195 | D25: =D16+D21+D22+D23 -> 0 | E25: =E16+E21+E22+E23 -> 15121195 | F25: =F16+F21+F22+F23 -> 1756.2364
A27: Người ghi sổ | C27: Kế toán trưởng | E27: Giám đốc
A28: (Ký , họ tên) | C28: (Ký , họ tên) | E28: (Ký , họ tên,đóng dấu)
A30: =A1 -> Công ty TNHH Thuận An | E30: Mẫu số : S 25 - SKT/DNN
A31: =A2 -> Ấp Chồng Nô 3, Xã Hòa Tân, Huyện Cầu Kè, Tỉnh Trà Vinh | E31: Ban hành theo quyết định số
E32: 133/2016/TT-BTC ngày 14/06/2016
E33: của bộ tài chính
A34: THẺ TÍNH GIÁ THÀNH SẢN PHẨM
A35: Tháng 2/2024
B36: ĐỊA ĐIỂM : | C36: HÒA ÂN
B37: Tên sản phẩm , dịch vụ : Điện năng lượng mặt trời
B38: Số lượng sản phẩm , dịch vụ hoàn thành trong kỳ : | E38: 19838
B39: Phương pháp tính giá thành : Giá thành thực tế
A41: Khoản mục chi phí sản xuất kinh doanh | B41: Chi phí SXKD dở dang đầu kỳ | C41: Chi phí SXKD phát sinh trong kỳ | D41: Chi phí SXKD dở dang cuối kỳ | E41: Giá thành sản phẩm dịch vụ trong kỳ
E42: Giá thành | F42: Giá thành đơn vị
A43: 1. Vật liệu
A45: 2. Nhân công | C45: 2800000 | E45: =C45 -> 2800000 | F45: =E45/E38 -> 141.14326
A47: 3. Máy
A49: 4. Chi phí chung
A50: Chi phí khấu hao hệ thống pin năng lượng mặt trời | C50: 21449563 | D50: =B50-(B50/12)*3 -> 0 | E50: =B50+C50-D50 -> 21449563 | F50: =E50/E38 -> 1081.2362
A51: Chi phí khấu hao thay tấm pin sửa chửa hệ thống (2023) | C51: 2872328 | E51: =B51+C51-D51 -> 2872328 | F51: =E51/E38 -> 144.78919
...

Sheet T3
A1: ='THONG TIN'!C3 -> Công ty TNHH Thuận An | E1: Mẫu số : S 25 - SKT/DNN
A2: ='THONG TIN'!C4 -> Ấp Chồng Nô 3, Xã Hòa Tân, Huyện Cầu Kè, Tỉnh Trà Vinh | E2: Ban hành theo quyết định số
E3: 133/2016/TT-BTC ngày 14/06/2016
E4: của bộ tài chính
A5: THẺ TÍNH GIÁ THÀNH SẢN PHẨM
A6: Tháng 3/2024
B7: ĐỊA ĐIỂM : | C7: HÒA TÂN
B8: Tên sản phẩm , dịch vụ : Điện năng lượng mặt trời
B9: Số lượng sản phẩm , dịch vụ hoàn thành trong kỳ : | E9: 9620
B10: Phương pháp tính giá thành : Giá thành thực tế
A12: Khoản mục chi phí sản xuất kinh doanh | B12: Chi phí SXKD dở dang đầu kỳ | C12: Chi phí SXKD phát sinh trong kỳ | D12: Chi phí SXKD dở dang cuối kỳ | E12: Giá thành sản phẩm dịch vụ trong kỳ
E13: Giá thành | F13: Giá thành đơn vị
A14: 1. Vật liệu
A16: 2. Nhân công | C16: =1400000 -> 1400000 | E16: =C16 -> 1400000 | F16: =E16/E9 -> 145.53015
A18: 3. Máy
A20: 4. Chi phí chung
A21: Chi phí khấu hao hệ thống pin năng lượng mặt trời | C21: =12823592+(B21/12) -> 12823592 | D21: =B21-(B21/12)*3 -> 0 | E21: =B21+C21-D21 -> 12823592 | F21: =E21/E9 -> 1333.0137
A22: Chi phí khấu hao thay tấm pin sửa chửa hệ thống (2023) | C22: 897603 | D22: =B22-(B22/12)*3 -> 0 | E22: =B22+C22-D22 -> 897603 | F22: =E22/E9 -> 93.305925
A23: Chi phí khấu hao thay tấm pin sửa chửa hệ thống (2024) | C23: 0 | E23: =B23+C23-D23 -> 0 | F23: =E23/E9 -> 0
A25: Cộng | B25: =B21+B24 -> 0 | C25: =C16+C21+C22+C23 -> 15121195 | D25: =D16+D21+D22+D23 -> 0 | E25: =E16+E21+E22+E23 -> 15121195 | F25: =F16+F21+F22+F23 -> 1571.8498
A27: Người ghi sổ | C27: Kế toán trưởng | E27: Giám đốc
A28: (Ký , họ tên) | C28: (Ký , họ tên) | E28: (Ký , họ tên,đóng dấu)
A30: =A1 -> Công ty TNHH Thuận An | E30: Mẫu số : S 25 - SKT/DNN
A31: =A2 -> Ấp Chồng Nô 3, Xã Hòa Tân, Huyện Cầu Kè, Tỉnh Trà Vinh | E31: Ban hành theo quyết định số
E32: 133/2016/TT-BTC ngày 14/06/2016
E33: của bộ tài chính
A34: THẺ TÍNH GIÁ THÀNH SẢN PHẨM
A35: Tháng 3/2024
B36: ĐỊA ĐIỂM : | C36: HÒA ÂN
B37: Tên sản phẩm , dịch vụ : Điện năng lượng mặt trời
B38: Số lượng sản phẩm , dịch vụ hoàn thành trong kỳ : | E38: 21374
B39: Phương pháp tính giá thành : Giá thành thực tế
A41: Khoản mục chi phí sản xuất kinh doanh | B41: Chi phí SXKD dở dang đầu kỳ | C41: Chi phí SXKD phát sinh trong kỳ | D41: Chi phí SXKD dở dang cuối kỳ | E41: Giá thành sản phẩm dịch vụ trong kỳ
E42: Giá thành | F42: Giá thành đơn vị
A43: 1. Vật liệu
A45: 2. Nhân công | C45: 2800000 | E45: =C45 -> 2800000 | F45: =E45/E38 -> 131.00028
A47: 3. Máy
A49: 4. Chi phí chung
A50: Chi phí khấu hao hệ thống pin năng lượng mặt trời | C50: 21449563 | D50: =B50-(B50/12)*3 -> 0 | E50: =B50+C50-D50 -> 21449563 | F50: =E50/E38 -> 1003.5353
A51: Chi phí khấu hao thay tấm pin sửa chửa hệ thống (2023) | C51: 2872328 | E51: =B51+C51-D51 -> 2872328 | F51: =E51/E38 -> 134.38421
...

Sheet T4
A1: ='THONG TIN'!C3 -> Công ty TNHH Thuận An | E1: Mẫu số : S 25 - SKT/DNN
A2: ='THONG TIN'!C4 -> Ấp Chồng Nô 3, Xã Hòa Tân, Huyện Cầu Kè, Tỉnh Trà Vinh | E2: Ban hành theo quyết định số
E3: 133/2016/TT-BTC ngày 14/06/2016
E4: của bộ tài chính
A5: THẺ TÍNH GIÁ THÀNH SẢN PHẨM
A6: Tháng 4/2024
B7: ĐỊA ĐIỂM : | C7: HÒA TÂN
B8: Tên sản phẩm , dịch vụ : Điện năng lượng mặt trời
B9: Số lượng sản phẩm , dịch vụ hoàn thành trong kỳ : | E9: 9310
B10: Phương pháp tính giá thành : Giá thành thực tế
A12: Khoản mục chi phí sản xuất kinh doanh | B12: Chi phí SXKD dở dang đầu kỳ | C12: Chi phí SXKD phát sinh trong kỳ | D12: Chi phí SXKD dở dang cuối kỳ | E12: Giá thành sản phẩm dịch vụ trong kỳ
E13: Giá thành | F13: Giá thành đơn vị
A14: 1. Vật liệu
A16: 2. Nhân công | C16: =1400000 -> 1400000 | E16: =C16 -> 1400000 | F16: =E16/E9 -> 150.37594
A18: 3. Máy
A20: 4. Chi phí chung
A21: Chi phí khấu hao hệ thống pin năng lượng mặt trời | C21: =12823592+(B21/12) -> 12823592 | D21: =B21-(B21/12)*3 -> 0 | E21: =B21+C21-D21 -> 12823592 | F21: =E21/E9 -> 1377.3998
A22: Chi phí khấu hao thay tấm pin sửa chửa hệ thống (2023) | C22: 897603 | D22: =B22-(B22/12)*3 -> 0 | E22: =B22+C22-D22 -> 897603 | F22: =E22/E9 -> 96.412782
A23: Chi phí khấu hao thay tấm pin sửa chửa hệ thống (2024) | C23: 0 | E23: =B23+C23-D23 -> 0 | F23: =E23/E9 -> 0
A25: Cộng | B25: =B21+B24 -> 0 | C25: =C16+C21+C22+C23 -> 15121195 | D25: =D16+D21+D22+D23 -> 0 | E25: =E16+E21+E22+E23 -> 15121195 | F25: =F16+F21+F22+F23 -> 1624.1885
A27: Người ghi sổ | C27: Kế toán trưởng | E27: Giám đốc
A28: (Ký , họ tên) | C28: (Ký , họ tên) | E28: (Ký , họ tên,đóng dấu)
A30: =A1 -> Công ty TNHH Thuận An | E30: Mẫu số : S 25 - SKT/DNN
A31: =A2 -> Ấp Chồng Nô 3, Xã Hòa Tân, Huyện Cầu Kè, Tỉnh Trà Vinh | E31: Ban hành theo quyết định số
E32: 133/2016/TT-BTC ngày 14/06/2016
E33: của bộ tài chính
A34: THẺ TÍNH GIÁ THÀNH SẢN PHẨM
A35: Tháng 4/2024
B36: ĐỊA ĐIỂM : | C36: HÒA ÂN
B37: Tên sản phẩm , dịch vụ : Điện năng lượng mặt trời
B38: Số lượng sản phẩm , dịch vụ hoàn thành trong kỳ : | E38: 20807
B39: Phương pháp tính giá thành : Giá thành thực tế
A41: Khoản mục chi phí sản xuất kinh doanh | B41: Chi phí SXKD dở dang đầu kỳ | C41: Chi phí SXKD phát sinh trong kỳ | D41: Chi phí SXKD dở dang cuối kỳ | E41: Giá thành sản phẩm dịch vụ trong kỳ
E42: Giá thành | F42: Giá thành đơn vị
A43: 1. Vật liệu
A45: 2. Nhân công | C45: 2800000 | E45: =C45 -> 2800000 | F45: =E45/E38 -> 134.5701
A47: 3. Máy
A49: 4. Chi phí chung
A50: Chi phí khấu hao hệ thống pin năng lượng mặt trời | C50: 21449563 | D50: =B50-(B50/12)*3 -> 0 | E50: =B50+C50-D50 -> 21449563 | F50: =E50/E38 -> 1030.8821
A51: Chi phí khấu hao thay tấm pin sửa chửa hệ thống | C51: 2872328 | E51: =B51+C51-D51 -> 2872328 | F51: =E51/E38 -> 138.04623
...

Sheet T5
A1: ='THONG TIN'!C3 -> Công ty TNHH Thuận An | E1: Mẫu số : S 25 - SKT/DNN
A2: ='THONG TIN'!C4 -> Ấp Chồng Nô 3, Xã Hòa Tân, Huyện Cầu Kè, Tỉnh Trà Vinh | E2: Ban hành theo quyết định số
E3: 133/2016/TT-BTC ngày 14/06/2016
E4: của bộ tài chính
A5: THẺ TÍNH GIÁ THÀNH SẢN PHẨM
A6: Tháng 5/2024
B7: ĐỊA ĐIỂM : | C7: HÒA TÂN
B8: Tên sản phẩm , dịch vụ : Điện năng lượng mặt trời
B9: Số lượng sản phẩm , dịch vụ hoàn thành trong kỳ : | E9: 7940
B10: Phương pháp tính giá thành : Giá thành thực tế
A12: Khoản mục chi phí sản xuất kinh doanh | B12: Chi phí SXKD dở dang đầu kỳ | C12: Chi phí SXKD phát sinh trong kỳ | D12: Chi phí SXKD dở dang cuối kỳ | E12: Giá thành sản phẩm dịch vụ trong kỳ
E13: Giá thành | F13: Giá thành đơn vị
A14: 1. Vật liệu
A16: 2. Nhân công | C16: =1400000 -> 1400000 | E16: =C16 -> 1400000 | F16: =E16/E9 -> 176.32242
A18: 3. Máy
A20: 4. Chi phí chung
A21: Chi phí khấu hao hệ thống pin năng lượng mặt trời | C21: =12823592+(B21/12) -> 12823592 | D21: =B21-(B21/12)*3 -> 0 | E21: =B21+C21-D21 -> 12823592 | F21: =E21/E9 -> 1615.062
A22: Chi phí khấu hao thay tấm pin sửa chửa hệ thống (2023) | C22: 897603 | D22: =B22-(B22/12)*3 -> 0 | E22: =B22+C22-D22 -> 897603 | F22: =E22/E9 -> 113.04824
A23: Chi phí khấu hao thay tấm pin sửa chửa hệ thống (2024) | C23: 0 | E23: =B23+C23-D23 -> 0 | F23: =E23/E9 -> 0
A25: Cộng | B25: =B21+B24 -> 0 | C25: =C16+C21+C22+C23 -> 15121195 | D25: =D16+D21+D22+D23 -> 0 | E25: =E16+E21+E22+E23 -> 15121195 | F25: =F16+F21+F22+F23 -> 1904.4326
A27: Người ghi sổ | C27: Kế toán trưởng | E27: Giám đốc
A28: (Ký , họ tên) | C28: (Ký , họ tên) | E28: (Ký , họ tên,đóng dấu)
A30: =A1 -> Công ty TNHH Thuận An | E30: Mẫu số : S 25 - SKT/DNN
A31: =A2 -> Ấp Chồng Nô 3, Xã Hòa Tân, Huyện Cầu Kè, Tỉnh Trà Vinh | E31: Ban hành theo quyết định số
E32: 133/2016/TT-BTC ngày 14/06/2016
E33: của bộ tài chính
A34: THẺ TÍNH GIÁ THÀNH SẢN PHẨM
A35: Tháng 5 /2024
B36: ĐỊA ĐIỂM : | C36: HÒA ÂN
B37: Tên sản phẩm , dịch vụ : Điện năng lượng mặt trời
B38: Số lượng sản phẩm , dịch vụ hoàn thành trong kỳ : | E38: 17625
B39: Phương pháp tính giá thành : Giá thành thực tế
A41: Khoản mục chi phí sản xuất kinh doanh | B41: Chi phí SXKD dở dang đầu kỳ | C41: Chi phí SXKD phát sinh trong kỳ | D41: Chi phí SXKD dở dang cuối kỳ | E41: Giá thành sản phẩm dịch vụ trong kỳ
E42: Giá thành | F42: Giá thành đơn vị
A43: 1. Vật liệu
A45: 2. Nhân công | C45: 2800000 | E45: =C45 -> 2800000 | F45: =E45/E38 -> 158.86525
A47: 3. Máy
A49: 4. Chi phí chung
A50: Chi phí khấu hao hệ thống pin năng lượng mặt trời | C50: 21449563 | D50: =B50-(B50/12)*3 -> 0 | E50: =B50+C50-D50 -> 21449563 | F50: =E50/E38 -> 1216.9965
A51: Chi phí khấu hao thay tấm pin sửa chửa hệ thống | C51: 2872328 | E51: =B51+C51-D51 -> 2872328 | F51: =E51/E38 -> 162.96896
...

Sheet T6
A1: ='THONG TIN'!C3 -> Công ty TNHH Thuận An | E1: Mẫu số : S 25 - SKT/DNN
A2: ='THONG TIN'!C4 -> Ấp Chồng Nô 3, Xã Hòa Tân, Huyện Cầu Kè, Tỉnh Trà Vinh | E2: Ban hành theo quyết định số
E3: 133/2016/TT-BTC ngày 14/06/2016
E4: của bộ tài chính
A5: THẺ TÍNH GIÁ THÀNH SẢN PHẨM
A6: Tháng 6/2024
B7: ĐỊA ĐIỂM : | C7: HÒA TÂN
B8: Tên sản phẩm , dịch vụ : Điện năng lượng mặt trời
B9: Số lượng sản phẩm , dịch vụ hoàn thành trong kỳ : | E9: 7331
B10: Phương pháp tính giá thành : Giá thành thực tế
A12: Khoản mục chi phí sản xuất kinh doanh | B12: Chi phí SXKD dở dang đầu kỳ | C12: Chi phí SXKD phát sinh trong kỳ | D12: Chi phí SXKD dở dang cuối kỳ | E12: Giá thành sản phẩm dịch vụ trong kỳ
E13: Giá thành | F13: Giá thành đơn vị
A14: 1. Vật liệu
A16: 2. Nhân công | C16: =1400000 -> 1400000 | E16: =C16 -> 1400000 | F16: =E16/E9 -> 190.96985
A18: 3. Máy
A20: 4. Chi phí chung
A21: Chi phí khấu hao hệ thống pin năng lượng mặt trời | C21: =12823592+(B21/12) -> 12823592 | D21: =B21-(B21/12)*3 -> 0 | E21: =B21+C21-D21 -> 12823592 | F21: =E21/E9 -> 1749.2282
A22: Chi phí khấu hao thay tấm pin sửa chửa hệ thống (2023) | C22: 897603 | D22: =B22-(B22/12)*3 -> 0 | E22: =B22+C22-D22 -> 897603 | F22: =E22/E9 -> 122.43937
A23: Chi phí khấu hao thay tấm pin sửa chửa hệ thống (2024) | C23: 0 | E23: =B23+C23-D23 -> 0 | F23: =E23/E9 -> 0
A25: Cộng | B25: =B21+B24 -> 0 | C25: =C16+C21+C22+C23 -> 15121195 | D25: =D16+D21+D22+D23 -> 0 | E25: =E16+E21+E22+E23 -> 15121195 | F25: =F16+F21+F22+F23 -> 2062.6374
A27: Người ghi sổ | C27: Kế toán trưởng | E27: Giám đốc
A28: (Ký , họ tên) | C28: (Ký , họ tên) | E28: (Ký , họ tên,đóng dấu)
A30: =A1 -> Công ty TNHH Thuận An | E30: Mẫu số : S 25 - SKT/DNN
A31: =A2 -> Ấp Chồng Nô 3, Xã Hòa Tân, Huyện Cầu Kè, Tỉnh Trà Vinh | E31: Ban hành theo quyết định số
E32: 133/2016/TT-BTC ngày 14/06/2016
E33: của bộ tài chính
A34: THẺ TÍNH GIÁ THÀNH SẢN PHẨM
A35: Tháng 6 /2024
B36: ĐỊA ĐIỂM : | C36: HÒA ÂN
B37: Tên sản phẩm , dịch vụ : Điện năng lượng mặt trời
B38: Số lượng sản phẩm , dịch vụ hoàn thành trong kỳ : | E38: 15999
B39: Phương pháp tính giá thành : Giá thành thực tế
A41: Khoản mục chi phí sản xuất kinh doanh | B41: Chi phí SXKD dở dang đầu kỳ | C41: Chi phí SXKD phát sinh trong kỳ | D41: Chi phí SXKD dở dang cuối kỳ | E41: Giá thành sản phẩm dịch vụ trong kỳ
E42: Giá thành | F42: Giá thành đơn vị
A43: 1. Vật liệu
A45: 2. Nhân công | C45: 2800000 | E45: =C45 -> 2800000 | F45: =E45/E38 -> 175.01094
A47: 3. Máy
A49: 4. Chi phí chung
A50: Chi phí khấu hao hệ thống pin năng lượng mặt trời | C50: 21449563 | D50: =B50-(B50/12)*3 -> 0 | E50: =B50+C50-D50 -> 21449563 | F50: =E50/E38 -> 1340.6815
A51: Chi phí khấu hao thay tấm pin sửa chửa hệ thống | C51: 2872328 | E51: =B51+C51-D51 -> 2872328 | F51: =E51/E38 -> 179.53172
...

Sheet T7
A1: ='THONG TIN'!C3 -> Công ty TNHH Thuận An | E1: Mẫu số : S 25 - SKT/DNN
A2: ='THONG TIN'!C4 -> Ấp Chồng Nô 3, Xã Hòa Tân, Huyện Cầu Kè, Tỉnh Trà Vinh | E2: Ban hành theo quyết định số
E3: 133/2016/TT-BTC ngày 14/06/2016
E4: của bộ tài chính
A5: THẺ TÍNH GIÁ THÀNH SẢN PHẨM
A6: Tháng 7/2024
B7: ĐỊA ĐIỂM : | C7: HÒA TÂN
B8: Tên sản phẩm , dịch vụ : Điện năng lượng mặt trời
B9: Số lượng sản phẩm , dịch vụ hoàn thành trong kỳ : | E9: 6700
B10: Phương pháp tính giá thành : Giá thành thực tế
A12: Khoản mục chi phí sản xuất kinh doanh | B12: Chi phí SXKD dở dang đầu kỳ | C12: Chi phí SXKD phát sinh trong kỳ | D12: Chi phí SXKD dở dang cuối kỳ | E12: Giá thành sản phẩm dịch vụ trong kỳ
E13: Giá thành | F13: Giá thành đơn vị
A14: 1. Vật liệu
A16: 2. Nhân công | C16: =1400000 -> 1400000 | E16: =C16 -> 1400000 | F16: =E16/E9 -> 208.95522
A18: 3. Máy
A20: 4. Chi phí chung
A21: Chi phí khấu hao hệ thống pin năng lượng mặt trời | C21: =12823592+(B21/12) -> 12823592 | D21: =B21-(B21/12)*3 -> 0 | E21: =B21+C21-D21 -> 12823592 | F21: =E21/E9 -> 1913.969
A22: Chi phí khấu hao thay tấm pin sửa chửa hệ thống (2023) | C22: 897603 | D22: =B22-(B22/12)*3 -> 0 | E22: =B22+C22-D22 -> 897603 | F22: =E22/E9 -> 133.9706
A23: Chi phí khấu hao thay tấm pin sửa chửa hệ thống (2024) | C23: 0 | E23: =B23+C23-D23 -> 0 | F23: =E23/E9 -> 0
A25: Cộng | B25: =B21+B24 -> 0 | C25: =C16+C21+C22+C23 -> 15121195 | D25: =D16+D21+D22+D23 -> 0 | E25: =E16+E21+E22+E23 -> 15121195 | F25: =F16+F21+F22+F23 -> 2256.8948
A27: Người ghi sổ | C27: Kế toán trưởng | E27: Giám đốc
A28: (Ký , họ tên) | C28: (Ký , họ tên) | E28: (Ký , họ tên,đóng dấu)
A30: =A1 -> Công ty TNHH Thuận An | E30: Mẫu số : S 25 - SKT/DNN
A31: =A2 -> Ấp Chồng Nô 3, Xã Hòa Tân, Huyện Cầu Kè, Tỉnh Trà Vinh | E31: Ban hành theo quyết định số
E32: 133/2016/TT-BTC ngày 14/06/2016
E33: của bộ tài chính
A34: THẺ TÍNH GIÁ THÀNH SẢN PHẨM
A35: Tháng 7 /2024
B36: ĐỊA ĐIỂM : | C36: HÒA ÂN
B37: Tên sản phẩm , dịch vụ : Điện năng lượng mặt trời
B38: Số lượng sản phẩm , dịch vụ hoàn thành trong kỳ : | E38: 15585
B39: Phương pháp tính giá thành : Giá thành thực tế
A41: Khoản mục chi phí sản xuất kinh doanh | B41: Chi phí SXKD dở dang đầu kỳ | C41: Chi phí SXKD phát sinh trong kỳ | D41: Chi phí SXKD dở dang cuối kỳ | E41: Giá thành sản phẩm dịch vụ trong kỳ
E42: Giá thành | F42: Giá thành đơn vị
A43: 1. Vật liệu
A45: 2. Nhân công | C45: 2800000 | E45: =C45 -> 2800000 | F45: =E45/E38 -> 179.65993
A47: 3. Máy
A49: 4. Chi phí chung
A50: Chi phí khấu hao hệ thống pin năng lượng mặt trời | C50: 21449563 | D50: =B50-(B50/12)*3 -> 0 | E50: =B50+C50-D50 -> 21449563 | F50: =E50/E38 -> 1376.2953
A51: Chi phí khấu hao thay tấm pin sửa chửa hệ thống | C51: 2872328 | E51: =B51+C51-D51 -> 2872328 | F51: =E51/E38 -> 184.3008
...

Sheet T8
A1: ='THONG TIN'!C3 -> Công ty TNHH Thuận An | E1: Mẫu số : S 25 - SKT/DNN
A2: ='THONG TIN'!C4 -> Ấp Chồng Nô 3, Xã Hòa Tân, Huyện Cầu Kè, Tỉnh Trà Vinh | E2: Ban hành theo quyết định số
E3: 133/2016/TT-BTC ngày 14/06/2016
E4: của bộ tài chính
A5: THẺ TÍNH GIÁ THÀNH SẢN PHẨM
A6: Tháng 8/2024
B7: ĐỊA ĐIỂM : | C7: HÒA TÂN
B8: Tên sản phẩm , dịch vụ : Điện năng lượng mặt trời
B9: Số lượng sản phẩm , dịch vụ hoàn thành trong kỳ : | E9: 8569
B10: Phương pháp tính giá thành : Giá thành thực tế
A12: Khoản mục chi phí sản xuất kinh doanh | B12: Chi phí SXKD dở dang đầu kỳ | C12: Chi phí SXKD phát sinh trong kỳ | D12: Chi phí SXKD dở dang cuối kỳ | E12: Giá thành sản phẩm dịch vụ trong kỳ
E13: Giá thành | F13: Giá thành đơn vị
A14: 1. Vật liệu
A16: 2. Nhân công | C16: =1400000 -> 1400000 | E16: =C16 -> 1400000 | F16: =E16/E9 -> 163.37962
A18: 3. Máy
A20: 4. Chi phí chung
A21: Chi phí khấu hao hệ thống pin năng lượng mặt trời | C21: =12823592+(B21/12) -> 12823592 | D21: =B21-(B21/12)*3 -> 0 | E21: =B21+C21-D21 -> 12823592 | F21: =E21/E9 -> 1496.5097
A22: Chi phí khấu hao thay tấm pin sửa chửa hệ thống (2023) | C22: 897603 | D22: =B22-(B22/12)*3 -> 0 | E22: =B22+C22-D22 -> 897603 | F22: =E22/E9 -> 104.75003
A23: Chi phí khấu hao thay tấm pin sửa chửa hệ thống (2024) | C23: 0 | E23: =B23+C23-D23 -> 0 | F23: =E23/E9 -> 0
A25: Cộng | B25: =B21+B24 -> 0 | C25: =C16+C21+C22+C23 -> 15121195 | D25: =D16+D21+D22+D23 -> 0 | E25: =E16+E21+E22+E23 -> 15121195 | F25: =F16+F21+F22+F23 -> 1764.6394
A27: Người ghi sổ | C27: Kế toán trưởng | E27: Giám đốc
A28: (Ký , họ tên) | C28: (Ký , họ tên) | E28: (Ký , họ tên,đóng dấu)
A30: =A1 -> Công ty TNHH Thuận An | E30: Mẫu số : S 25 - SKT/DNN
A31: =A2 -> Ấp Chồng Nô 3, Xã Hòa Tân, Huyện Cầu Kè, Tỉnh Trà Vinh | E31: Ban hành theo quyết định số
E32: 133/2016/TT-BTC ngày 14/06/2016
E33: của bộ tài chính
A34: THẺ TÍNH GIÁ THÀNH SẢN PHẨM
A35: Tháng 8 /2024
B36: ĐỊA ĐIỂM : | C36: HÒA ÂN
B37: Tên sản phẩm , dịch vụ : Điện năng lượng mặt trời
B38: Số lượng sản phẩm , dịch vụ hoàn thành trong kỳ : | E38: 16920
B39: Phương pháp tính giá thành : Giá thành thực tế
A41: Khoản mục chi phí sản xuất kinh doanh | B41: Chi phí SXKD dở dang đầu kỳ | C41: Chi phí SXKD phát sinh trong kỳ | D41: Chi phí SXKD dở dang cuối kỳ | E41: Giá thành sản phẩm dịch vụ trong kỳ
E42: Giá thành | F42: Giá thành đơn vị
A43: 1. Vật liệu
A45: 2. Nhân công | C45: 2800000 | E45: =C45 -> 2800000 | F45: =E45/E38 -> 165.48463
A47: 3. Máy
A49: 4. Chi phí chung
A50: Chi phí khấu hao hệ thống pin năng lượng mặt trời | C50: 21449563 | D50: =B50-(B50/12)*3 -> 0 | E50: =B50+C50-D50 -> 21449563 | F50: =E50/E38 -> 1267.7047
A51: Chi phí khấu hao thay tấm pin sửa chửa hệ thống | C51: 2872328 | E51: =B51+C51-D51 -> 2872328 | F51: =E51/E38 -> 169.75934
...

Sheet T9
A1: ='THONG TIN'!C3 -> Công ty TNHH Thuận An | E1: Mẫu số : S 25 - SKT/DNN
A2: ='THONG TIN'!C4 -> Ấp Chồng Nô 3, Xã Hòa Tân, Huyện Cầu Kè, Tỉnh Trà Vinh | E2: Ban hành theo quyết định số
E3: 133/2016/TT-BTC ngày 14/06/2016
E4: của bộ tài chính
A5: THẺ TÍNH GIÁ THÀNH SẢN PHẨM
A6: Tháng 9/2024
B7: ĐỊA ĐIỂM : | C7: HÒA TÂN
B8: Tên sản phẩm , dịch vụ : Điện năng lượng mặt trời
B9: Số lượng sản phẩm , dịch vụ hoàn thành trong kỳ : | E9: 6429
B10: Phương pháp tính giá thành : Giá thành thực tế
A12: Khoản mục chi phí sản xuất kinh doanh | B12: Chi phí SXKD dở dang đầu kỳ | C12: Chi phí SXKD phát sinh trong kỳ | D12: Chi phí SXKD dở dang cuối kỳ | E12: Giá thành sản phẩm dịch vụ trong kỳ
E13: Giá thành | F13: Giá thành đơn vị
A14: 1. Vật liệu
A16: 2. Nhân công | C16: =1400000 -> 1400000 | E16: =C16 -> 1400000 | F16: =E16/E9 -> 217.76326
A18: 3. Máy
A20: 4. Chi phí chung
A21: Chi phí khấu hao hệ thống pin năng lượng mặt trời | C21: =12823592+(B21/12) -> 12823592 | D21: =B21-(B21/12)*3 -> 0 | E21: =B21+C21-D21 -> 12823592 | F21: =E21/E9 -> 1994.648
A22: Chi phí khấu hao thay tấm pin sửa chửa hệ thống (2023) | C22: 897603 | D22: =B22-(B22/12)*3 -> 0 | E22: =B22+C22-D22 -> 897603 | F22: =E22/E9 -> 139.61783
A23: Chi phí khấu hao thay tấm pin sửa chửa hệ thống (2024) | C23: 0 | E23: =B23+C23-D23 -> 0 | F23: =E23/E9 -> 0
A25: Cộng | B25: =B21+B24 -> 0 | C25: =C16+C21+C22+C23 -> 15121195 | D25: =D16+D21+D22+D23 -> 0 | E25: =E16+E21+E22+E23 -> 15121195 | F25: =F16+F21+F22+F23 -> 2352.0291
A27: Người ghi sổ | C27: Kế toán trưởng | E27: Giám đốc
A28: (Ký , họ tên) | C28: (Ký , họ tên) | E28: (Ký , họ tên,đóng dấu)
A30: =A1 -> Công ty TNHH Thuận An | E30: Mẫu số : S 25 - SKT/DNN
A31: =A2 -> Ấp Chồng Nô 3, Xã Hòa Tân, Huyện Cầu Kè, Tỉnh Trà Vinh | E31: Ban hành theo quyết định số
E32: 133/2016/TT-BTC ngày 14/06/2016
E33: của bộ tài chính
A34: THẺ TÍNH GIÁ THÀNH SẢN PHẨM
A35: Tháng 9 /2024
B36: ĐỊA ĐIỂM : | C36: HÒA ÂN
B37: Tên sản phẩm , dịch vụ : Điện năng lượng mặt trời
B38: Số lượng sản phẩm , dịch vụ hoàn thành trong kỳ : | E38: 16057
B39: Phương pháp tính giá thành : Giá thành thực tế
A41: Khoản mục chi phí sản xuất kinh doanh | B41: Chi phí SXKD dở dang đầu kỳ | C41: Chi phí SXKD phát sinh trong kỳ | D41: Chi phí SXKD dở dang cuối kỳ | E41: Giá thành sản phẩm dịch vụ trong kỳ
E42: Giá thành | F42: Giá thành đơn vị
A43: 1. Vật liệu
A45: 2. Nhân công | C45: 2800000 | E45: =C45 -> 2800000 | F45: =E45/E38 -> 174.37878
A47: 3. Máy
A49: 4. Chi phí chung
A50: Chi phí khấu hao hệ thống pin năng lượng mặt trời | C50: 21449563 | D50: =B50-(B50/12)*3 -> 0 | E50: =B50+C50-D50 -> 21449563 | F50: =E50/E38 -> 1335.8388
A51: Chi phí khấu hao thay tấm pin sửa chửa hệ thống | C51: 2872328 | E51: =B51+C51-D51 -> 2872328 | F51: =E51/E38 -> 178.88323
...

Sheet T10
A1: ='THONG TIN'!C3 -> Công ty TNHH Thuận An | E1: Mẫu số : S 25 - SKT/DNN
A2: ='THONG TIN'!C4 -> Ấp Chồng Nô 3, Xã Hòa Tân, Huyện Cầu Kè, Tỉnh Trà Vinh | E2: Ban hành theo quyết định số
E3: 133/2016/TT-BTC ngày 14/06/2016
E4: của bộ tài chính
A5: THẺ TÍNH GIÁ THÀNH SẢN PHẨM
A6: Tháng 10/2024
B7: ĐỊA ĐIỂM : | C7: HÒA TÂN
B8: Tên sản phẩm , dịch vụ : Điện năng lượng mặt trời
B9: Số lượng sản phẩm , dịch vụ hoàn thành trong kỳ : | E9: 6850
B10: Phương pháp tính giá thành : Giá thành thực tế
A12: Khoản mục chi phí sản xuất kinh doanh | B12: Chi phí SXKD dở dang đầu kỳ | C12: Chi phí SXKD phát sinh trong kỳ | D12: Chi phí SXKD dở dang cuối kỳ | E12: Giá thành sản phẩm dịch vụ trong kỳ
E13: Giá thành | F13: Giá thành đơn vị
A14: 1. Vật liệu
A16: 2. Nhân công | C16: =1400000 -> 1400000 | E16: =C16 -> 1400000 | F16: =E16/E9 -> 204.37956
A18: 3. Máy
A20: 4. Chi phí chung
A21: Chi phí khấu hao hệ thống pin năng lượng mặt trời | C21: =12823592+(B21/12) -> 12823592 | D21: =B21-(B21/12)*3 -> 0 | E21: =B21+C21-D21 -> 12823592 | F21: =E21/E9 -> 1872.0572
A22: Chi phí khấu hao thay tấm pin sửa chửa hệ thống (2023) | C22: 897603 | D22: =B22-(B22/12)*3 -> 0 | E22: =B22+C22-D22 -> 897603 | F22: =E22/E9 -> 131.03693
A23: Chi phí khấu hao thay tấm pin sửa chửa hệ thống (2024) | C23: 0 | E23: =B23+C23-D23 -> 0 | F23: =E23/E9 -> 0
A25: Cộng | B25: =B21+B24 -> 0 | C25: =C16+C21+C22+C23 -> 15121195 | D25: =D16+D21+D22+D23 -> 0 | E25: =E16+E21+E22+E23 -> 15121195 | F25: =F16+F21+F22+F23 -> 2207.4737
A27: Người ghi sổ | C27: Kế toán trưởng | E27: Giám đốc
A28: (Ký , họ tên) | C28: (Ký , họ tên) | E28: (Ký , họ tên,đóng dấu)
A30: =A1 -> Công ty TNHH Thuận An | E30: Mẫu số : S 25 - SKT/DNN
A31: =A2 -> Ấp Chồng Nô 3, Xã Hòa Tân, Huyện Cầu Kè, Tỉnh Trà Vinh | E31: Ban hành theo quyết định số
E32: 133/2016/TT-BTC ngày 14/06/2016
E33: của bộ tài chính
A34: THẺ TÍNH GIÁ THÀNH SẢN PHẨM
A35: Tháng 10 /2024
B36: ĐỊA ĐIỂM : | C36: HÒA ÂN
B37: Tên sản phẩm , dịch vụ : Điện năng lượng mặt trời
B38: Số lượng sản phẩm , dịch vụ hoàn thành trong kỳ : | E38: 16591
B39: Phương pháp tính giá thành : Giá thành thực tế
A41: Khoản mục chi phí sản xuất kinh doanh | B41: Chi phí SXKD dở dang đầu kỳ | C41: Chi phí SXKD phát sinh trong kỳ | D41: Chi phí SXKD dở dang cuối kỳ | E41: Giá thành sản phẩm dịch vụ trong kỳ
E42: Giá thành | F42: Giá thành đơn vị
A43: 1. Vật liệu
A45: 2. Nhân công | C45: 2800000 | E45: =C45 -> 2800000 | F45: =E45/E38 -> 168.7662
A47: 3. Máy
A49: 4. Chi phí chung
A50: Chi phí khấu hao hệ thống pin năng lượng mặt trời | C50: 21449563 | D50: =B50-(B50/12)*3 -> 0 | E50: =B50+C50-D50 -> 21449563 | F50: =E50/E38 -> 1292.8433
A51: Chi phí khấu hao thay tấm pin sửa chửa hệ thống | C51: 2872328 | E51: =B51+C51-D51 -> 2872328 | F51: =E51/E38 -> 173.12567
...

Sheet T11
A1: ='THONG TIN'!C3 -> Công ty TNHH Thuận An | E1: Mẫu số : S 25 - SKT/DNN
A2: ='THONG TIN'!C4 -> Ấp Chồng Nô 3, Xã Hòa Tân, Huyện Cầu Kè, Tỉnh Trà Vinh | E2: Ban hành theo quyết định số
E3: 133/2016/TT-BTC ngày 14/06/2016
E4: của bộ tài chính
A5: THẺ TÍNH GIÁ THÀNH SẢN PHẨM
A6: Tháng 11/2024
B7: ĐỊA ĐIỂM : | C7: HÒA TÂN
B8: Tên sản phẩm , dịch vụ : Điện năng lượng mặt trời
B9: Số lượng sản phẩm , dịch vụ hoàn thành trong kỳ : | E9: 7575
B10: Phương pháp tính giá thành : Giá thành thực tế
A12: Khoản mục chi phí sản xuất kinh doanh | B12: Chi phí SXKD dở dang đầu kỳ | C12: Chi phí SXKD phát sinh trong kỳ | D12: Chi phí SXKD dở dang cuối kỳ | E12: Giá thành sản phẩm dịch vụ trong kỳ
E13: Giá thành | F13: Giá thành đơn vị
A14: 1. Vật liệu
A16: 2. Nhân công | C16: =1400000 -> 1400000 | E16: =C16 -> 1400000 | F16: =E16/E9 -> 184.81848
A18: 3. Máy
A20: 4. Chi phí chung
A21: Chi phí khấu hao hệ thống pin năng lượng mặt trời | C21: =12823592+(B21/12) -> 12823592 | D21: =B21-(B21/12)*3 -> 0 | E21: =B21+C21-D21 -> 12823592 | F21: =E21/E9 -> 1692.8834
A22: Chi phí khấu hao thay tấm pin sửa chửa hệ thống (2023) | C22: 897603 | D22: =B22-(B22/12)*3 -> 0 | E22: =B22+C22-D22 -> 897603 | F22: =E22/E9 -> 118.49545
A23: Chi phí khấu hao thay tấm pin sửa chửa hệ thống (2024) | C23: 0 | E23: =B23+C23-D23 -> 0 | F23: =E23/E9 -> 0
A25: Cộng | B25: =B21+B24 -> 0 | C25: =C16+C21+C22+C23 -> 15121195 | D25: =D16+D21+D22+D23 -> 0 | E25: =E16+E21+E22+E23 -> 15121195 | F25: =F16+F21+F22+F23 -> 1996.1974
A27: Người ghi sổ | C27: Kế toán trưởng | E27: Giám đốc
A28: (Ký , họ tên) | C28: (Ký , họ tên) | E28: (Ký , họ tên,đóng dấu)
A30: =A1 -> Công ty TNHH Thuận An | E30: Mẫu số : S 25 - SKT/DNN
A31: =A2 -> Ấp Chồng Nô 3, Xã Hòa Tân, Huyện Cầu Kè, Tỉnh Trà Vinh | E31: Ban hành theo quyết định số
E32: 133/2016/TT-BTC ngày 14/06/2016
E33: của bộ tài chính
A34: THẺ TÍNH GIÁ THÀNH SẢN PHẨM
A35: Tháng 11 /2024
B36: ĐỊA ĐIỂM : | C36: HÒA ÂN
B37: Tên sản phẩm , dịch vụ : Điện năng lượng mặt trời
B38: Số lượng sản phẩm , dịch vụ hoàn thành trong kỳ : | E38: 16184
B39: Phương pháp tính giá thành : Giá thành thực tế
A41: Khoản mục chi phí sản xuất kinh doanh | B41: Chi phí SXKD dở dang đầu kỳ | C41: Chi phí SXKD phát sinh trong kỳ | D41: Chi phí SXKD dở dang cuối kỳ | E41: Giá thành sản phẩm dịch vụ trong kỳ
E42: Giá thành | F42: Giá thành đơn vị
A43: 1. Vật liệu
A45: 2. Nhân công | C45: 2800000 | E45: =C45 -> 2800000 | F45: =E45/E38 -> 173.01038
A47: 3. Máy
A49: 4. Chi phí chung
A50: Chi phí khấu hao hệ thống pin năng lượng mặt trời | C50: 21449563 | D50: =B50-(B50/12)*3 -> 0 | E50: =B50+C50-D50 -> 21449563 | F50: =E50/E38 -> 1325.3561
A51: Chi phí khấu hao thay tấm pin sửa chửa hệ thống | C51: 2872328 | E51: =B51+C51-D51 -> 2872328 | F51: =E51/E38 -> 177.47949
...

Sheet T12
A1: ='THONG TIN'!C3 -> Công ty TNHH Thuận An | E1: Mẫu số : S 25 - SKT/DNN
A2: ='THONG TIN'!C4 -> Ấp Chồng Nô 3, Xã Hòa Tân, Huyện Cầu Kè, Tỉnh Trà Vinh | E2: Ban hành theo quyết định số
E3: 133/2016/TT-BTC ngày 14/06/2016
E4: của bộ tài chính
A5: THẺ TÍNH GIÁ THÀNH SẢN PHẨM
A6: Tháng 12/2024
B7: ĐỊA ĐIỂM : | C7: HÒA TÂN
B8: Tên sản phẩm , dịch vụ : Điện năng lượng mặt trời
B9: Số lượng sản phẩm , dịch vụ hoàn thành trong kỳ : | E9: 6573
B10: Phương pháp tính giá thành : Giá thành thực tế
A12: Khoản mục chi phí sản xuất kinh doanh | B12: Chi phí SXKD dở dang đầu kỳ | C12: Chi phí SXKD phát sinh trong kỳ | D12: Chi phí SXKD dở dang cuối kỳ | E12: Giá thành sản phẩm dịch vụ trong kỳ
E13: Giá thành | F13: Giá thành đơn vị
A14: 1. Vật liệu
A16: 2. Nhân công | C16: =1400000 -> 1400000 | E16: =C16 -> 1400000 | F16: =E16/E9 -> 212.99255
A18: 3. Máy
A20: 4. Chi phí chung
A21: Chi phí khấu hao hệ thống pin năng lượng mặt trời | C21: =12823592+(B21/12) -> 12823592 | D21: =B21-(B21/12)*3 -> 0 | E21: =B21+C21-D21 -> 12823592 | F21: =E21/E9 -> 1950.9496
A22: Chi phí khấu hao thay tấm pin sửa chửa hệ thống (2023) | C22: 897603 | D22: =B22-(B22/12)*3 -> 0 | E22: =B22+C22-D22 -> 897603 | F22: =E22/E9 -> 136.55911
A23: Chi phí khấu hao thay tấm pin sửa chửa hệ thống (2024) | C23: 0 | E23: =B23+C23-D23 -> 0 | F23: =E23/E9 -> 0
A25: Cộng | B25: =B21+B24 -> 0 | C25: =C16+C21+C22+C23 -> 15121195 | D25: =D16+D21+D22+D23 -> 0 | E25: =E16+E21+E22+E23 -> 15121195 | F25: =F16+F21+F22+F23 -> 2300.5013
A27: Người ghi sổ | C27: Kế toán trưởng | E27: Giám đốc
A28: (Ký , họ tên) | C28: (Ký , họ tên) | E28: (Ký , họ tên,đóng dấu)
A30: =A1 -> Công ty TNHH Thuận An | E30: Mẫu số : S 25 - SKT/DNN
A31: =A2 -> Ấp Chồng Nô 3, Xã Hòa Tân, Huyện Cầu Kè, Tỉnh Trà Vinh | E31: Ban hành theo quyết định số
E32: 133/2016/TT-BTC ngày 14/06/2016
E33: của bộ tài chính
A34: THẺ TÍNH GIÁ THÀNH SẢN PHẨM
A35: Tháng 12 /2024
B36: ĐỊA ĐIỂM : | C36: HÒA ÂN
B37: Tên sản phẩm , dịch vụ : Điện năng lượng mặt trời
B38: Số lượng sản phẩm , dịch vụ hoàn thành trong kỳ : | E38: 15947
B39: Phương pháp tính giá thành : Giá thành thực tế
A41: Khoản mục chi phí sản xuất kinh doanh | B41: Chi phí SXKD dở dang đầu kỳ | C41: Chi phí SXKD phát sinh trong kỳ | D41: Chi phí SXKD dở dang cuối kỳ | E41: Giá thành sản phẩm dịch vụ trong kỳ
E42: Giá thành | F42: Giá thành đơn vị
A43: 1. Vật liệu
A45: 2. Nhân công | C45: 2800000 | E45: =C45 -> 2800000 | F45: =E45/E38 -> 175.58161
A47: 3. Máy
A49: 4. Chi phí chung
A50: Chi phí khấu hao hệ thống pin năng lượng mặt trời | C50: 21449563 | D50: =B50-(B50/12)*3 -> 0 | E50: =B50+C50-D50 -> 21449563 | F50: =E50/E38 -> 1345.0532
A51: Chi phí khấu hao thay tấm pin sửa chửa hệ thống | C51: 2872328 | E51: =B51+C51-D51 -> 2872328 | F51: =E51/E38 -> 180.11714
...
